Workbook

Sheet O-PTIR
A1: X value [cmâ»Â¹] | B1: IR Spectrum 1/OPTIR (mV) [] | C1: IR Spectrum 2/OPTIR (mV) [] | D1: IR Spectrum 3/OPTIR (mV) [] | E1: IR Spectrum 4/OPTIR (mV) [] | F1: IR Spectrum 5/OPTIR (mV) [] | G1: IR Spectrum 6/OPTIR (mV) [] | H1: IR Spectrum 7/OPTIR (mV) [] | I1: IR Spectrum 8/OPTIR (mV) [] | J1: IR Spectrum 9/OPTIR (mV) [] | K1: IR Spectrum 10/OPTIR (mV) [] | L1: IR Spectrum 11/OPTIR (mV) [] | M1: IR Spectrum 12/OPTIR (mV) [] | N1: IR Spectrum 13/OPTIR (mV) [] | O1: IR Spectrum 14/OPTIR (mV) [] | P1: IR Spectrum 15/OPTIR (mV) [] | Q1: IR Spectrum 16/OPTIR (mV) [] | R1: IR Spectrum 17/OPTIR (mV) [] | S1: IR Spectrum 18/OPTIR (mV) [] | T1: IR Spectrum 19/OPTIR (mV) [] | U1: IR Spectrum 20/OPTIR (mV) [] | V1: IR Spectrum 21/OPTIR (mV) [] | W1: IR Spectrum 22/OPTIR (mV) [] | X1: IR Spectrum 23/OPTIR (mV) [] | Y1: IR Spectrum 24/OPTIR (mV) [] | Z1: IR Spectrum 25/OPTIR (mV) [] | AA1: IR Spectrum 26/OPTIR (mV) [] | AB1: IR Spectrum 27/OPTIR (mV) [] | AC1: IR Spectrum 28/OPTIR (mV) [] | AD1: IR Spectrum 29/OPTIR (mV) [] | AE1: IR Spectrum 1/OPTIR (mV) [] | AF1: IR Spectrum 2/OPTIR (mV) [] | AG1: IR Spectrum 3/OPTIR (mV) [] | AH1: IR Spectrum 4/OPTIR (mV) [] | AI1: IR Spectrum 5/OPTIR (mV) [] | AJ1: IR Spectrum 6/OPTIR (mV) [] | AK1: IR Spectrum 7/OPTIR (mV) [] | AL1: IR Spectrum 8/OPTIR (mV) [] | AM1: IR Spectrum 9/OPTIR (mV) [] | AN1: IR Spectrum 10/OPTIR (mV) [] | AO1: IR Spectrum 11/OPTIR (mV) [] | AP1: IR Spectrum 12/OPTIR (mV) [] | AQ1: IR Spectrum 13/OPTIR (mV) [] | AR1: IR Spectrum 14/OPTIR (mV) [] | AS1: IR Spectrum 15/OPTIR (mV) [] | AT1: IR Spectrum 16/OPTIR (mV) [] | AU1: IR Spectrum 17/OPTIR (mV) [] | AV1: IR Spectrum 18/OPTIR (mV) [] | AW1: IR Spectrum 19/OPTIR (mV) [] | AX1: IR Spectrum 20/OPTIR (mV) [] | AY1: IR Spectrum 21/OPTIR (mV) [] | AZ1: IR Spectrum 22/OPTIR (mV) [] | BA1: IR Spectrum 23/OPTIR (mV) [] | BB1: IR Spectrum 24/OPTIR (mV) [] | BC1: IR Spectrum 25/OPTIR (mV) [] | BD1: IR Spectrum 26/OPTIR (mV) [] | BE1: IR Spectrum 27/OPTIR (mV) [] | BF1: IR Spectrum 28/OPTIR (mV) [] | BG1: IR Spectrum 29/OPTIR (mV) [] | BH1: IR Spectrum 30/OPTIR (mV) [] | BI1: IR Spectrum 31/OPTIR (mV) []
A2: 948 | B2: 0.74432343 | C2: 0.29022789 | D2: 0.33323428 | E2: 0.89626718 | F2: 1.1511611 | G2: 0.87787187 | H2: -3.7398376 | I2: -1.292586 | J2: -1.0857691 | K2: 0.68850511 | L2: -2.7830307 | M2: 2.6062672 | N2: 2.6788189 | O2: 3.3899632 | P2: -3.052681 | Q2: 1.5085568 | R2: -0.27823669 | S2: 1.1597732 | T2: -3.3678029 | U2: 0.68371469 | V2: 0.54264247 | W2: 2.854846 | X2: 0.0644053 | Y2: 1.8906963 | Z2: -2.9151525 | AA2: 1.7216339 | AB2: -0.070259519 | AC2: -1.4113824 | AD2: -0.33851454 | AE2: 0.29469606 | AF2: 0.29375452 | AG2: -0.43269265 | AH2: 0.35083154 | AI2: -0.059525579 | AJ2: -0.74037015 | AK2: -0.12429151 | AL2: 0.81776029 | AM2: -0.45792088 | AN2: -0.21826203 | AO2: -0.23684561 | AP2: 1.2109176 | AQ2: 1.5022793 | AR2: -1.1719726 | AS2: -0.21310548 | AT2: 0.0075503797 | AU2: -0.45432034 | AV2: 0.48737475 | AW2: 0.78080243 | AX2: -0.6214295 | AY2: -0.19462076 | AZ2: -1.5493608 | BA2: -0.052670561 | BB2: -0.960926 | BC2: 0.30232492 | BD2: -0.99079204 | BE2: 0.050230358 | BF2: 0.11434116 | BG2: -1.3257575 | BH2: 0.20294034 | BI2: -1.0418974
A3: 950 | B3: 2.2915871 | C3: 0.5833354 | D3: -1.4359747 | E3: -0.72650009 | F3: -0.17859009 | G3: 4.4197459 | H3: -1.2791016 | I3: -3.4884639 | J3: -0.097145036 | K3: -1.2027476 | L3: -0.8786242 | M3: 0.15259647 | N3: 1.1953312 | O3: 1.1355958 | P3: -2.1158793 | Q3: 1.5974119 | R3: -1.2858925 | S3: 3.7473531 | T3: -0.53124022 | U3: 0.57488757 | V3: 0.83460474 | W3: 4.6252007 | X3: -1.1124498 | Y3: 0.44499016 | Z3: -1.316946 | AA3: -0.30430162 | AB3: -0.96343124 | AC3: -2.7554588 | AD3: 1.3552005 | AE3: 0.5898335 | AF3: 0.61630845 | AG3: -0.57168102 | AH3: 0.33139503 | AI3: 0.1022228 | AJ3: -0.56181425 | AK3: -0.68551397 | AL3: 0.73370004 | AM3: -0.23681927 | AN3: -0.7079969 | AO3: -0.17293818 | AP3: 1.0996188 | AQ3: 1.3859539 | AR3: 0.10336083 | AS3: -0.11485173 | AT3: 0.084633291 | AU3: 0.2663334 | AV3: 0.20474257 | AW3: 0.57210821 | AX3: -0.44865519 | AY3: -0.12041634 | AZ3: -1.016572 | BA3: 0.079519406 | BB3: -0.29070082 | BC3: -0.39513159 | BD3: -1.487605 | BE3: 0.46957985 | BF3: 0.31223589 | BG3: -1.521701 | BH3: 0.35079992 | BI3: -1.6125057
A4: 952 | B4: 0.29183397 | C4: 1.3603048 | D4: 1.7600306 | E4: 0.84983611 | F4: 0.50614345 | G4: 2.7854109 | H4: 0.65802556 | I4: -1.8848004 | J4: -1.5413561 | K4: 0.74953961 | L4: 3.4662402 | M4: 0.9789443 | N4: 0.60865974 | O4: 0.22454084 | P4: -0.23272128 | Q4: 2.2606895 | R4: -0.68435723 | S4: 2.2380757 | T4: -2.3182249 | U4: 0.33913678 | V4: 0.17580399 | W4: 2.7184012 | X4: -2.6517324 | Y4: -0.61045635 | Z4: 0.86172885 | AA4: -2.7307742 | AB4: -2.1637814 | AC4: -2.4634359 | AD4: 2.5221035 | AE4: -0.10534324 | AF4: 0.62441182 | AG4: -0.32947788 | AH4: -0.34979308 | AI4: -0.13028479 | AJ4: -0.92391682 | AK4: -0.39414221 | AL4: 1.0881226 | AM4: -0.72639143 | AN4: -0.96200991 | AO4: 0.060016435 | AP4: 1.174626 | AQ4: 1.5262344 | AR4: -0.023694972 | AS4: 0.34042689 | AT4: -0.15626796 | AU4: 0.28926083 | AV4: 0.39106831 | AW4: 0.68603134 | AX4: -0.56171751 | AY4: 0.037795838 | AZ4: -0.52456331 | BA4: 0.051077187 | BB4: -0.37117001 | BC4: -1.0676277 | BD4: -1.0690904 | BE4: 0.052453063 | BF4: -0.10963911 | BG4: -1.2711316 | BH4: 0.36264083 | BI4: -1.3216432
A5: 954 | B5: 1.8470817 | C5: 0.81226367 | D5: 1.43516 | E5: 0.56408548 | F5: -1.5203713 | G5: 1.2694269 | H5: 1.1026112 | I5: -1.4209926 | J5: -0.28707308 | K5: -0.21842881 | L5: 2.1726861 | M5: 0.5067606 | N5: 0.81710255 | O5: -0.33647794 | P5: -1.4203889 | Q5: 0.37371281 | R5: -0.8683694 | S5: 1.4935646 | T5: -1.6993775 | U5: 0.91388619 | V5: 0.88116294 | W5: -0.45097581 | X5: -0.73999524 | Y5: 0.21763514 | Z5: 1.4131801 | AA5: 0.41526029 | AB5: -1.0226611 | AC5: -1.8329035 | AD5: 1.0942413 | AE5: -0.6193698 | AF5: 0.37635845 | AG5: 0.12576707 | AH5: -0.43639794 | AI5: -0.27663156 | AJ5: -0.72388381 | AK5: -0.77379781 | AL5: 0.71472502 | AM5: -1.0118484 | AN5: -0.13492127 | AO5: 0.25110334 | AP5: 0.72178376 | AQ5: 0.65083402 | AR5: 0.2361317 | AS5: 0.079925582 | AT5: -0.76849169 | AU5: -0.44416967 | AV5: -0.37683013 | AW5: 0.14851129 | AX5: -0.33412397 | AY5: -0.33875614 | AZ5: -0.81621313 | BA5: 0.36088401 | BB5: -0.28320122 | BC5: -0.14213774 | BD5: -0.41703799 | BE5: -0.17186072 | BF5: 0.32163104 | BG5: -0.43552125 | BH5: 0.41907182 | BI5: -0.86314464
A6: 956 | B6: 2.1132426 | C6: 0.087585017 | D6: 1.3728111 | E6: 0.63575268 | F6: -0.88015652 | G6: 2.1246893 | H6: 0.82454765 | I6: -1.5907736 | J6: -0.44417101 | K6: -0.4128654 | L6: 0.8887955 | M6: -1.4894218 | N6: 1.0790849 | O6: 0.72812402 | P6: -0.95945615 | Q6: -0.66571254 | R6: -1.3365483 | S6: -0.25954285 | T6: -1.1230031 | U6: 1.6801956 | V6: -0.7390092 | W6: -0.31180626 | X6: -2.4162071 | Y6: -0.011069408 | Z6: -0.050180178 | AA6: 0.43399948 | AB6: -0.50132048 | AC6: -1.3109767 | AD6: 0.21746126 | AE6: -0.17700857 | AF6: 0.35075042 | AG6: 0.26982343 | AH6: 0.2305055 | AI6: -0.26899084 | AJ6: -1.1276478 | AK6: -0.50779706 | AL6: 0.1941506 | AM6: -0.64551693 | AN6: -0.58168 | AO6: 0.21783698 | AP6: 0.80955344 | AQ6: 0.043746173 | AR6: -0.53042173 | AS6: 0.9030925 | AT6: -0.39953405 | AU6: 0.070076719 | AV6: -0.83581632 | AW6: 0.29176712 | AX6: -0.15203235 | AY6: -0.52265513 | AZ6: -0.28818366 | BA6: -0.12696253 | BB6: -0.58340192 | BC6: 0.34464943 | BD6: -1.0156094 | BE6: -0.90960348 | BF6: -0.11193198 | BG6: -0.017530859 | BH6: -0.093448356 | BI6: -0.52255684
A7: 958 | B7: -0.18345611 | C7: -0.61098665 | D7: 0.31607163 | E7: 1.2131209 | F7: -0.60783702 | G7: 1.252107 | H7: -1.2259028 | I7: -0.85664678 | J7: -1.037943 | K7: -1.2280812 | L7: 1.5811067 | M7: 0.18202238 | N7: 0.023702165 | O7: 1.2315419 | P7: -0.8399663 | Q7: 1.5060034 | R7: -1.6836376 | S7: 0.99319643 | T7: -1.3214065 | U7: 0.53676867 | V7: -0.42508391 | W7: 0.85226899 | X7: -0.56984431 | Y7: 0.29334289 | Z7: -2.204288 | AA7: 0.83185416 | AB7: 0.30006254 | AC7: -1.3062472 | AD7: 1.1398602 | AE7: -0.17516236 | AF7: 0.059484176 | AG7: 0.16147092 | AH7: 0.33650979 | AI7: -0.82749909 | AJ7: -0.97143656 | AK7: -0.081473462 | AL7: 0.05059899 | AM7: -0.4093723 | AN7: -0.24028084 | AO7: 0.22679006 | AP7: 0.41196555 | AQ7: 0.36198404 | AR7: -0.68256414 | AS7: -0.49624988 | AT7: -0.030843036 | AU7: 0.091949984 | AV7: -0.71757138 | AW7: 0.45761833 | AX7: -0.071469128 | AY7: -0.0062858034 | AZ7: 0.3121745 | BA7: -0.14495601 | BB7: -0.58635008 | BC7: -0.33652747 | BD7: -0.74174339 | BE7: -0.54188269 | BF7: -0.51387924 | BG7: -0.24867532 | BH7: 0.05212526 | BI7: -0.069193795
A8: 960 | B8: 1.2732528 | C8: 0.084803298 | D8: 0.43352324 | E8: 0.57761037 | F8: -0.87230378 | G8: 0.54134816 | H8: -2.059289 | I8: -1.3872007 | J8: -0.1295156 | K8: -0.95730895 | L8: 0.36244887 | M8: -0.47243756 | N8: 0.9814865 | O8: -0.27958068 | P8: -1.534268 | Q8: 0.88921428 | R8: 0.1871618 | S8: 0.517726 | T8: -1.76194 | U8: 0.36037877 | V8: -0.55307585 | W8: -0.025023971 | X8: -0.37236798 | Y8: 0.52768481 | Z8: -1.3020117 | AA8: 0.10353839 | AB8: 0.049754515 | AC8: -2.0463541 | AD8: 0.24213953 | AE8: -0.4362725 | AF8: -0.12029681 | AG8: -0.086275294 | AH8: 0.18149474 | AI8: -0.42373419 | AJ8: -0.9085862 | AK8: -0.34800756 | AL8: -0.19558766 | AM8: 0.0014367655 | AN8: -0.11201996 | AO8: 0.21557453 | AP8: 0.43544757 | AQ8: 0.36259982 | AR8: -0.40175638 | AS8: -0.38562405 | AT8: -0.11018761 | AU8: 0.064403787 | AV8: -0.4347021 | AW8: 0.049957134 | AX8: 0.080052957 | AY8: -0.085257925 | AZ8: -0.12385185 | BA8: -0.11473977 | BB8: -0.39573598 | BC8: 0.14187726 | BD8: -0.091184139 | BE8: -0.57040453 | BF8: 0.32796609 | BG8: -0.16728252 | BH8: 0.096845485 | BI8: 0.14731528
A9: 962 | B9: 0.69802564 | C9: 0.94188923 | D9: 0.73204857 | E9: 1.403367 | F9: -1.2677385 | G9: 2.042618 | H9: -0.36096862 | I9: -0.91846317 | J9: -0.0093100341 | K9: 0.46601149 | L9: 0.31237924 | M9: 0.29313615 | N9: 1.279992 | O9: -1.028752 | P9: -0.46205458 | Q9: 0.39528492 | R9: 0.48408943 | S9: -0.05226782 | T9: -0.97857535 | U9: 0.35031301 | V9: -1.3394257 | W9: -0.12585849 | X9: -0.25954673 | Y9: 0.426061 | Z9: -0.10566749 | AA9: -0.067738876 | AB9: 0.97449869 | AC9: -1.1074677 | AD9: 0.17468722 | AE9: -0.27992132 | AF9: -0.056971952 | AG9: 0.090217754 | AH9: -0.072565399 | AI9: -0.0027862072 | AJ9: -0.55638224 | AK9: -0.32088733 | AL9: 0.19970673 | AM9: -0.18076989 | AN9: 0.33567974 | AO9: 0.1290267 | AP9: 0.23539241 | AQ9: 0.43952447 | AR9: 0.31992987 | AS9: -0.30859229 | AT9: -0.019626806 | AU9: 0.32926545 | AV9: 0.20824334 | AW9: -0.1970695 | AX9: 0.084131882 | AY9: -0.055895939 | AZ9: 0.3510063 | BA9: -0.21388689 | BB9: -0.53875524 | BC9: -0.033891208 | BD9: -0.63760632 | BE9: 0.10392695 | BF9: 0.077968426 | BG9: -0.13450256 | BH9: -0.13259238 | BI9: -0.2688075
A10: 964 | B10: 1.6073052 | C10: 0.80427349 | D10: 0.86198586 | E10: -0.25310799 | F10: -0.56014341 | G10: 1.423357 | H10: -0.63442641 | I10: -0.369241 | J10: 0.47711638 | K10: -0.058138158 | L10: -0.26348418 | M10: 0.24100578 | N10: 1.4584178 | O10: -0.87474418 | P10: -0.028061295 | Q10: 0.15348411 | R10: 0.14276329 | S10: -0.2612358 | T10: -0.7801075 | U10: 0.44687423 | V10: -0.6247409 | W10: 0.36238804 | X10: -0.3896513 | Y10: 0.36482972 | Z10: -0.45253447 | AA10: -0.084953271 | AB10: -0.13744256 | AC10: -0.67943978 | AD10: 0.78018481 | AE10: 0.13254444 | AF10: 0.15540677 | AG10: -0.056808513 | AH10: -0.260831 | AI10: 0.40394804 | AJ10: -0.38363007 | AK10: -0.33204371 | AL10: -0.017469388 | AM10: -0.034073748 | AN10: 0.053389698 | AO10: -0.11236956 | AP10: -0.075184703 | AQ10: 0.12862095 | AR10: 0.21681806 | AS10: 0.052441619 | AT10: -0.023930851 | AU10: 0.15593253 | AV10: 0.31821412 | AW10: -0.2259403 | AX10: -0.14063022 | AY10: -0.065967768 | AZ10: 0.099241704 | BA10: 0.0097618988 | BB10: -0.1681852 | BC10: 0.28353688 | BD10: -0.58306962 | BE10: 0.11998355 | BF10: -0.057682287 | BG10: -0.13743587 | BH10: -0.012121148 | BI10: -0.22131702
A11: 966 | B11: 0.8209796 | C11: 0.13451257 | D11: 1.1611456 | E11: -0.11478829 | F11: -0.25910878 | G11: 1.1064004 | H11: -0.81811982 | I11: 0.17722426 | J11: -0.02399846 | K11: -0.55729926 | L11: -0.22246085 | M11: 0.23608391 | N11: 1.2200786 | O11: -0.26134974 | P11: -0.40915847 | Q11: 0.0077680983 | R11: 0.094347656 | S11: 0.24468628 | T11: -0.489171 | U11: 0.59907877 | V11: -0.41311154 | W11: -0.1899682 | X11: -0.073133461 | Y11: 0.26190194 | Z11: -0.60715765 | AA11: -0.010133931 | AB11: -0.44932294 | AC11: -0.30464157 | AD11: 0.82012624 | AE11: -0.27035496 | AF11: 0.051025517 | AG11: 0.037817813 | AH11: -0.090429723 | AI11: -0.011290182 | AJ11: -0.56584543 | AK11: -0.054266062 | AL11: -0.26986092 | AM11: -0.37933183 | AN11: -0.17550711 | AO11: 0.083995432 | AP11: -0.21809205 | AQ11: -0.020450795 | AR11: 0.28123522 | AS11: -0.061201844 | AT11: 0.21704563 | AU11: 0.085692078 | AV11: 0.018659554 | AW11: -0.16788651 | AX11: -0.11170167 | AY11: -0.12966347 | AZ11: 0.0068319007 | BA11: 0.072433844 | BB11: -0.21383254 | BC11: 0.10998891 | BD11: -0.35871449 | BE11: 0.20025222 | BF11: -0.35016462 | BG11: -0.074738987 | BH11: 0.02101486 | BI11: -0.21854182
A12: 968 | B12: 0.50754452 | C12: -0.61106622 | D12: 0.44641757 | E12: -0.3849268 | F12: -0.57586586 | G12: 1.3206104 | H12: -0.74588782 | I12: -0.86721784 | J12: -0.53765148 | K12: 0.15651575 | L12: -0.92252314 | M12: -0.39687556 | N12: 1.2929349 | O12: -0.032078478 | P12: -0.40046644 | Q12: 0.53855228 | R12: -0.0075209811 | S12: 0.042256903 | T12: -0.54059672 | U12: 0.13597822 | V12: -0.55769277 | W12: 0.77587724 | X12: -0.3659637 | Y12: 0.069243215 | Z12: -0.74933559 | AA12: -0.46617544 | AB12: 0.11102417 | AC12: 0.50991279 | AD12: 0.76560676 | AE12: 0.03051383 | AF12: -0.052075315 | AG12: 0.034702633 | AH12: 0.34769648 | AI12: -0.1431713 | AJ12: -0.45705044 | AK12: -0.013211809 | AL12: 0.17130336 | AM12: 0.1552829 | AN12: -0.32368109 | AO12: 0.1096007 | AP12: 0.050998904 | AQ12: 0.14577773 | AR12: 0.033422675 | AS12: -0.38203937 | AT12: 0.30076075 | AU12: -0.12791306 | AV12: -0.23165621 | AW12: -0.013343892 | AX12: -0.023663936 | AY12: -0.12458103 | AZ12: -0.10463776 | BA12: 0.024404477 | BB12: -0.32416841 | BC12: 0.12047655 | BD12: -0.051975708 | BE12: -0.079789281 | BF12: -0.20937395 | BG12: -0.055077892 | BH12: -0.050093129 | BI12: -0.32387662
A13: 970 | B13: 0.49141777 | C13: -0.73317969 | D13: 0.58562022 | E13: -0.22284724 | F13: -0.39186147 | G13: 0.75493747 | H13: -0.82684511 | I13: -1.2210937 | J13: -0.49288774 | K13: 0.036194671 | L13: 0.048850954 | M13: -0.18807067 | N13: 0.42528871 | O13: 0.32053861 | P13: -0.26075512 | Q13: 0.88324267 | R13: -0.24525453 | S13: -0.023286011 | T13: -0.41773844 | U13: -0.27785113 | V13: -0.13531362 | W13: 0.6777724 | X13: -0.32984835 | Y13: 0.51723742 | Z13: -0.47191301 | AA13: 0.19962034 | AB13: -0.35121426 | AC13: 0.15926929 | AD13: 0.1029425 | AE13: -0.1230415 | AF13: -0.045607995 | AG13: 0.13421237 | AH13: 0.59748179 | AI13: -0.081236094 | AJ13: -0.42645788 | AK13: 0.09225376 | AL13: 0.12107285 | AM13: 0.020645313 | AN13: -0.077491492 | AO13: -0.18248387 | AP13: -0.10080609 | AQ13: 0.28865361 | AR13: -0.12306952 | AS13: -0.1631618 | AT13: 0.18014084 | AU13: -0.028640538 | AV13: -0.068220235 | AW13: -0.028922522 | AX13: -0.092681699 | AY13: -0.15886511 | AZ13: -0.093389824 | BA13: 0.094647624 | BB13: -0.15941274 | BC13: 0.19791234 | BD13: -0.084048912 | BE13: -0.40857628 | BF13: -0.13045391 | BG13: 0.0037638615 | BH13: -0.093477651 | BI13: -0.38519105
... A1030: 3004 | B1030: -1.7428007 | C1030: 6.0990157 | D1030: -3.7746119 | E1030: 0.17596778 | F1030: -5.8451867 | G1030: 2.7390375 | H1030: -3.6820669 | I1030: -2.2868814 | J1030: -2.6328011 | K1030: 0.44567117 | L1030: 0.42734551 | M1030: 2.3206248 | N1030: 0.99290162 | O1030: -0.090885974 | P1030: -1.8174033 | Q1030: 4.3202977 | R1030: -1.0318197 | S1030: -0.48279789 | T1030: -3.2523775 | U1030: 0.035281532 | V1030: -0.58340997 | W1030: -0.43148461 | X1030: 0.9192555 | Y1030: -2.2003472 | Z1030: -4.4586849 | AA1030: 1.4762101 | AB1030: 3.0303147 | AC1030: -2.812371 | AD1030: 0.30952752 | AE1030: -0.0018238127 | AF1030: 0.3667374 | AG1030: 0.84641063 | AH1030: 1.050382 | AI1030: 1.2837179 | AJ1030: -3.3295834 | AK1030: -0.65282089 | AL1030: -0.029919062 | AM1030: 0.53446436 | AN1030: -1.2299261 | AO1030: -0.37679976 | AP1030: -1.35751 | AQ1030: 0.59490824 | AR1030: -0.81823337 | AS1030: -1.3167062 | AT1030: 0.21663934 | AU1030: 0.93596011 | AV1030: -0.48279625 | AW1030: -0.31565735 | AX1030: 0.60567975 | AY1030: -0.29585451 | AZ1030: -0.99147934 | BA1030: 0.21748833 | BB1030: -0.032897796 | BC1030: 0.57897639 | BD1030: -2.2480798 | BE1030: -0.23092949 | BF1030: 0.47444978 | BG1030: -0.35490146 | BH1030: -0.51402348 | BI1030: -1.3910024

Sheet O-PTIR norm
A1: OPTIR waveno | B1: 1 | C1: =B1+1 -> 2 | D1: =C1+1 -> 3 | E1: =D1+1 -> 4 | F1: =E1+1 -> 5 | G1: =F1+1 -> 6 | H1: =G1+1 -> 7 | I1: =H1+1 -> 8 | J1: =I1+1 -> 9 | ... BI1: =BH1+1 -> 60
A2: 948 | B2: ='O-PTIR'!B2/MAX('O-PTIR'!B:B) -> 0.068346228 | C2: ='O-PTIR'!C2/MAX('O-PTIR'!C:C) -> 0.015370312 | D2: ='O-PTIR'!D2/MAX('O-PTIR'!D:D) -> 0.044072935 | E2: ='O-PTIR'!E2/MAX('O-PTIR'!E:E) -> 0.17189187 | F2: ='O-PTIR'!F2/MAX('O-PTIR'!F:F) -> 0.67633454 | G2: ='O-PTIR'!G2/MAX('O-PTIR'!G:G) -> 0.16269415 | H2: ='O-PTIR'!H2/MAX('O-PTIR'!H:H) -> -3.3918009 | I2: ='O-PTIR'!I2/MAX('O-PTIR'!I:I) -> -0.80908179 | J2: ='O-PTIR'!J2/MAX('O-PTIR'!J:J) -> -0.30394702 | K2: ='O-PTIR'!K2/MAX('O-PTIR'!K:K) -> 0.014647206 | L2: ='O-PTIR'!L2/MAX('O-PTIR'!L:L) -> -0.80289611 | M2: ='O-PTIR'!M2/MAX('O-PTIR'!M:M) -> 0.0027202932 | N2: ='O-PTIR'!N2/MAX('O-PTIR'!N:N) -> 0.46923549 | O2: ='O-PTIR'!O2/MAX('O-PTIR'!O:O) -> 0.52828617 | P2: ='O-PTIR'!P2/MAX('O-PTIR'!P:P) -> -0.14071711 | Q2: ='O-PTIR'!Q2/MAX('O-PTIR'!Q:Q) -> 0.0090648509 | R2: ='O-PTIR'!R2/MAX('O-PTIR'!R:R) -> -0.12717512 | S2: ='O-PTIR'!S2/MAX('O-PTIR'!S:S) -> 0.034678876 | T2: ='O-PTIR'!T2/MAX('O-PTIR'!T:T) -> -0.082413297 | U2: ='O-PTIR'!U2/MAX('O-PTIR'!U:U) -> 0.0053050448 | V2: ='O-PTIR'!V2/MAX('O-PTIR'!V:V) -> 0.019400195 | W2: ='O-PTIR'!W2/MAX('O-PTIR'!W:W) -> 0.11872515 | X2: ='O-PTIR'!X2/MAX('O-PTIR'!X:X) -> 0.014891056 | Y2: ='O-PTIR'!Y2/MAX('O-PTIR'!Y:Y) -> 0.062091134 | Z2: ='O-PTIR'!Z2/MAX('O-PTIR'!Z:Z) -> -0.18602094 | AA2: ='O-PTIR'!AA2/MAX('O-PTIR'!AA:AA) -> 0.93222405 | AB2: ='O-PTIR'!AB2/MAX('O-PTIR'!AB:AB) -> -0.023185552 | AC2: ='O-PTIR'!AC2/MAX('O-PTIR'!AC:AC) -> -0.044567294 | AD2: ='O-PTIR'!AD2/MAX('O-PTIR'!AD:AD) -> -0.0074065677 | AE2: ='O-PTIR'!AE2/MAX('O-PTIR'!AE:AE) -> 0.0051344816 | AF2: ='O-PTIR'!AF2/MAX('O-PTIR'!AF:AF) -> 0.016437164 | AG2: ='O-PTIR'!AG2/MAX('O-PTIR'!AG:AG) -> -0.02719344 | AH2: ='O-PTIR'!AH2/MAX('O-PTIR'!AH:AH) -> 0.011893094 | AI2: ='O-PTIR'!AI2/MAX('O-PTIR'!AI:AI) -> -0.0038461779 | AJ2: ='O-PTIR'!AJ2/MAX('O-PTIR'!AJ:AJ) -> -0.5616955 | AK2: ='O-PTIR'!AK2/MAX('O-PTIR'!AK:AK) -> -0.12039919 | AL2: ='O-PTIR'!AL2/MAX('O-PTIR'!AL:AL) -> 0.23619242 | AM2: ='O-PTIR'!AM2/MAX('O-PTIR'!AM:AM) -> -0.068257983 | AN2: ='O-PTIR'!AN2/MAX('O-PTIR'!AN:AN) -> -0.011462801 | AO2: ='O-PTIR'!AO2/MAX('O-PTIR'!AO:AO) -> -0.0058161962 | AP2: ='O-PTIR'!AP2/MAX('O-PTIR'!AP:AP) -> 0.016028448 | AQ2: ='O-PTIR'!AQ2/MAX('O-PTIR'!AQ:AQ) -> 0.035206091 | AR2: ='O-PTIR'!AR2/MAX('O-PTIR'!AR:AR) -> -0.035369931 | AS2: ='O-PTIR'!AS2/MAX('O-PTIR'!AS:AS) -> -0.00457557 | AT2: ='O-PTIR'!AT2/MAX('O-PTIR'!AT:AT) -> 2.609672e-05 | AU2: ='O-PTIR'!AU2/MAX('O-PTIR'!AU:AU) -> -0.022809878 | AV2: ='O-PTIR'!AV2/MAX('O-PTIR'!AV:AV) -> 0.010691966 | AW2: ='O-PTIR'!AW2/MAX('O-PTIR'!AW:AW) -> 0.02646121 | AX2: ='O-PTIR'!AX2/MAX('O-PTIR'!AX:AX) -> -0.014511075 | AY2: ='O-PTIR'!AY2/MAX('O-PTIR'!AY:AY) -> -0.17617134 | AZ2: ='O-PTIR'!AZ2/MAX('O-PTIR'!AZ:AZ) -> -0.026805408 | BA2: ='O-PTIR'!BA2/MAX('O-PTIR'!BA:BA) -> -0.0042650077 | BB2: ='O-PTIR'!BB2/MAX('O-PTIR'!BB:BB) -> -0.0096354105 | BC2: ='O-PTIR'!BC2/MAX('O-PTIR'!BC:BC) -> 0.1819654 | BD2: ='O-PTIR'!BD2/MAX('O-PTIR'!BD:BD) -> -0.13305955 | BE2: ='O-PTIR'!BE2/MAX('O-PTIR'!BE:BE) -> 0.010839298 | BF2: ='O-PTIR'!BF2/MAX('O-PTIR'!BF:BF) -> 0.0018855972 | BG2: ='O-PTIR'!BG2/MAX('O-PTIR'!BG:BG) -> -0.0032088341 | BH2: ='O-PTIR'!BH2/MAX('O-PTIR'!BH:BH) -> 0.0086932157 | BI2: ='O-PTIR'!BI2/MAX('O-PTIR'!BI:BI) -> -0.019092127
A3: 950 | B3: ='O-PTIR'!B3/MAX('O-PTIR'!B:B) -> 0.21042107 | C3: ='O-PTIR'!C3/MAX('O-PTIR'!C:C) -> 0.030893127 | D3: ='O-PTIR'!D3/MAX('O-PTIR'!D:D) -> -0.1899193 | E3: ='O-PTIR'!E3/MAX('O-PTIR'!E:E) -> -0.13933285 | F3: ='O-PTIR'!F3/MAX('O-PTIR'!F:F) -> -0.10492593 | G3: ='O-PTIR'!G3/MAX('O-PTIR'!G:G) -> 0.81910224 | H3: ='O-PTIR'!H3/MAX('O-PTIR'!H:H) -> -1.1600659 | I3: ='O-PTIR'!I3/MAX('O-PTIR'!I:I) -> -2.1835705 | J3: ='O-PTIR'!J3/MAX('O-PTIR'!J:J) -> -0.027194498 | K3: ='O-PTIR'!K3/MAX('O-PTIR'!K:K) -> -0.025587161 | L3: ='O-PTIR'!L3/MAX('O-PTIR'!L:L) -> -0.25348047 | M3: ='O-PTIR'!M3/MAX('O-PTIR'!M:M) -> 0.00015927268 | N3: ='O-PTIR'!N3/MAX('O-PTIR'!N:N) -> 0.20938027 | O3: ='O-PTIR'!O3/MAX('O-PTIR'!O:O) -> 0.17696934 | P3: ='O-PTIR'!P3/MAX('O-PTIR'!P:P) -> -0.097534074 | Q3: ='O-PTIR'!Q3/MAX('O-PTIR'!Q:Q) -> 0.0095987768 | R3: ='O-PTIR'!R3/MAX('O-PTIR'!R:R) -> -0.5877497 | S3: ='O-PTIR'!S3/MAX('O-PTIR'!S:S) -> 0.11205121 | T3: ='O-PTIR'!T3/MAX('O-PTIR'!T:T) -> -0.012999947 | U3: ='O-PTIR'!U3/MAX('O-PTIR'!U:U) -> 0.0044606389 | V3: ='O-PTIR'!V3/MAX('O-PTIR'!V:V) -> 0.029838238 | W3: ='O-PTIR'!W3/MAX('O-PTIR'!W:W) -> 0.1923493 | X3: ='O-PTIR'!X3/MAX('O-PTIR'!X:X) -> -0.2572079 | Y3: ='O-PTIR'!Y3/MAX('O-PTIR'!Y:Y) -> 0.014613634 | Z3: ='O-PTIR'!Z3/MAX('O-PTIR'!Z:Z) -> -0.084036611 | AA3: ='O-PTIR'!AA3/MAX('O-PTIR'!AA:AA) -> -0.16477213 | AB3: ='O-PTIR'!AB3/MAX('O-PTIR'!AB:AB) -> -0.31793109 | AC3: ='O-PTIR'!AC3/MAX('O-PTIR'!AC:AC) -> -0.087009261 | AD3: ='O-PTIR'!AD3/MAX('O-PTIR'!AD:AD) -> 0.029651266 | AE3: ='O-PTIR'!AE3/MAX('O-PTIR'!AE:AE) -> 0.010276653 | AF3: ='O-PTIR'!AF3/MAX('O-PTIR'!AF:AF) -> 0.034485812 | AG3: ='O-PTIR'!AG3/MAX('O-PTIR'!AG:AG) -> -0.035928444 | AH3: ='O-PTIR'!AH3/MAX('O-PTIR'!AH:AH) -> 0.011234202 | AI3: ='O-PTIR'!AI3/MAX('O-PTIR'!AI:AI) -> 0.0066050104 | AJ3: ='O-PTIR'!AJ3/MAX('O-PTIR'!AJ:AJ) -> -0.42623076 | AK3: ='O-PTIR'!AK3/MAX('O-PTIR'!AK:AK) -> -0.66404636 | AL3: ='O-PTIR'!AL3/MAX('O-PTIR'!AL:AL) -> 0.21191343 | AM3: ='O-PTIR'!AM3/MAX('O-PTIR'!AM:AM) -> -0.035300434 | AN3: ='O-PTIR'!AN3/MAX('O-PTIR'!AN:AN) -> -0.037182955 | AO3: ='O-PTIR'!AO3/MAX('O-PTIR'!AO:AO) -> -0.0042468273 | AP3: ='O-PTIR'!AP3/MAX('O-PTIR'!AP:AP) -> 0.014555228 | AQ3: ='O-PTIR'!AQ3/MAX('O-PTIR'!AQ:AQ) -> 0.032479992 | AR3: ='O-PTIR'!AR3/MAX('O-PTIR'!AR:AR) -> 0.003119412 | AS3: ='O-PTIR'!AS3/MAX('O-PTIR'!AS:AS) -> -0.0024659718 | AT3: ='O-PTIR'!AT3/MAX('O-PTIR'!AT:AT) -> 0.00029252188 | AU3: ='O-PTIR'!AU3/MAX('O-PTIR'!AU:AU) -> 0.013371693 | AV3: ='O-PTIR'!AV3/MAX('O-PTIR'!AV:AV) -> 0.0044916167 | AW3: ='O-PTIR'!AW3/MAX('O-PTIR'!AW:AW) -> 0.019388612 | AX3: ='O-PTIR'!AX3/MAX('O-PTIR'!AX:AX) -> -0.010476601 | AY3: ='O-PTIR'!AY3/MAX('O-PTIR'!AY:AY) -> -0.10900126 | AZ3: ='O-PTIR'!AZ3/MAX('O-PTIR'!AZ:AZ) -> -0.017587658 | BA3: ='O-PTIR'!BA3/MAX('O-PTIR'!BA:BA) -> 0.0064390975 | BB3: ='O-PTIR'!BB3/MAX('O-PTIR'!BB:BB) -> -0.0029149193 | BC3: ='O-PTIR'!BC3/MAX('O-PTIR'!BC:BC) -> -0.23782451 | BD3: ='O-PTIR'!BD3/MAX('O-PTIR'!BD:BD) -> -0.19977962 | BE3: ='O-PTIR'!BE3/MAX('O-PTIR'!BE:BE) -> 0.10133146 | BF3: ='O-PTIR'!BF3/MAX('O-PTIR'!BF:BF) -> 0.0051490743 | BG3: ='O-PTIR'!BG3/MAX('O-PTIR'!BG:BG) -> -0.0036830914 | BH3: ='O-PTIR'!BH3/MAX('O-PTIR'!BH:BH) -> 0.015026974 | BI3: ='O-PTIR'!BI3/MAX('O-PTIR'!BI:BI) -> -0.029548171
A4: 952 | B4: ='O-PTIR'!B4/MAX('O-PTIR'!B:B) -> 0.026797156 | C4: ='O-PTIR'!C4/MAX('O-PTIR'!C:C) -> 0.072041008 | D4: ='O-PTIR'!D4/MAX('O-PTIR'!D:D) -> 0.23277832 | E4: ='O-PTIR'!E4/MAX('O-PTIR'!E:E) -> 0.16298702 | F4: ='O-PTIR'!F4/MAX('O-PTIR'!F:F) -> 0.29737133 | G4: ='O-PTIR'!G4/MAX('O-PTIR'!G:G) -> 0.51621435 | H4: ='O-PTIR'!H4/MAX('O-PTIR'!H:H) -> 0.5967884 | I4: ='O-PTIR'!I4/MAX('O-PTIR'!I:I) -> -1.1797728 | J4: ='O-PTIR'!J4/MAX('O-PTIR'!J:J) -> -0.43148272 | K4: ='O-PTIR'!K4/MAX('O-PTIR'!K:K) -> 0.015945649 | L4: ='O-PTIR'!L4/MAX('O-PTIR'!L:L) -> 1 | M4: ='O-PTIR'!M4/MAX('O-PTIR'!M:M) -> 0.0010217738 | N4: ='O-PTIR'!N4/MAX('O-PTIR'!N:N) -> 0.10661592 | O4: ='O-PTIR'!O4/MAX('O-PTIR'!O:O) -> 0.034992069 | P4: ='O-PTIR'!P4/MAX('O-PTIR'!P:P) -> -0.010727576 | Q4: ='O-PTIR'!Q4/MAX('O-PTIR'!Q:Q) -> 0.013584383 | R4: ='O-PTIR'!R4/MAX('O-PTIR'!R:R) -> -0.31280279 | S4: ='O-PTIR'!S4/MAX('O-PTIR'!S:S) -> 0.066921662 | T4: ='O-PTIR'!T4/MAX('O-PTIR'!T:T) -> -0.056729139 | U4: ='O-PTIR'!U4/MAX('O-PTIR'!U:U) -> 0.0026314131 | V4: ='O-PTIR'!V4/MAX('O-PTIR'!V:V) -> 0.0062852282 | W4: ='O-PTIR'!W4/MAX('O-PTIR'!W:W) -> 0.11305078 | X4: ='O-PTIR'!X4/MAX('O-PTIR'!X:X) -> -0.61310323 | Y4: ='O-PTIR'!Y4/MAX('O-PTIR'!Y:Y) -> -0.020047602 | Z4: ='O-PTIR'!Z4/MAX('O-PTIR'!Z:Z) -> 0.054988413 | AA4: ='O-PTIR'!AA4/MAX('O-PTIR'!AA:AA) -> -1.4786496 | AB4: ='O-PTIR'!AB4/MAX('O-PTIR'!AB:AB) -> -0.71404512 | AC4: ='O-PTIR'!AC4/MAX('O-PTIR'!AC:AC) -> -0.077788038 | AD4: ='O-PTIR'!AD4/MAX('O-PTIR'!AD:AD) -> 0.055182655 | AE4: ='O-PTIR'!AE4/MAX('O-PTIR'!AE:AE) -> -0.0018353925 | AF4: ='O-PTIR'!AF4/MAX('O-PTIR'!AF:AF) -> 0.03493924 | AG4: ='O-PTIR'!AG4/MAX('O-PTIR'!AG:AG) -> -0.0207067 | AH4: ='O-PTIR'!AH4/MAX('O-PTIR'!AH:AH) -> -0.011857891 | AI4: ='O-PTIR'!AI4/MAX('O-PTIR'!AI:AI) -> -0.0084182039 | AJ4: ='O-PTIR'!AJ4/MAX('O-PTIR'!AJ:AJ) -> -0.70094657 | AK4: ='O-PTIR'!AK4/MAX('O-PTIR'!AK:AK) -> -0.38179922 | AL4: ='O-PTIR'!AL4/MAX('O-PTIR'!AL:AL) -> 0.31428074 | AM4: ='O-PTIR'!AM4/MAX('O-PTIR'!AM:AM) -> -0.10827638 | AN4: ='O-PTIR'!AN4/MAX('O-PTIR'!AN:AN) -> -0.050523344 | AO4: ='O-PTIR'!AO4/MAX('O-PTIR'!AO:AO) -> 0.0014738181 | AP4: ='O-PTIR'!AP4/MAX('O-PTIR'!AP:AP) -> 0.01554807 | AQ4: ='O-PTIR'!AQ4/MAX('O-PTIR'!AQ:AQ) -> 0.035767481 | AR4: ='O-PTIR'!AR4/MAX('O-PTIR'!AR:AR) -> -0.00071511014 | AS4: ='O-PTIR'!AS4/MAX('O-PTIR'!AS:AS) -> 0.0073092773 | AT4: ='O-PTIR'!AT4/MAX('O-PTIR'!AT:AT) -> -0.00054011603 | AU4: ='O-PTIR'!AU4/MAX('O-PTIR'!AU:AU) -> 0.014522802 | AV4: ='O-PTIR'!AV4/MAX('O-PTIR'!AV:AV) -> 0.0085792075 | AW4: ='O-PTIR'!AW4/MAX('O-PTIR'!AW:AW) -> 0.02324944 | AX4: ='O-PTIR'!AX4/MAX('O-PTIR'!AX:AX) -> -0.013116733 | AY4: ='O-PTIR'!AY4/MAX('O-PTIR'!AY:AY) -> 0.034212915 | AZ4: ='O-PTIR'!AZ4/MAX('O-PTIR'!AZ:AZ) -> -0.009075442 | BA4: ='O-PTIR'!BA4/MAX('O-PTIR'!BA:BA) -> 0.004135984 | BB4: ='O-PTIR'!BB4/MAX('O-PTIR'!BB:BB) -> -0.0037218011 | BC4: ='O-PTIR'!BC4/MAX('O-PTIR'!BC:BC) -> -0.64259107 | BD4: ='O-PTIR'!BD4/MAX('O-PTIR'!BD:BD) -> -0.14357472 | BE4: ='O-PTIR'!BE4/MAX('O-PTIR'!BE:BE) -> 0.011318939 | BF4: ='O-PTIR'!BF4/MAX('O-PTIR'!BF:BF) -> -0.0018080558 | BG4: ='O-PTIR'!BG4/MAX('O-PTIR'!BG:BG) -> -0.0030766189 | BH4: ='O-PTIR'!BH4/MAX('O-PTIR'!BH:BH) -> 0.015534195 | BI4: ='O-PTIR'!BI4/MAX('O-PTIR'!BI:BI) -> -0.024218296
A5: 954 | B5: ='O-PTIR'!B5/MAX('O-PTIR'!B:B) -> 0.16960512 | C5: ='O-PTIR'!C5/MAX('O-PTIR'!C:C) -> 0.043017044 | D5: ='O-PTIR'!D5/MAX('O-PTIR'!D:D) -> 0.18981155 | E5: ='O-PTIR'!E5/MAX('O-PTIR'!E:E) -> 0.10818393 | F5: ='O-PTIR'!F5/MAX('O-PTIR'!F:F) -> -0.89325435 | G5: ='O-PTIR'!G5/MAX('O-PTIR'!G:G) -> 0.23526023 | H5: ='O-PTIR'!H5/MAX('O-PTIR'!H:H) -> 1 | I5: ='O-PTIR'!I5/MAX('O-PTIR'!I:I) -> -0.8894567 | J5: ='O-PTIR'!J5/MAX('O-PTIR'!J:J) -> -0.080362399 | K5: ='O-PTIR'!K5/MAX('O-PTIR'!K:K) -> -0.0046468379 | L5: ='O-PTIR'!L5/MAX('O-PTIR'!L:L) -> 0.62681349 | M5: ='O-PTIR'!M5/MAX('O-PTIR'!M:M) -> 0.00052893173 | N5: ='O-PTIR'!N5/MAX('O-PTIR'!N:N) -> 0.14312782 | O5: ='O-PTIR'!O5/MAX('O-PTIR'!O:O) -> -0.052436157 | P5: ='O-PTIR'!P5/MAX('O-PTIR'!P:P) -> -0.065474585 | Q5: ='O-PTIR'!Q5/MAX('O-PTIR'!Q:Q) -> 0.0022456236 | R5: ='O-PTIR'!R5/MAX('O-PTIR'!R:R) -> -0.39691021 | S5: ='O-PTIR'!S5/MAX('O-PTIR'!S:S) -> 0.044659715 | T5: ='O-PTIR'!T5/MAX('O-PTIR'!T:T) -> -0.041585363 | U5: ='O-PTIR'!U5/MAX('O-PTIR'!U:U) -> 0.00709098 | V5: ='O-PTIR'!V5/MAX('O-PTIR'!V:V) -> 0.031502756 | W5: ='O-PTIR'!W5/MAX('O-PTIR'!W:W) -> -0.018754836 | X5: ='O-PTIR'!X5/MAX('O-PTIR'!X:X) -> -0.17109323 | Y5: ='O-PTIR'!Y5/MAX('O-PTIR'!Y:Y) -> 0.0071472149 | Z5: ='O-PTIR'!Z5/MAX('O-PTIR'!Z:Z) -> 0.090177475 | AA5: ='O-PTIR'!AA5/MAX('O-PTIR'!AA:AA) -> 0.22485363 | AB5: ='O-PTIR'!AB5/MAX('O-PTIR'!AB:AB) -> -0.33747686 | AC5: ='O-PTIR'!AC5/MAX('O-PTIR'!AC:AC) -> -0.057877685 | AD5: ='O-PTIR'!AD5/MAX('O-PTIR'!AD:AD) -> 0.023941578 | AE5: ='O-PTIR'!AE5/MAX('O-PTIR'!AE:AE) -> -0.010791264 | AF5: ='O-PTIR'!AF5/MAX('O-PTIR'!AF:AF) -> 0.021059303 | AG5: ='O-PTIR'!AG5/MAX('O-PTIR'!AG:AG) -> 0.0079040844 | AH5: ='O-PTIR'!AH5/MAX('O-PTIR'!AH:AH) -> -0.014793772 | AI5: ='O-PTIR'!AI5/MAX('O-PTIR'!AI:AI) -> -0.017874235 | AJ5: ='O-PTIR'!AJ5/MAX('O-PTIR'!AJ:AJ) -> -0.54918783 | AK5: ='O-PTIR'!AK5/MAX('O-PTIR'!AK:AK) -> -0.74956549 | AL5: ='O-PTIR'!AL5/MAX('O-PTIR'!AL:AL) -> 0.2064329 | AM5: ='O-PTIR'!AM5/MAX('O-PTIR'!AM:AM) -> -0.15082679 | AN5: ='O-PTIR'!AN5/MAX('O-PTIR'!AN:AN) -> -0.0070858664 | AO5: ='O-PTIR'!AO5/MAX('O-PTIR'!AO:AO) -> 0.006166322 | AP5: ='O-PTIR'!AP5/MAX('O-PTIR'!AP:AP) -> 0.0095539723 | AQ5: ='O-PTIR'!AQ5/MAX('O-PTIR'!AQ:AQ) -> 0.015252371 | AR5: ='O-PTIR'!AR5/MAX('O-PTIR'!AR:AR) -> 0.0071264138 | AS5: ='O-PTIR'!AS5/MAX('O-PTIR'!AS:AS) -> 0.0017160755 | AT5: ='O-PTIR'!AT5/MAX('O-PTIR'!AT:AT) -> -0.0026561727 | AU5: ='O-PTIR'!AU5/MAX('O-PTIR'!AU:AU) -> -0.022300247 | AV5: ='O-PTIR'!AV5/MAX('O-PTIR'!AV:AV) -> -0.0082668522 | AW5: ='O-PTIR'!AW5/MAX('O-PTIR'!AW:AW) -> 0.0050330126 | AX5: ='O-PTIR'!AX5/MAX('O-PTIR'!AX:AX) -> -0.0078021691 | AY5: ='O-PTIR'!AY5/MAX('O-PTIR'!AY:AY) -> -0.30664316 | AZ5: ='O-PTIR'!AZ5/MAX('O-PTIR'!AZ:AZ) -> -0.01412126 | BA5: ='O-PTIR'!BA5/MAX('O-PTIR'!BA:BA) -> 0.029222645 | BB5: ='O-PTIR'!BB5/MAX('O-PTIR'!BB:BB) -> -0.0028397192 | BC5: ='O-PTIR'!BC5/MAX('O-PTIR'!BC:BC) -> -0.085550837 | BD5: ='O-PTIR'!BD5/MAX('O-PTIR'!BD:BD) -> -0.056006596 | BE5: ='O-PTIR'!BE5/MAX('O-PTIR'!BE:BE) -> -0.037086129 | BF5: ='O-PTIR'!BF5/MAX('O-PTIR'!BF:BF) -> 0.0053040095 | BG5: ='O-PTIR'!BG5/MAX('O-PTIR'!BG:BG) -> -0.001054126 | BH5: ='O-PTIR'!BH5/MAX('O-PTIR'!BH:BH) -> 0.017951491 | BI5: ='O-PTIR'!BI5/MAX('O-PTIR'!BI:BI) -> -0.015816593
A6: 956 | B6: ='O-PTIR'!B6/MAX('O-PTIR'!B:B) -> 0.1940449 | C6: ='O-PTIR'!C6/MAX('O-PTIR'!C:C) -> 0.0046384551 | D6: ='O-PTIR'!D6/MAX('O-PTIR'!D:D) -> 0.18156539 | E6: ='O-PTIR'!E6/MAX('O-PTIR'!E:E) -> 0.12192872 | F6: ='O-PTIR'!F6/MAX('O-PTIR'!F:F) -> -0.51711291 | G6: ='O-PTIR'!G6/MAX('O-PTIR'!G:G) -> 0.39376422 | H6: ='O-PTIR'!H6/MAX('O-PTIR'!H:H) -> 0.74781361 | I6: ='O-PTIR'!I6/MAX('O-PTIR'!I:I) -> -0.99572947 | J6: ='O-PTIR'!J6/MAX('O-PTIR'!J:J) -> -0.12433994 | K6: ='O-PTIR'!K6/MAX('O-PTIR'!K:K) -> -0.0087832674 | L6: ='O-PTIR'!L6/MAX('O-PTIR'!L:L) -> 0.25641486 | M6: ='O-PTIR'!M6/MAX('O-PTIR'!M:M) -> -0.0015545851 | N6: ='O-PTIR'!N6/MAX('O-PTIR'!N:N) -> 0.18901797 | O6: ='O-PTIR'!O6/MAX('O-PTIR'!O:O) -> 0.11346963 | P6: ='O-PTIR'!P6/MAX('O-PTIR'!P:P) -> -0.044227318 | Q6: ='O-PTIR'!Q6/MAX('O-PTIR'!Q:Q) -> -0.004000237 | R6: ='O-PTIR'!R6/MAX('O-PTIR'!R:R) -> -0.61090323 | S6: ='O-PTIR'!S6/MAX('O-PTIR'!S:S) -> -0.0077607021 | T6: ='O-PTIR'!T6/MAX('O-PTIR'!T:T) -> -0.027480941 | U6: ='O-PTIR'!U6/MAX('O-PTIR'!U:U) -> 0.013036889 | V6: ='O-PTIR'!V6/MAX('O-PTIR'!V:V) -> -0.026420569 | W6: ='O-PTIR'!W6/MAX('O-PTIR'!W:W) -> -0.01296716 | X6: ='O-PTIR'!X6/MAX('O-PTIR'!X:X) -> -0.55864775 | Y6: ='O-PTIR'!Y6/MAX('O-PTIR'!Y:Y) -> -0.00036352326 | Z6: ='O-PTIR'!Z6/MAX('O-PTIR'!Z:Z) -> -0.0032020842 | AA6: ='O-PTIR'!AA6/MAX('O-PTIR'!AA:AA) -> 0.23500046 | AB6: ='O-PTIR'!AB6/MAX('O-PTIR'!AB:AB) -> -0.16543512 | AC6: ='O-PTIR'!AC6/MAX('O-PTIR'!AC:AC) -> -0.041396778 | AD6: ='O-PTIR'!AD6/MAX('O-PTIR'!AD:AD) -> 0.0047579686 | AE6: ='O-PTIR'!AE6/MAX('O-PTIR'!AE:AE) -> -0.0030840156 | AF6: ='O-PTIR'!AF6/MAX('O-PTIR'!AF:AF) -> 0.019626395 | AG6: ='O-PTIR'!AG6/MAX('O-PTIR'!AG:AG) -> 0.016957596 | AH6: ='O-PTIR'!AH6/MAX('O-PTIR'!AH:AH) -> 0.007814074 | AI6: ='O-PTIR'!AI6/MAX('O-PTIR'!AI:AI) -> -0.017380539 | AJ6: ='O-PTIR'!AJ6/MAX('O-PTIR'!AJ:AJ) -> -0.85551081 | AK6: ='O-PTIR'!AK6/MAX('O-PTIR'!AK:AK) -> -0.49189485 | AL6: ='O-PTIR'!AL6/MAX('O-PTIR'!AL:AL) -> 0.056076211 | AM6: ='O-PTIR'!AM6/MAX('O-PTIR'!AM:AM) -> -0.096221172 | AN6: ='O-PTIR'!AN6/MAX('O-PTIR'!AN:AN) -> -0.030548977 | AO6: ='O-PTIR'!AO6/MAX('O-PTIR'!AO:AO) -> 0.0053494029 | AP6: ='O-PTIR'!AP6/MAX('O-PTIR'!AP:AP) -> 0.010715746 | AQ6: ='O-PTIR'!AQ6/MAX('O-PTIR'!AQ:AQ) -> 0.0010251967 | AR6: ='O-PTIR'!AR6/MAX('O-PTIR'!AR:AR) -> -0.016008036 | AS6: ='O-PTIR'!AS6/MAX('O-PTIR'!AS:AS) -> 0.019390224 | AT6: ='O-PTIR'!AT6/MAX('O-PTIR'!AT:AT) -> -0.0013809277 | AU6: ='O-PTIR'!AU6/MAX('O-PTIR'!AU:AU) -> 0.0035183135 | AV6: ='O-PTIR'!AV6/MAX('O-PTIR'!AV:AV) -> -0.018336034 | AW6: ='O-PTIR'!AW6/MAX('O-PTIR'!AW:AW) -> 0.0098879188 | AX6: ='O-PTIR'!AX6/MAX('O-PTIR'!AX:AX) -> -0.0035501256 | AY6: ='O-PTIR'!AY6/MAX('O-PTIR'!AY:AY) -> -0.47310911 | AZ6: ='O-PTIR'!AZ6/MAX('O-PTIR'!AZ:AZ) -> -0.0049858502 | BA6: ='O-PTIR'!BA6/MAX('O-PTIR'!BA:BA) -> -0.010280812 | BB6: ='O-PTIR'!BB6/MAX('O-PTIR'!BB:BB) -> -0.0058498958 | BC6: ='O-PTIR'!BC6/MAX('O-PTIR'!BC:BC) -> 0.20743997 | BD6: ='O-PTIR'!BD6/MAX('O-PTIR'!BD:BD) -> -0.13639243 | BE6: ='O-PTIR'!BE6/MAX('O-PTIR'!BE:BE) -> -0.19628494 | BF6: ='O-PTIR'!BF6/MAX('O-PTIR'!BF:BF) -> -0.0018458675 | BG6: ='O-PTIR'!BG6/MAX('O-PTIR'!BG:BG) -> -4.2431302e-05 | BH6: ='O-PTIR'!BH6/MAX('O-PTIR'!BH:BH) -> -0.0040029828 | BI6: ='O-PTIR'!BI6/MAX('O-PTIR'!BI:BI) -> -0.0095755315
A7: 958 | B7: ='O-PTIR'!B7/MAX('O-PTIR'!B:B) -> -0.016845544 | C7: ='O-PTIR'!C7/MAX('O-PTIR'!C:C) -> -0.032357522 | D7: ='O-PTIR'!D7/MAX('O-PTIR'!D:D) -> 0.041803035 | E7: ='O-PTIR'!E7/MAX('O-PTIR'!E:E) -> 0.23266011 | F7: ='O-PTIR'!F7/MAX('O-PTIR'!F:F) -> -0.35711872 | G7: ='O-PTIR'!G7/MAX('O-PTIR'!G:G) -> 0.23205037 | H7: ='O-PTIR'!H7/MAX('O-PTIR'!H:H) -> -1.1118178 | I7: ='O-PTIR'!I7/MAX('O-PTIR'!I:I) -> -0.53620983 | J7: ='O-PTIR'!J7/MAX('O-PTIR'!J:J) -> -0.29055874 | K7: ='O-PTIR'!K7/MAX('O-PTIR'!K:K) -> -0.026126107 | L7: ='O-PTIR'!L7/MAX('O-PTIR'!L:L) -> 0.45614458 | M7: ='O-PTIR'!M7/MAX('O-PTIR'!M:M) -> 0.00018998598 | N7: ='O-PTIR'!N7/MAX('O-PTIR'!N:N) -> 0.0041517913 | O7: ='O-PTIR'!O7/MAX('O-PTIR'!O:O) -> 0.19192142 | P7: ='O-PTIR'!P7/MAX('O-PTIR'!P:P) -> -0.038719286 | Q7: ='O-PTIR'!Q7/MAX('O-PTIR'!Q:Q) -> 0.0090495073 | R7: ='O-PTIR'!R7/MAX('O-PTIR'!R:R) -> -0.76954918 | S7: ='O-PTIR'!S7/MAX('O-PTIR'!S:S) -> 0.029697992 | T7: ='O-PTIR'!T7/MAX('O-PTIR'!T:T) -> -0.032336057 | U7: ='O-PTIR'!U7/MAX('O-PTIR'!U:U) -> 0.0041648687 | V7: ='O-PTIR'!V7/MAX('O-PTIR'!V:V) -> -0.015197319 | W7: ='O-PTIR'!W7/MAX('O-PTIR'!W:W) -> 0.035443509 | X7: ='O-PTIR'!X7/MAX('O-PTIR'!X:X) -> -0.13175288 | Y7: ='O-PTIR'!Y7/MAX('O-PTIR'!Y:Y) -> 0.0096334841 | Z7: ='O-PTIR'!Z7/MAX('O-PTIR'!Z:Z) -> -0.14065944 | AA7: ='O-PTIR'!AA7/MAX('O-PTIR'!AA:AA) -> 0.45042936 | AB7: ='O-PTIR'!AB7/MAX('O-PTIR'!AB:AB) -> 0.099020256 | AC7: ='O-PTIR'!AC7/MAX('O-PTIR'!AC:AC) -> -0.041247434 | AD7: ='O-PTIR'!AD7/MAX('O-PTIR'!AD:AD) -> 0.024939701 | AE7: ='O-PTIR'!AE7/MAX('O-PTIR'!AE:AE) -> -0.0030518491 | AF7: ='O-PTIR'!AF7/MAX('O-PTIR'!AF:AF) -> 0.0033284634 | AG7: ='O-PTIR'!AG7/MAX('O-PTIR'!AG:AG) -> 0.010147965 | AH7: ='O-PTIR'!AH7/MAX('O-PTIR'!AH:AH) -> 0.011407591 | AI7: ='O-PTIR'!AI7/MAX('O-PTIR'!AI:AI) -> -0.053467916 | AJ7: ='O-PTIR'!AJ7/MAX('O-PTIR'!AJ:AJ) -> -0.7369983 | AK7: ='O-PTIR'!AK7/MAX('O-PTIR'!AK:AK) -> -0.078922032 | AL7: ='O-PTIR'!AL7/MAX('O-PTIR'!AL:AL) -> 0.014614427 | AM7: ='O-PTIR'!AM7/MAX('O-PTIR'!AM:AM) -> -0.0610213 | AN7: ='O-PTIR'!AN7/MAX('O-PTIR'!AN:AN) -> -0.012619196 | AO7: ='O-PTIR'!AO7/MAX('O-PTIR'!AO:AO) -> 0.0055692628 | AP7: ='O-PTIR'!AP7/MAX('O-PTIR'!AP:AP) -> 0.0054530286 | AQ7: ='O-PTIR'!AQ7/MAX('O-PTIR'!AQ:AQ) -> 0.0084831384 | AR7: ='O-PTIR'!AR7/MAX('O-PTIR'!AR:AR) -> -0.020599668 | AS7: ='O-PTIR'!AS7/MAX('O-PTIR'!AS:AS) -> -0.01065494 | AT7: ='O-PTIR'!AT7/MAX('O-PTIR'!AT:AT) -> -0.00010660419 | AU7: ='O-PTIR'!AU7/MAX('O-PTIR'!AU:AU) -> 0.0046164957 | AV7: ='O-PTIR'!AV7/MAX('O-PTIR'!AV:AV) -> -0.015741991 | AW7: ='O-PTIR'!AW7/MAX('O-PTIR'!AW:AW) -> 0.015508577 | AX7: ='O-PTIR'!AX7/MAX('O-PTIR'!AX:AX) -> -0.0016688842 | AY7: ='O-PTIR'!AY7/MAX('O-PTIR'!AY:AY) -> -0.0056899296 | AZ7: ='O-PTIR'!AZ7/MAX('O-PTIR'!AZ:AZ) -> 0.0054009144 | BA7: ='O-PTIR'!BA7/MAX('O-PTIR'!BA:BA) -> -0.011737838 | BB7: ='O-PTIR'!BB7/MAX('O-PTIR'!BB:BB) -> -0.0058794577 | BC7: ='O-PTIR'!BC7/MAX('O-PTIR'!BC:BC) -> -0.20255146 | BD7: ='O-PTIR'!BD7/MAX('O-PTIR'!BD:BD) -> -0.09961328 | BE7: ='O-PTIR'!BE7/MAX('O-PTIR'!BE:BE) -> -0.11693382 | BF7: ='O-PTIR'!BF7/MAX('O-PTIR'!BF:BF) -> -0.0084743696 | BG7: ='O-PTIR'!BG7/MAX('O-PTIR'!BG:BG) -> -0.00060188823 | BH7: ='O-PTIR'!BH7/MAX('O-PTIR'!BH:BH) -> 0.0022328538 | BI7: ='O-PTIR'!BI7/MAX('O-PTIR'!BI:BI) -> -0.0012679336
A8: 960 | B8: ='O-PTIR'!B8/MAX('O-PTIR'!B:B) -> 0.11691427 | C8: ='O-PTIR'!C8/MAX('O-PTIR'!C:C) -> 0.0044911368 | D8: ='O-PTIR'!D8/MAX('O-PTIR'!D:D) -> 0.057336963 | E8: ='O-PTIR'!E8/MAX('O-PTIR'!E:E) -> 0.11077782 | F8: ='O-PTIR'!F8/MAX('O-PTIR'!F:F) -> -0.51249924 | G8: ='O-PTIR'!G8/MAX('O-PTIR'!G:G) -> 0.10032692 | H8: ='O-PTIR'!H8/MAX('O-PTIR'!H:H) -> -1.8676475 | I8: ='O-PTIR'!I8/MAX('O-PTIR'!I:I) -> -0.86830498 | J8: ='O-PTIR'!J8/MAX('O-PTIR'!J:J) -> -0.03625622 | K8: ='O-PTIR'!K8/MAX('O-PTIR'!K:K) -> -0.020365718 | L8: ='O-PTIR'!L8/MAX('O-PTIR'!L:L) -> 0.10456542 | M8: ='O-PTIR'!M8/MAX('O-PTIR'!M:M) -> -0.00049310703 | N8: ='O-PTIR'!N8/MAX('O-PTIR'!N:N) -> 0.17192215 | O8: ='O-PTIR'!O8/MAX('O-PTIR'!O:O) -> -0.043569385 | P8: ='O-PTIR'!P8/MAX('O-PTIR'!P:P) -> -0.070723983 | Q8: ='O-PTIR'!Q8/MAX('O-PTIR'!Q:Q) -> 0.005343249 | R8: ='O-PTIR'!R8/MAX('O-PTIR'!R:R) -> 0.085547038 | S8: ='O-PTIR'!S8/MAX('O-PTIR'!S:S) -> 0.015480747 | T8: ='O-PTIR'!T8/MAX('O-PTIR'!T:T) -> -0.043116326 | U8: ='O-PTIR'!U8/MAX('O-PTIR'!U:U) -> 0.0027962329 | V8: ='O-PTIR'!V8/MAX('O-PTIR'!V:V) -> -0.019773203 | W8: ='O-PTIR'!W8/MAX('O-PTIR'!W:W) -> -0.0010406777 | X8: ='O-PTIR'!X8/MAX('O-PTIR'!X:X) -> -0.086094662 | Y8: ='O-PTIR'!Y8/MAX('O-PTIR'!Y:Y) -> 0.017329356 | Z8: ='O-PTIR'!Z8/MAX('O-PTIR'!Z:Z) -> -0.083083628 | AA8: ='O-PTIR'!AA8/MAX('O-PTIR'!AA:AA) -> 0.056063588 | AB8: ='O-PTIR'!AB8/MAX('O-PTIR'!AB:AB) -> 0.016418927 | AC8: ='O-PTIR'!AC8/MAX('O-PTIR'!AC:AC) -> -0.064617824 | AD8: ='O-PTIR'!AD8/MAX('O-PTIR'!AD:AD) -> 0.0052979198 | AE8: ='O-PTIR'!AE8/MAX('O-PTIR'!AE:AE) -> -0.0076011641 | AF8: ='O-PTIR'!AF8/MAX('O-PTIR'!AF:AF) -> -0.006731261 | AG8: ='O-PTIR'!AG8/MAX('O-PTIR'!AG:AG) -> -0.0054221445 | AH8: ='O-PTIR'!AH8/MAX('O-PTIR'!AH:AH) -> 0.0061526227 | AI8: ='O-PTIR'!AI8/MAX('O-PTIR'!AI:AI) -> -0.027379105 | AJ8: ='O-PTIR'!AJ8/MAX('O-PTIR'!AJ:AJ) -> -0.68931571 | AK8: ='O-PTIR'!AK8/MAX('O-PTIR'!AK:AK) -> -0.33710933 | AL8: ='O-PTIR'!AL8/MAX('O-PTIR'!AL:AL) -> -0.056491277 | AM8: ='O-PTIR'!AM8/MAX('O-PTIR'!AM:AM) -> 0.0002141652 | AN8: ='O-PTIR'!AN8/MAX('O-PTIR'!AN:AN) -> -0.0058831236 | AO8: ='O-PTIR'!AO8/MAX('O-PTIR'!AO:AO) -> 0.0052938442 | AP8: ='O-PTIR'!AP8/MAX('O-PTIR'!AP:AP) -> 0.005763851 | AQ8: ='O-PTIR'!AQ8/MAX('O-PTIR'!AQ:AQ) -> 0.0084975692 | AR8: ='O-PTIR'!AR8/MAX('O-PTIR'!AR:AR) -> -0.012124938 | AS8: ='O-PTIR'!AS8/MAX('O-PTIR'!AS:AS) -> -0.0082797017 | AT8: ='O-PTIR'!AT8/MAX('O-PTIR'!AT:AT) -> -0.00038084645 | AU8: ='O-PTIR'!AU8/MAX('O-PTIR'!AU:AU) -> 0.0032334949 | AV8: ='O-PTIR'!AV8/MAX('O-PTIR'!AV:AV) -> -0.0095364401 | AW8: ='O-PTIR'!AW8/MAX('O-PTIR'!AW:AW) -> 0.0016930355 | AX8: ='O-PTIR'!AX8/MAX('O-PTIR'!AX:AX) -> 0.0018693263 | AY8: ='O-PTIR'!AY8/MAX('O-PTIR'!AY:AY) -> -0.07717575 | AZ8: ='O-PTIR'!AZ8/MAX('O-PTIR'!AZ:AZ) -> -0.0021427543 | BA8: ='O-PTIR'!BA8/MAX('O-PTIR'!BA:BA) -> -0.0092910724 | BB8: ='O-PTIR'!BB8/MAX('O-PTIR'!BB:BB) -> -0.0039681293 | BC8: ='O-PTIR'!BC8/MAX('O-PTIR'!BC:BC) -> 0.085394062 | BD8: ='O-PTIR'!BD8/MAX('O-PTIR'!BD:BD) -> -0.012245679 | BE8: ='O-PTIR'!BE8/MAX('O-PTIR'!BE:BE) -> -0.1230886 | BF8: ='O-PTIR'!BF8/MAX('O-PTIR'!BF:BF) -> 0.0054084806 | BG8: ='O-PTIR'!BG8/MAX('O-PTIR'!BG:BG) -> -0.00040488691 | BH8: ='O-PTIR'!BH8/MAX('O-PTIR'!BH:BH) -> 0.0041485033 | BI8: ='O-PTIR'!BI8/MAX('O-PTIR'!BI:BI) -> 0.0026994615
A9: 962 | B9: ='O-PTIR'!B9/MAX('O-PTIR'!B:B) -> 0.064095013 | C9: ='O-PTIR'!C9/MAX('O-PTIR'!C:C) -> 0.049881944 | D9: ='O-PTIR'!D9/MAX('O-PTIR'!D:D) -> 0.096819358 | E9: ='O-PTIR'!E9/MAX('O-PTIR'!E:E) -> 0.26914673 | F9: ='O-PTIR'!F9/MAX('O-PTIR'!F:F) -> -0.74482653 | G9: ='O-PTIR'!G9/MAX('O-PTIR'!G:G) -> 0.37855411 | H9: ='O-PTIR'!H9/MAX('O-PTIR'!H:H) -> -0.32737616 | I9: ='O-PTIR'!I9/MAX('O-PTIR'!I:I) -> -0.57490321 | J9: ='O-PTIR'!J9/MAX('O-PTIR'!J:J) -> -0.0026062238 | K9: ='O-PTIR'!K9/MAX('O-PTIR'!K:K) -> 0.0099138934 | L9: ='O-PTIR'!L9/MAX('O-PTIR'!L:L) -> 0.090120484 | M9: ='O-PTIR'!M9/MAX('O-PTIR'!M:M) -> 0.00030596106 | N9: ='O-PTIR'!N9/MAX('O-PTIR'!N:N) -> 0.22420988 | O9: ='O-PTIR'!O9/MAX('O-PTIR'!O:O) -> -0.16031898 | P9: ='O-PTIR'!P9/MAX('O-PTIR'!P:P) -> -0.021298978 | Q9: ='O-PTIR'!Q9/MAX('O-PTIR'!Q:Q) -> 0.0023752495 | R9: ='O-PTIR'!R9/MAX('O-PTIR'!R:R) -> 0.22126533 | S9: ='O-PTIR'!S9/MAX('O-PTIR'!S:S) -> -0.0015628825 | T9: ='O-PTIR'!T9/MAX('O-PTIR'!T:T) -> -0.023946657 | U9: ='O-PTIR'!U9/MAX('O-PTIR'!U:U) -> 0.0027181312 | V9: ='O-PTIR'!V9/MAX('O-PTIR'!V:V) -> -0.047886263 | W9: ='O-PTIR'!W9/MAX('O-PTIR'!W:W) -> -0.0052341062 | X9: ='O-PTIR'!X9/MAX('O-PTIR'!X:X) -> -0.060009424 | Y9: ='O-PTIR'!Y9/MAX('O-PTIR'!Y:Y) -> 0.013991994 | Z9: ='O-PTIR'!Z9/MAX('O-PTIR'!Z:Z) -> -0.0067428257 | AA9: ='O-PTIR'!AA9/MAX('O-PTIR'!AA:AA) -> -0.036679 | AB9: ='O-PTIR'!AB9/MAX('O-PTIR'!AB:AB) -> 0.32158333 | AC9: ='O-PTIR'!AC9/MAX('O-PTIR'!AC:AC) -> -0.034970561 | AD9: ='O-PTIR'!AD9/MAX('O-PTIR'!AD:AD) -> 0.0038220892 | AE9: ='O-PTIR'!AE9/MAX('O-PTIR'!AE:AE) -> -0.0048770617 | AF9: ='O-PTIR'!AF9/MAX('O-PTIR'!AF:AF) -> -0.0031878908 | AG9: ='O-PTIR'!AG9/MAX('O-PTIR'!AG:AG) -> 0.0056699163 | AH9: ='O-PTIR'!AH9/MAX('O-PTIR'!AH:AH) -> -0.0024599474 | AI9: ='O-PTIR'!AI9/MAX('O-PTIR'!AI:AI) -> -0.00018002763 | AJ9: ='O-PTIR'!AJ9/MAX('O-PTIR'!AJ:AJ) -> -0.42210967 | AK9: ='O-PTIR'!AK9/MAX('O-PTIR'!AK:AK) -> -0.31083839 | AL9: ='O-PTIR'!AL9/MAX('O-PTIR'!AL:AL) -> 0.057680981 | AM9: ='O-PTIR'!AM9/MAX('O-PTIR'!AM:AM) -> -0.026945677 | AN9: ='O-PTIR'!AN9/MAX('O-PTIR'!AN:AN) -> 0.017629406 | AO9: ='O-PTIR'!AO9/MAX('O-PTIR'!AO:AO) -> 0.0031684969 | AP9: ='O-PTIR'!AP9/MAX('O-PTIR'!AP:AP) -> 0.0031157982 | AQ9: ='O-PTIR'!AQ9/MAX('O-PTIR'!AQ:AQ) -> 0.010300307 | AR9: ='O-PTIR'!AR9/MAX('O-PTIR'!AR:AR) -> 0.0096554281 | AS9: ='O-PTIR'!AS9/MAX('O-PTIR'!AS:AS) -> -0.0066257592 | AT9: ='O-PTIR'!AT9/MAX('O-PTIR'!AT:AT) -> -6.7837019e-05 | AU9: ='O-PTIR'!AU9/MAX('O-PTIR'!AU:AU) -> 0.016531297 | AV9: ='O-PTIR'!AV9/MAX('O-PTIR'!AV:AV) -> 0.0045684163 | AW9: ='O-PTIR'!AW9/MAX('O-PTIR'!AW:AW) -> -0.0066786387 | AX9: ='O-PTIR'!AX9/MAX('O-PTIR'!AX:AX) -> 0.0019645737 | AY9: ='O-PTIR'!AY9/MAX('O-PTIR'!AY:AY) -> -0.050597185 | AZ9: ='O-PTIR'!AZ9/MAX('O-PTIR'!AZ:AZ) -> 0.0060727414 | BA9: ='O-PTIR'!BA9/MAX('O-PTIR'!BA:BA) -> -0.017319527 | BB9: ='O-PTIR'!BB9/MAX('O-PTIR'!BB:BB) -> -0.005402214 | BC9: ='O-PTIR'!BC9/MAX('O-PTIR'!BC:BC) -> -0.020398673 | BD9: ='O-PTIR'!BD9/MAX('O-PTIR'!BD:BD) -> -0.085628073 | BE9: ='O-PTIR'!BE9/MAX('O-PTIR'!BE:BE) -> 0.02242658 | BF9: ='O-PTIR'!BF9/MAX('O-PTIR'!BF:BF) -> 0.0012857754 | BG9: ='O-PTIR'!BG9/MAX('O-PTIR'!BG:BG) -> -0.00032554702 | BH9: ='O-PTIR'!BH9/MAX('O-PTIR'!BH:BH) -> -0.0056797684 | BI9: ='O-PTIR'!BI9/MAX('O-PTIR'!BI:BI) -> -0.0049257315
A10: 964 | B10: ='O-PTIR'!B10/MAX('O-PTIR'!B:B) -> 0.14758805 | C10: ='O-PTIR'!C10/MAX('O-PTIR'!C:C) -> 0.042593889 | D10: ='O-PTIR'!D10/MAX('O-PTIR'!D:D) -> 0.11400462 | E10: ='O-PTIR'!E10/MAX('O-PTIR'!E:E) -> -0.048542674 | F10: ='O-PTIR'!F10/MAX('O-PTIR'!F:F) -> -0.32909759 | G10: ='O-PTIR'!G10/MAX('O-PTIR'!G:G) -> 0.26378777 | H10: ='O-PTIR'!H10/MAX('O-PTIR'!H:H) -> -0.57538543 | I10: ='O-PTIR'!I10/MAX('O-PTIR'!I:I) -> -0.23112286 | J10: ='O-PTIR'!J10/MAX('O-PTIR'!J:J) -> 0.13356257 | K10: ='O-PTIR'!K10/MAX('O-PTIR'!K:K) -> -0.0012368268 | L10: ='O-PTIR'!L10/MAX('O-PTIR'!L:L) -> -0.076014404 | M10: ='O-PTIR'!M10/MAX('O-PTIR'!M:M) -> 0.00025154995 | N10: ='O-PTIR'!N10/MAX('O-PTIR'!N:N) -> 0.25546384 | O10: ='O-PTIR'!O10/MAX('O-PTIR'!O:O) -> -0.13631867 | P10: ='O-PTIR'!P10/MAX('O-PTIR'!P:P) -> -0.0012935201 | Q10: ='O-PTIR'!Q10/MAX('O-PTIR'!Q:Q) -> 0.00092227916 | R10: ='O-PTIR'!R10/MAX('O-PTIR'!R:R) -> 0.065253573 | S10: ='O-PTIR'!S10/MAX('O-PTIR'!S:S) -> -0.0078113237 | T10: ='O-PTIR'!T10/MAX('O-PTIR'!T:T) -> -0.019089963 | U10: ='O-PTIR'!U10/MAX('O-PTIR'!U:U) -> 0.0034673642 | V10: ='O-PTIR'!V10/MAX('O-PTIR'!V:V) -> -0.022335324 | W10: ='O-PTIR'!W10/MAX('O-PTIR'!W:W) -> 0.015070716 | X10: ='O-PTIR'!X10/MAX('O-PTIR'!X:X) -> -0.090090714 | Y10: ='O-PTIR'!Y10/MAX('O-PTIR'!Y:Y) -> 0.011981137 | Z10: ='O-PTIR'!Z10/MAX('O-PTIR'!Z:Z) -> -0.02887701 | AA10: ='O-PTIR'!AA10/MAX('O-PTIR'!AA:AA) -> -0.046000187 | AB10: ='O-PTIR'!AB10/MAX('O-PTIR'!AB:AB) -> -0.04535587 | AC10: ='O-PTIR'!AC10/MAX('O-PTIR'!AC:AC) -> -0.021454704 | AD10: ='O-PTIR'!AD10/MAX('O-PTIR'!AD:AD) -> 0.017070143 | AE10: ='O-PTIR'!AE10/MAX('O-PTIR'!AE:AE) -> 0.0023093183 | AF10: ='O-PTIR'!AF10/MAX('O-PTIR'!AF:AF) -> 0.0086958547 | AG10: ='O-PTIR'!AG10/MAX('O-PTIR'!AG:AG) -> -0.0035702453 | AH10: ='O-PTIR'!AH10/MAX('O-PTIR'!AH:AH) -> -0.0088421004 | AI10: ='O-PTIR'!AI10/MAX('O-PTIR'!AI:AI) -> 0.026100645 | AJ10: ='O-PTIR'!AJ10/MAX('O-PTIR'!AJ:AJ) -> -0.29104804 | AK10: ='O-PTIR'!AK10/MAX('O-PTIR'!AK:AK) -> -0.3216454 | AL10: ='O-PTIR'!AL10/MAX('O-PTIR'!AL:AL) -> -0.0050456557 | AM10: ='O-PTIR'!AM10/MAX('O-PTIR'!AM:AM) -> -0.0050790549 | AN10: ='O-PTIR'!AN10/MAX('O-PTIR'!AN:AN) -> 0.0028039484 | AO10: ='O-PTIR'!AO10/MAX('O-PTIR'!AO:AO) -> -0.0027594491 | AP10: ='O-PTIR'!AP10/MAX('O-PTIR'!AP:AP) -> -0.00099519082 | AQ10: ='O-PTIR'!AQ10/MAX('O-PTIR'!AQ:AQ) -> 0.0030142471 | AR10: ='O-PTIR'!AR10/MAX('O-PTIR'!AR:AR) -> 0.0065435317 | AS10: ='O-PTIR'!AS10/MAX('O-PTIR'!AS:AS) -> 0.0011259696 | AT10: ='O-PTIR'!AT10/MAX('O-PTIR'!AT:AT) -> -8.2713288e-05 | AU10: ='O-PTIR'!AU10/MAX('O-PTIR'!AU:AU) -> 0.0078288415 | AV10: ='O-PTIR'!AV10/MAX('O-PTIR'!AV:AV) -> 0.0069809414 | AW10: ='O-PTIR'!AW10/MAX('O-PTIR'!AW:AW) -> -0.0076570635 | AX10: ='O-PTIR'!AX10/MAX('O-PTIR'!AX:AX) -> -0.0032838731 | AY10: ='O-PTIR'!AY10/MAX('O-PTIR'!AY:AY) -> -0.059714237 | AZ10: ='O-PTIR'!AZ10/MAX('O-PTIR'!AZ:AZ) -> 0.0017169755 | BA10: ='O-PTIR'!BA10/MAX('O-PTIR'!BA:BA) -> 0.00079047143 | BB10: ='O-PTIR'!BB10/MAX('O-PTIR'!BB:BB) -> -0.001686429 | BC10: ='O-PTIR'!BC10/MAX('O-PTIR'!BC:BC) -> 0.17065712 | BD10: ='O-PTIR'!BD10/MAX('O-PTIR'!BD:BD) -> -0.078304005 | BE10: ='O-PTIR'!BE10/MAX('O-PTIR'!BE:BE) -> 0.025891461 | BF10: ='O-PTIR'!BF10/MAX('O-PTIR'!BF:BF) -> -0.00095123715 | BG10: ='O-PTIR'!BG10/MAX('O-PTIR'!BG:BG) -> -0.00033264673 | BH10: ='O-PTIR'!BH10/MAX('O-PTIR'!BH:BH) -> -0.00051922528 | BI10: ='O-PTIR'!BI10/MAX('O-PTIR'!BI:BI) -> -0.0040554978
A11: 966 | B11: ='O-PTIR'!B11/MAX('O-PTIR'!B:B) -> 0.07538505 | C11: ='O-PTIR'!C11/MAX('O-PTIR'!C:C) -> 0.0071237131 | D11: ='O-PTIR'!D11/MAX('O-PTIR'!D:D) -> 0.15357092 | E11: ='O-PTIR'!E11/MAX('O-PTIR'!E:E) -> -0.022014835 | F11: ='O-PTIR'!F11/MAX('O-PTIR'!F:F) -> -0.15223258 | G11: ='O-PTIR'!G11/MAX('O-PTIR'!G:G) -> 0.20504686 | H11: ='O-PTIR'!H11/MAX('O-PTIR'!H:H) -> -0.74198397 | I11: ='O-PTIR'!I11/MAX('O-PTIR'!I:I) -> 0.11093183 | J11: ='O-PTIR'!J11/MAX('O-PTIR'!J:J) -> -0.0067180588 | K11: ='O-PTIR'!K11/MAX('O-PTIR'!K:K) -> -0.011855942 | L11: ='O-PTIR'!L11/MAX('O-PTIR'!L:L) -> -0.064179295 | M11: ='O-PTIR'!M11/MAX('O-PTIR'!M:M) -> 0.00024641275 | N11: ='O-PTIR'!N11/MAX('O-PTIR'!N:N) -> 0.21371514 | O11: ='O-PTIR'!O11/MAX('O-PTIR'!O:O) -> -0.040728305 | P11: ='O-PTIR'!P11/MAX('O-PTIR'!P:P) -> -0.018860666 | Q11: ='O-PTIR'!Q11/MAX('O-PTIR'!Q:Q) -> 4.6678157e-05 | R11: ='O-PTIR'!R11/MAX('O-PTIR'!R:R) -> 0.043123984 | S11: ='O-PTIR'!S11/MAX('O-PTIR'!S:S) -> 0.0073164692 | T11: ='O-PTIR'!T11/MAX('O-PTIR'!T:T) -> -0.011970473 | U11: ='O-PTIR'!U11/MAX('O-PTIR'!U:U) -> 0.0046483421 | V11: ='O-PTIR'!V11/MAX('O-PTIR'!V:V) -> -0.014769291 | W11: ='O-PTIR'!W11/MAX('O-PTIR'!W:W) -> -0.0079002517 | X11: ='O-PTIR'!X11/MAX('O-PTIR'!X:X) -> -0.016909082 | Y11: ='O-PTIR'!Y11/MAX('O-PTIR'!Y:Y) -> 0.0086009524 | Z11: ='O-PTIR'!Z11/MAX('O-PTIR'!Z:Z) -> -0.038743783 | AA11: ='O-PTIR'!AA11/MAX('O-PTIR'!AA:AA) -> -0.0054872842 | AB11: ='O-PTIR'!AB11/MAX('O-PTIR'!AB:AB) -> -0.148276 | AC11: ='O-PTIR'!AC11/MAX('O-PTIR'!AC:AC) -> -0.0096196822 | AD11: ='O-PTIR'!AD11/MAX('O-PTIR'!AD:AD) -> 0.017944046 | AE11: ='O-PTIR'!AE11/MAX('O-PTIR'!AE:AE) -> -0.0047103872 | AF11: ='O-PTIR'!AF11/MAX('O-PTIR'!AF:AF) -> 0.0028551554 | AG11: ='O-PTIR'!AG11/MAX('O-PTIR'!AG:AG) -> 0.0023767366 | AH11: ='O-PTIR'!AH11/MAX('O-PTIR'!AH:AH) -> -0.0030655432 | AI11: ='O-PTIR'!AI11/MAX('O-PTIR'!AI:AI) -> -0.00072950234 | AJ11: ='O-PTIR'!AJ11/MAX('O-PTIR'!AJ:AJ) -> -0.42928909 | AK11: ='O-PTIR'!AK11/MAX('O-PTIR'!AK:AK) -> -0.052566661 | AL11: ='O-PTIR'!AL11/MAX('O-PTIR'!AL:AL) -> -0.077943505 | AM11: ='O-PTIR'!AM11/MAX('O-PTIR'!AM:AM) -> -0.056543448 | AN11: ='O-PTIR'!AN11/MAX('O-PTIR'!AN:AN) -> -0.0092173752 | AO11: ='O-PTIR'!AO11/MAX('O-PTIR'!AO:AO) -> 0.0020626682 | AP11: ='O-PTIR'!AP11/MAX('O-PTIR'!AP:AP) -> -0.0028868001 | AQ11: ='O-PTIR'!AQ11/MAX('O-PTIR'!AQ:AQ) -> -0.00047926677 | AR11: ='O-PTIR'!AR11/MAX('O-PTIR'!AR:AR) -> 0.0084876302 | AS11: ='O-PTIR'!AS11/MAX('O-PTIR'!AS:AS) -> -0.0013140597 | AT11: ='O-PTIR'!AT11/MAX('O-PTIR'!AT:AT) -> 0.00075018468 | AU11: ='O-PTIR'!AU11/MAX('O-PTIR'!AU:AU) -> 0.0043023075 | AV11: ='O-PTIR'!AV11/MAX('O-PTIR'!AV:AV) -> 0.00040935097 | AW11: ='O-PTIR'!AW11/MAX('O-PTIR'!AW:AW) -> -0.0056896342 | AX11: ='O-PTIR'!AX11/MAX('O-PTIR'!AX:AX) -> -0.0026083593 | AY11: ='O-PTIR'!AY11/MAX('O-PTIR'!AY:AY) -> -0.11737179 | AZ11: ='O-PTIR'!AZ11/MAX('O-PTIR'!AZ:AZ) -> 0.00011819835 | BA11: ='O-PTIR'!BA11/MAX('O-PTIR'!BA:BA) -> 0.005865343 | BB11: ='O-PTIR'!BB11/MAX('O-PTIR'!BB:BB) -> -0.0021441446 | BC11: ='O-PTIR'!BC11/MAX('O-PTIR'!BC:BC) -> 0.066200882 | BD11: ='O-PTIR'!BD11/MAX('O-PTIR'!BD:BD) -> -0.048173975 | BE11: ='O-PTIR'!BE11/MAX('O-PTIR'!BE:BE) -> 0.04321278 | BF11: ='O-PTIR'!BF11/MAX('O-PTIR'!BF:BF) -> -0.005774556 | BG11: ='O-PTIR'!BG11/MAX('O-PTIR'!BG:BG) -> -0.00018089659 | BH11: ='O-PTIR'!BH11/MAX('O-PTIR'!BH:BH) -> 0.00090019907 | BI11: ='O-PTIR'!BI11/MAX('O-PTIR'!BI:BI) -> -0.0040046439
A12: 968 | B12: ='O-PTIR'!B12/MAX('O-PTIR'!B:B) -> 0.046604409 | C12: ='O-PTIR'!C12/MAX('O-PTIR'!C:C) -> -0.032361737 | D12: ='O-PTIR'!D12/MAX('O-PTIR'!D:D) -> 0.059042343 | E12: ='O-PTIR'!E12/MAX('O-PTIR'!E:E) -> -0.073823729 | F12: ='O-PTIR'!F12/MAX('O-PTIR'!F:F) -> -0.33833491 | G12: ='O-PTIR'!G12/MAX('O-PTIR'!G:G) -> 0.24474595 | H12: ='O-PTIR'!H12/MAX('O-PTIR'!H:H) -> -0.67647402 | I12: ='O-PTIR'!I12/MAX('O-PTIR'!I:I) -> -0.54282669 | J12: ='O-PTIR'!J12/MAX('O-PTIR'!J:J) -> -0.15050859 | K12: ='O-PTIR'!K12/MAX('O-PTIR'!K:K) -> 0.0033297042 | L12: ='O-PTIR'!L12/MAX('O-PTIR'!L:L) -> -0.26614519 | M12: ='O-PTIR'!M12/MAX('O-PTIR'!M:M) -> -0.00041423914 | N12: ='O-PTIR'!N12/MAX('O-PTIR'!N:N) -> 0.22647702 | O12: ='O-PTIR'!O12/MAX('O-PTIR'!O:O) -> -0.0049990563 | P12: ='O-PTIR'!P12/MAX('O-PTIR'!P:P) -> -0.018459996 | Q12: ='O-PTIR'!Q12/MAX('O-PTIR'!Q:Q) -> 0.0032361367 | R12: ='O-PTIR'!R12/MAX('O-PTIR'!R:R) -> -0.0034376547 | S12: ='O-PTIR'!S12/MAX('O-PTIR'!S:S) -> 0.0012635418 | T12: ='O-PTIR'!T12/MAX('O-PTIR'!T:T) -> -0.013228909 | U12: ='O-PTIR'!U12/MAX('O-PTIR'!U:U) -> 0.0010550754 | V12: ='O-PTIR'!V12/MAX('O-PTIR'!V:V) -> -0.019938264 | W12: ='O-PTIR'!W12/MAX('O-PTIR'!W:W) -> 0.032266587 | X12: ='O-PTIR'!X12/MAX('O-PTIR'!X:X) -> -0.084613938 | Y12: ='O-PTIR'!Y12/MAX('O-PTIR'!Y:Y) -> 0.0022739717 | Z12: ='O-PTIR'!Z12/MAX('O-PTIR'!Z:Z) -> -0.047816404 | AA12: ='O-PTIR'!AA12/MAX('O-PTIR'!AA:AA) -> -0.25242298 | AB12: ='O-PTIR'!AB12/MAX('O-PTIR'!AB:AB) -> 0.036637836 | AC12: ='O-PTIR'!AC12/MAX('O-PTIR'!AC:AC) -> 0.016101542 | AD12: ='O-PTIR'!AD12/MAX('O-PTIR'!AD:AD) -> 0.016751181 | AE12: ='O-PTIR'!AE12/MAX('O-PTIR'!AE:AE) -> 0.00053164165 | AF12: ='O-PTIR'!AF12/MAX('O-PTIR'!AF:AF) -> -0.0029138973 | AG12: ='O-PTIR'!AG12/MAX('O-PTIR'!AG:AG) -> 0.0021809568 | AH12: ='O-PTIR'!AH12/MAX('O-PTIR'!AH:AH) -> 0.011786817 | AI12: ='O-PTIR'!AI12/MAX('O-PTIR'!AI:AI) -> -0.0092508511 | AJ12: ='O-PTIR'!AJ12/MAX('O-PTIR'!AJ:AJ) -> -0.34674976 | AK12: ='O-PTIR'!AK12/MAX('O-PTIR'!AK:AK) -> -0.012798067 | AL12: ='O-PTIR'!AL12/MAX('O-PTIR'!AL:AL) -> 0.04947728 | AM12: ='O-PTIR'!AM12/MAX('O-PTIR'!AM:AM) -> 0.02314657 | AN12: ='O-PTIR'!AN12/MAX('O-PTIR'!AN:AN) -> -0.016999254 | AO12: ='O-PTIR'!AO12/MAX('O-PTIR'!AO:AO) -> 0.0026914545 | AP12: ='O-PTIR'!AP12/MAX('O-PTIR'!AP:AP) -> 0.00067505276 | AQ12: ='O-PTIR'!AQ12/MAX('O-PTIR'!AQ:AQ) -> 0.0034163182 | AR12: ='O-PTIR'!AR12/MAX('O-PTIR'!AR:AR) -> 0.0010086906 | AS12: ='O-PTIR'!AS12/MAX('O-PTIR'!AS:AS) -> -0.0082027353 | AT12: ='O-PTIR'!AT12/MAX('O-PTIR'!AT:AT) -> 0.001039533 | AU12: ='O-PTIR'!AU12/MAX('O-PTIR'!AU:AU) -> -0.0064220792 | AV12: ='O-PTIR'!AV12/MAX('O-PTIR'!AV:AV) -> -0.0050820449 | AW12: ='O-PTIR'!AW12/MAX('O-PTIR'!AW:AW) -> -0.00045222135 | AX12: ='O-PTIR'!AX12/MAX('O-PTIR'!AX:AX) -> -0.00055257943 | AY12: ='O-PTIR'!AY12/MAX('O-PTIR'!AY:AY) -> -0.11277115 | AZ12: ='O-PTIR'!AZ12/MAX('O-PTIR'!AZ:AZ) -> -0.0018103324 | BA12: ='O-PTIR'!BA12/MAX('O-PTIR'!BA:BA) -> 0.0019761567 | BB12: ='O-PTIR'!BB12/MAX('O-PTIR'!BB:BB) -> -0.003250506 | BC12: ='O-PTIR'!BC12/MAX('O-PTIR'!BC:BC) -> 0.072513254 | BD12: ='O-PTIR'!BD12/MAX('O-PTIR'!BD:BD) -> -0.0069801375 | BE12: ='O-PTIR'!BE12/MAX('O-PTIR'!BE:BE) -> -0.01721787 | BF12: ='O-PTIR'!BF12/MAX('O-PTIR'!BF:BF) -> -0.0034527806 | BG12: ='O-PTIR'!BG12/MAX('O-PTIR'!BG:BG) -> -0.00013330931 | BH12: ='O-PTIR'!BH12/MAX('O-PTIR'!BH:BH) -> -0.0021458049 | BI12: ='O-PTIR'!BI12/MAX('O-PTIR'!BI:BI) -> -0.0059348391
A13: 970 | B13: ='O-PTIR'!B13/MAX('O-PTIR'!B:B) -> 0.045123597 | C13: ='O-PTIR'!C13/MAX('O-PTIR'!C:C) -> -0.0388288 | D13: ='O-PTIR'!D13/MAX('O-PTIR'!D:D) -> 0.077453022 | E13: ='O-PTIR'!E13/MAX('O-PTIR'!E:E) -> -0.042739072 | F13: ='O-PTIR'!F13/MAX('O-PTIR'!F:F) -> -0.23022794 | G13: ='O-PTIR'!G13/MAX('O-PTIR'!G:G) -> 0.13991098 | H13: ='O-PTIR'!H13/MAX('O-PTIR'!H:H) -> -0.74989726 | I13: ='O-PTIR'!I13/MAX('O-PTIR'!I:I) -> -0.76433186 | J13: ='O-PTIR'!J13/MAX('O-PTIR'!J:J) -> -0.13797755 | K13: ='O-PTIR'!K13/MAX('O-PTIR'!K:K) -> 0.0007700027 | L13: ='O-PTIR'!L13/MAX('O-PTIR'!L:L) -> 0.014093355 | M13: ='O-PTIR'!M13/MAX('O-PTIR'!M:M) -> -0.00019629889 | N13: ='O-PTIR'!N13/MAX('O-PTIR'!N:N) -> 0.074495724 | O13: ='O-PTIR'!O13/MAX('O-PTIR'!O:O) -> 0.049952199 | P13: ='O-PTIR'!P13/MAX('O-PTIR'!P:P) -> -0.01201983 | Q13: ='O-PTIR'!Q13/MAX('O-PTIR'!Q:Q) -> 0.0053073659 | R13: ='O-PTIR'!R13/MAX('O-PTIR'!R:R) -> -0.11209979 | S13: ='O-PTIR'!S13/MAX('O-PTIR'!S:S) -> -0.000696285 | T13: ='O-PTIR'!T13/MAX('O-PTIR'!T:T) -> -0.010222452 | U13: ='O-PTIR'!U13/MAX('O-PTIR'!U:U) -> -0.0021558886 | V13: ='O-PTIR'!V13/MAX('O-PTIR'!V:V) -> -0.004837643 | W13: ='O-PTIR'!W13/MAX('O-PTIR'!W:W) -> 0.028186679 | X13: ='O-PTIR'!X13/MAX('O-PTIR'!X:X) -> -0.07626376 | Y13: ='O-PTIR'!Y13/MAX('O-PTIR'!Y:Y) -> 0.01698626 | Z13: ='O-PTIR'!Z13/MAX('O-PTIR'!Z:Z) -> -0.030113588 | AA13: ='O-PTIR'!AA13/MAX('O-PTIR'!AA:AA) -> 0.10808969 | AB13: ='O-PTIR'!AB13/MAX('O-PTIR'!AB:AB) -> -0.11590026 | AC13: ='O-PTIR'!AC13/MAX('O-PTIR'!AC:AC) -> 0.0050292543 | AD13: ='O-PTIR'!AD13/MAX('O-PTIR'!AD:AD) -> 0.0022523422 | AE13: ='O-PTIR'!AE13/MAX('O-PTIR'!AE:AE) -> -0.0021437488 | AF13: ='O-PTIR'!AF13/MAX('O-PTIR'!AF:AF) -> -0.0025520155 | AG13: ='O-PTIR'!AG13/MAX('O-PTIR'!AG:AG) -> 0.0084348467 | AH13: ='O-PTIR'!AH13/MAX('O-PTIR'!AH:AH) -> 0.020254471 | AI13: ='O-PTIR'!AI13/MAX('O-PTIR'!AI:AI) -> -0.0052489782 | AJ13: ='O-PTIR'!AJ13/MAX('O-PTIR'!AJ:AJ) -> -0.32354015 | AK13: ='O-PTIR'!AK13/MAX('O-PTIR'!AK:AK) -> 0.089364733 | AL13: ='O-PTIR'!AL13/MAX('O-PTIR'!AL:AL) -> 0.034969281 | AM13: ='O-PTIR'!AM13/MAX('O-PTIR'!AM:AM) -> 0.0030774037 | AN13: ='O-PTIR'!AN13/MAX('O-PTIR'!AN:AN) -> -0.0040697391 | AO13: ='O-PTIR'!AO13/MAX('O-PTIR'!AO:AO) -> -0.0044812398 | AP13: ='O-PTIR'!AP13/MAX('O-PTIR'!AP:AP) -> -0.0013343313 | AQ13: ='O-PTIR'!AQ13/MAX('O-PTIR'!AQ:AQ) -> 0.0067646312 | AR13: ='O-PTIR'!AR13/MAX('O-PTIR'!AR:AR) -> -0.003714217 | AS13: ='O-PTIR'!AS13/MAX('O-PTIR'!AS:AS) -> -0.0035032333 | AT13: ='O-PTIR'!AT13/MAX('O-PTIR'!AT:AT) -> 0.00062262896 | AU13: ='O-PTIR'!AU13/MAX('O-PTIR'!AU:AU) -> -0.0014379439 | AV13: ='O-PTIR'!AV13/MAX('O-PTIR'!AV:AV) -> -0.001496607 | AW13: ='O-PTIR'!AW13/MAX('O-PTIR'!AW:AW) -> -0.00098017746 | AX13: ='O-PTIR'!AX13/MAX('O-PTIR'!AX:AX) -> -0.0021642215 | AY13: ='O-PTIR'!AY13/MAX('O-PTIR'!AY:AY) -> -0.14380521 | AZ13: ='O-PTIR'!AZ13/MAX('O-PTIR'!AZ:AZ) -> -0.0016157324 | BA13: ='O-PTIR'!BA13/MAX('O-PTIR'!BA:BA) -> 0.0076641076 | BB13: ='O-PTIR'!BB13/MAX('O-PTIR'!BB:BB) -> -0.0015984657 | BC13: ='O-PTIR'!BC13/MAX('O-PTIR'!BC:BC) -> 0.11912084 | BD13: ='O-PTIR'!BD13/MAX('O-PTIR'!BD:BD) -> -0.011287445 | BE13: ='O-PTIR'!BE13/MAX('O-PTIR'!BE:BE) -> -0.088167397 | BF13: ='O-PTIR'!BF13/MAX('O-PTIR'!BF:BF) -> -0.0021513122 | BG13: ='O-PTIR'!BG13/MAX('O-PTIR'!BG:BG) -> 9.109967e-06 | BH13: ='O-PTIR'!BH13/MAX('O-PTIR'!BH:BH) -> -0.0040042377 | BI13: ='O-PTIR'!BI13/MAX('O-PTIR'!BI:BI) -> -0.0070583882
