Workbook

Sheet O-PTIR
A1: X value [cmâ»Â¹] | B1: IR Spectrum 1/OPTIR (mV) [] | C1: IR Spectrum 2/OPTIR (mV) [] | D1: IR Spectrum 3/OPTIR (mV) [] | E1: IR Spectrum 4/OPTIR (mV) [] | F1: IR Spectrum 5/OPTIR (mV) [] | G1: IR Spectrum 6/OPTIR (mV) [] | H1: IR Spectrum 7/OPTIR (mV) [] | I1: IR Spectrum 8/OPTIR (mV) [] | J1: IR Spectrum 9/OPTIR (mV) [] | K1: IR Spectrum 10/OPTIR (mV) [] | L1: IR Spectrum 11/OPTIR (mV) [] | M1: IR Spectrum 12/OPTIR (mV) [] | N1: IR Spectrum 13/OPTIR (mV) [] | O1: IR Spectrum 14/OPTIR (mV) [] | P1: IR Spectrum 15/OPTIR (mV) [] | Q1: IR Spectrum 16/OPTIR (mV) [] | R1: IR Spectrum 17/OPTIR (mV) [] | S1: IR Spectrum 18/OPTIR (mV) [] | T1: IR Spectrum 19/OPTIR (mV) [] | U1: IR Spectrum 20/OPTIR (mV) [] | V1: IR Spectrum 21/OPTIR (mV) [] | W1: IR Spectrum 22/OPTIR (mV) [] | X1: IR Spectrum 23/OPTIR (mV) [] | Y1: IR Spectrum 24/OPTIR (mV) [] | Z1: IR Spectrum 25/OPTIR (mV) [] | AA1: IR Spectrum 26/OPTIR (mV) [] | AB1: IR Spectrum 27/OPTIR (mV) [] | AC1: IR Spectrum 28/OPTIR (mV) [] | AD1: IR Spectrum 29/OPTIR (mV) [] | AE1: IR Spectrum 30/OPTIR (mV) [] | AF1: IR Spectrum 31/OPTIR (mV) [] | AG1: IR Spectrum 32/OPTIR (mV) [] | AH1: IR Spectrum 33/OPTIR (mV) [] | AI1: IR Spectrum 34/OPTIR (mV) [] | AJ1: IR Spectrum 35/OPTIR (mV) [] | AK1: IR Spectrum 36/OPTIR (mV) [] | AL1: IR Spectrum 37/OPTIR (mV) [] | AM1: IR Spectrum 38/OPTIR (mV) [] | AN1: IR Spectrum 39/OPTIR (mV) [] | AO1: IR Spectrum 40/OPTIR (mV) [] | AP1: IR Spectrum 41/OPTIR (mV) [] | AQ1: IR Spectrum 42/OPTIR (mV) [] | AR1: IR Spectrum 43/OPTIR (mV) [] | AS1: IR Spectrum 44/OPTIR (mV) [] | AT1: IR Spectrum 45/OPTIR (mV) [] | AU1: IR Spectrum 46/OPTIR (mV) [] | AV1: IR Spectrum 47/OPTIR (mV) [] | AW1: IR Spectrum 48/OPTIR (mV) [] | AX1: IR Spectrum 49/OPTIR (mV) [] | AY1: IR Spectrum 50/OPTIR (mV) [] | AZ1: IR Spectrum 51/OPTIR (mV) [] | BA1: IR Spectrum 52/OPTIR (mV) [] | BB1: IR Spectrum 53/OPTIR (mV) []
A2: 948 | B2: -2.9455159 | C2: -0.94406849 | D2: 0.45855966 | E2: -0.70573318 | F2: -2.8331902 | G2: 3.414643 | H2: -1.3994781 | I2: 3.9829834 | J2: 0.97102046 | K2: 0.89426976 | L2: 0.5682326 | M2: -0.19558384 | N2: 1.1726007 | O2: -1.215485 | P2: -0.88370383 | Q2: 0.63720489 | R2: -0.35786945 | S2: 0.66997051 | T2: 2.2866504 | U2: -2.8590839 | V2: -1.381547 | W2: 2.721735 | X2: 2.0580812 | Y2: 4.1913695 | Z2: -2.5136197 | AA2: -0.71581137 | AB2: 1.070726 | AC2: -0.78136677 | AD2: -1.2627838 | AE2: -6.3887796 | AF2: -3.9814658 | AG2: 2.1020768 | AH2: 3.7201846 | AI2: 2.7601991 | AJ2: -3.3469744 | AK2: 0.64973569 | AL2: -1.7161684 | AM2: 0.4871397 | AN2: -2.8346064 | AO2: 0.79753417 | AP2: 7.6741595 | AQ2: 0.97659248 | AR2: -2.3066669 | AS2: -1.2199825 | AT2: -0.12290196 | AU2: -0.51165533 | AV2: 0.40301466 | AW2: -0.95598447 | AX2: -0.25380674 | AY2: 1.6157031 | AZ2: 0.32189965 | BA2: -3.5952904 | BB2: 1.7352048
A3: 950 | B3: -2.3163342 | C3: -0.2919251 | D3: 0.97207564 | E3: 2.313926 | F3: -0.2898463 | G3: 0.88419968 | H3: -4.3558474 | I3: 4.271606 | J3: 0.88393307 | K3: 1.1890951 | L3: 1.6826261 | M3: 0.57582682 | N3: -0.73717338 | O3: 0.82835239 | P3: 0.34327221 | Q3: 1.972824 | R3: -1.6528938 | S3: 2.9236314 | T3: 0.19507162 | U3: -0.74883449 | V3: -0.22998616 | W3: 0.65206265 | X3: 3.788553 | Y3: 2.665221 | Z3: 1.4984446 | AA3: 0.46150282 | AB3: 0.048466109 | AC3: 0.20533472 | AD3: 2.2923412 | AE3: -5.9206452 | AF3: -0.041117657 | AG3: -2.7593236 | AH3: 4.0331073 | AI3: 1.6030498 | AJ3: -0.36608684 | AK3: 1.6046128 | AL3: -3.0018969 | AM3: 1.0813611 | AN3: 0.057792258 | AO3: 0.73242956 | AP3: 4.2339611 | AQ3: 2.8988781 | AR3: 0.14583978 | AS3: -0.073555887 | AT3: 0.020378059 | AU3: 0.96354377 | AV3: -1.317142 | AW3: 0.60810286 | AX3: -2.9394929 | AY3: 0.15445343 | AZ3: 0.21778578 | BA3: -0.75645316 | BB3: 1.3645933
A4: 952 | B4: -0.15503475 | C4: 1.5222485 | D4: 1.5401527 | E4: 1.6410276 | F4: 1.0312167 | G4: -0.19614553 | H4: -2.117321 | I4: -0.19022489 | J4: 0.48896989 | K4: 0.20396969 | L4: 0.30626115 | M4: -0.50516623 | N4: -1.0260204 | O4: -0.90265667 | P4: 0.92697483 | Q4: 0.70110476 | R4: 0.50385523 | S4: 1.525912 | T4: 0.72100115 | U4: -1.4613287 | V4: -0.60600179 | W4: -0.18715188 | X4: 0.53041542 | Y4: -1.465114 | Z4: 0.47161564 | AA4: -1.1371477 | AB4: -1.3659947 | AC4: -0.15991598 | AD4: 0.057410534 | AE4: -5.1623077 | AF4: 1.2613848 | AG4: -0.7772432 | AH4: 1.4944578 | AI4: -2.0436375 | AJ4: 0.64861667 | AK4: -0.19213374 | AL4: -2.5670099 | AM4: 2.4426296 | AN4: -0.30350271 | AO4: 0.42929119 | AP4: -0.00073358417 | AQ4: 0.08837527 | AR4: -1.0006274 | AS4: -0.70659393 | AT4: -0.52359313 | AU4: 0.66994202 | AV4: -3.0307343 | AW4: 0.17360422 | AX4: -0.69338667 | AY4: 0.28280434 | AZ4: -0.6681242 | BA4: 0.87433237 | BB4: -0.4478218
A5: 954 | B5: 0.61447781 | C5: 1.2405982 | D5: 2.1329823 | E5: 0.10552914 | F5: -0.32368839 | G5: -0.42882007 | H5: -1.2715647 | I5: 0.45719361 | J5: -0.28398079 | K5: -0.51300466 | L5: 0.89035982 | M5: 0.6606825 | N5: -1.0746672 | O5: -1.0756819 | P5: -1.3920567 | Q5: 1.185447 | R5: 0.87490672 | S5: 0.63742685 | T5: 0.71696442 | U5: -0.4743042 | V5: -0.30978078 | W5: -0.4911207 | X5: 0.069413424 | Y5: 0.057818003 | Z5: 0.72667062 | AA5: -1.1587031 | AB5: -1.0300581 | AC5: -0.38775083 | AD5: 0.52277869 | AE5: -2.7940803 | AF5: 0.70130908 | AG5: -0.68812871 | AH5: 2.4820848 | AI5: -0.73547369 | AJ5: -0.35177177 | AK5: -0.97025675 | AL5: -1.4420878 | AM5: 0.7880854 | AN5: 0.30450746 | AO5: 1.3115915 | AP5: 2.0118246 | AQ5: -1.2631861 | AR5: -0.061231472 | AS5: 0.66359919 | AT5: -0.43690279 | AU5: -0.91977805 | AV5: -3.3183868 | AW5: 1.2011259 | AX5: -1.7011049 | AY5: 0.65178919 | AZ5: 0.14193952 | BA5: 0.035668783 | BB5: -0.061437495
A6: 956 | B6: -0.10509956 | C6: 0.52727151 | D6: 1.2068686 | E6: 0.92756742 | F6: -0.77887541 | G6: -0.029369315 | H6: -0.8727057 | I6: -0.25940743 | J6: 0.63149691 | K6: 0.11669867 | L6: 1.4613848 | M6: 0.13241923 | N6: 0.69786221 | O6: -1.313942 | P6: 0.95670414 | Q6: 1.4728347 | R6: 0.86412948 | S6: 1.1651481 | T6: -0.13515259 | U6: 0.098788448 | V6: -0.65021795 | W6: -0.39322293 | X6: -0.5807693 | Y6: 0.73854244 | Z6: 1.1039376 | AA6: -1.4071285 | AB6: -0.14603233 | AC6: -0.29134813 | AD6: 1.107655 | AE6: -1.6832885 | AF6: 0.59852278 | AG6: 0.1952967 | AH6: 1.9984946 | AI6: -1.0988537 | AJ6: 0.92733818 | AK6: 0.028589869 | AL6: -1.4395375 | AM6: 0.4823139 | AN6: -0.066520266 | AO6: 0.13908233 | AP6: 2.3107927 | AQ6: -2.1832066 | AR6: 2.1823235 | AS6: -0.92559558 | AT6: 0.61364865 | AU6: -0.80006945 | AV6: -0.94520628 | AW6: 0.42047793 | AX6: -0.38505173 | AY6: 0.41220796 | AZ6: -0.47827032 | BA6: -0.30378115 | BB6: 0.34216076
A7: 958 | B7: 0.56396073 | C7: 1.5118935 | D7: 0.94060946 | E7: 1.062263 | F7: -0.80847824 | G7: -1.4867407 | H7: -0.78910643 | I7: -0.92371345 | J7: 0.6519075 | K7: -0.18415287 | L7: -0.026976852 | M7: 0.72820407 | N7: 0.10121484 | O7: -0.74560875 | P7: 0.32895815 | Q7: 1.2017925 | R7: 0.54549569 | S7: -0.81996262 | T7: 0.99595857 | U7: 0.78254026 | V7: 0.051300675 | W7: 0.65575093 | X7: 0.7765215 | Y7: 0.53726536 | Z7: 0.19980425 | AA7: -0.73041898 | AB7: -0.07838922 | AC7: -0.46141043 | AD7: 0.52057654 | AE7: -1.5579215 | AF7: 1.198446 | AG7: 0.35791922 | AH7: 2.0150955 | AI7: -0.26010543 | AJ7: -0.25947812 | AK7: 2.219656 | AL7: -1.7281595 | AM7: -0.18718585 | AN7: 0.37957379 | AO7: -0.42653403 | AP7: 1.4668497 | AQ7: -1.0962914 | AR7: 1.3238633 | AS7: -0.66139269 | AT7: 2.0572472 | AU7: -0.99584961 | AV7: -0.83022243 | AW7: 0.95589948 | AX7: 0.12419425 | AY7: -0.38851109 | AZ7: -0.11504546 | BA7: -1.1896169 | BB7: -0.18054792
A8: 960 | B8: -0.24395354 | C8: 1.1547987 | D8: -0.52622634 | E8: 0.44302553 | F8: -0.31835079 | G8: -0.81918198 | H8: -0.48261544 | I8: -0.11078919 | J8: -0.044308841 | K8: 0.049868435 | L8: 0.010651067 | M8: 0.41364774 | N8: 0.094497718 | O8: -1.6964043 | P8: 0.24282147 | Q8: 0.31073508 | R8: 0.86106062 | S8: 0.24615249 | T8: 1.0694001 | U8: 0.30819947 | V8: -0.056883629 | W8: 0.44668388 | X8: 1.2968599 | Y8: 0.22988638 | Z8: -0.63220209 | AA8: -0.1560739 | AB8: -0.11042078 | AC8: 0.40890095 | AD8: -0.24660696 | AE8: -1.8981403 | AF8: 0.93244177 | AG8: 1.2926295 | AH8: 0.553563 | AI8: 0.15265903 | AJ8: 0.78114998 | AK8: 1.7982297 | AL8: -1.388234 | AM8: -0.58043599 | AN8: 0.033644624 | AO8: -0.22288246 | AP8: 1.0943569 | AQ8: -0.18276955 | AR8: 1.2279346 | AS8: 0.17698514 | AT8: 0.46598884 | AU8: 0.46277454 | AV8: -1.1342001 | AW8: -0.35687262 | AX8: -0.1796975 | AY8: -0.86854875 | AZ8: -0.7697593 | BA8: -0.4522562 | BB8: 0.41920048
A9: 962 | B9: -0.29771283 | C9: 1.1700348 | D9: -0.11744866 | E9: 1.1671349 | F9: -0.87473607 | G9: -0.19428644 | H9: -1.0396554 | I9: 0.63343865 | J9: 0.60536259 | K9: 0.42886445 | L9: 0.051367916 | M9: 0.13154842 | N9: 0.18503326 | O9: -0.6313768 | P9: 1.0675279 | Q9: 0.36374158 | R9: 1.3605552 | S9: 0.8844927 | T9: 0.55470467 | U9: 0.05860091 | V9: -0.34348756 | W9: 0.6844207 | X9: 1.0668528 | Y9: -0.7015205 | Z9: -0.72679478 | AA9: -0.48333082 | AB9: -0.99987394 | AC9: -0.19683376 | AD9: 0.10713632 | AE9: -1.8377481 | AF9: 1.8268992 | AG9: 0.42649737 | AH9: 0.73296732 | AI9: -0.38379812 | AJ9: 1.0262167 | AK9: 0.70190448 | AL9: -0.54048562 | AM9: -0.36173654 | AN9: 0.050458737 | AO9: 0.64430928 | AP9: 1.1503248 | AQ9: 0.33296567 | AR9: -0.088707194 | AS9: -0.54230213 | AT9: -0.318928 | AU9: -0.255573 | AV9: -0.95367575 | AW9: -0.70812488 | AX9: 0.30791298 | AY9: -0.57945234 | AZ9: -0.74378777 | BA9: -0.68780577 | BB9: 0.28125492
A10: 964 | B10: -0.18576613 | C10: 0.72590661 | D10: 0.19310929 | E10: 0.54223901 | F10: -0.10715276 | G10: -0.080724433 | H10: -1.2885717 | I10: 0.98887628 | J10: 0.9432956 | K10: 0.51310176 | L10: 0.82248461 | M10: 0.060919639 | N10: 0.10780284 | O10: 0.4358142 | P10: 1.2848308 | Q10: 0.35914612 | R10: 0.04368047 | S10: 1.0503292 | T10: 1.0492871 | U10: 0.28959653 | V10: 0.12145887 | W10: 0.045030117 | X10: 0.3379443 | Y10: -0.37826633 | Z10: -0.95304197 | AA10: -0.089507774 | AB10: -1.0921284 | AC10: 0.20625386 | AD10: -0.50286424 | AE10: -1.0698884 | AF10: 2.1447058 | AG10: 0.19051199 | AH10: 1.0761048 | AI10: 0.20172212 | AJ10: -0.14836957 | AK10: 0.45914209 | AL10: -0.023305282 | AM10: -0.33427659 | AN10: -0.24240351 | AO10: 0.83621454 | AP10: 1.1472247 | AQ10: 0.29103246 | AR10: -0.4602924 | AS10: -0.059124075 | AT10: 0.059520766 | AU10: -0.45778087 | AV10: -0.87584388 | AW10: -0.25797567 | AX10: -0.5157429 | AY10: 0.14688358 | AZ10: -1.1111755 | BA10: 0.33192119 | BB10: 0.32281548
A11: 966 | B11: -0.064064883 | C11: -0.013548068 | D11: 0.79478282 | E11: 0.550246 | F11: -0.14911477 | G11: 1.0619335 | H11: -0.43156922 | I11: 0.45826739 | J11: -0.14170195 | K11: 0.48313725 | L11: 0.57383806 | M11: -0.059440106 | N11: -0.69619358 | O11: 0.34379917 | P11: 1.0452894 | Q11: 0.44243893 | R11: 0.071134068 | S11: 0.80263686 | T11: 0.29152888 | U11: 0.28689709 | V11: -0.45067346 | W11: 0.6106196 | X11: 0.65150458 | Y11: 0.19082482 | Z11: -0.50126505 | AA11: -0.10389448 | AB11: -0.62010354 | AC11: -0.18133223 | AD11: -0.13317564 | AE11: -1.2720684 | AF11: 1.4984202 | AG11: 0.31711799 | AH11: 0.38199633 | AI11: 0.061614078 | AJ11: 0.025002725 | AK11: 0.4150975 | AL11: -0.069959253 | AM11: -0.20695527 | AN11: 0.1644692 | AO11: -0.031108996 | AP11: 1.3319619 | AQ11: 0.13506976 | AR11: 0.11159726 | AS11: -0.89870828 | AT11: -0.050480194 | AU11: -0.7885164 | AV11: -0.41456932 | AW11: 0.1575482 | AX11: -0.56490242 | AY11: 0.72910118 | AZ11: -0.40346673 | BA11: -0.16742338 | BB11: 0.49067459
A12: 968 | B12: 0.071573846 | C12: 0.095546469 | D12: 0.42258668 | E12: 0.64182532 | F12: -0.10923932 | G12: 0.38182992 | H12: -0.44962379 | I12: 0.22637677 | J12: -0.031602539 | K12: -0.09970364 | L12: -0.43863004 | M12: -0.020416632 | N12: -0.21922889 | O12: -0.22684519 | P12: 0.91156375 | Q12: 0.1699594 | R12: 0.21689077 | S12: 0.37883639 | T12: 0.82960522 | U12: -0.062682316 | V12: -0.23204114 | W12: -0.097443365 | X12: 0.7175591 | Y12: 0.054712836 | Z12: -0.28452656 | AA12: 0.23511788 | AB12: -0.10165522 | AC12: 0.39113852 | AD12: -0.46284828 | AE12: -0.50420254 | AF12: 2.4034808 | AG12: 0.34060264 | AH12: 0.61245102 | AI12: 0.61152369 | AJ12: -0.15532157 | AK12: -0.10692022 | AL12: -0.34175512 | AM12: -0.3118282 | AN12: 0.30887777 | AO12: 0.27121148 | AP12: 1.0333698 | AQ12: 0.011374868 | AR12: -0.086301163 | AS12: 0.26536572 | AT12: -0.61742711 | AU12: -0.30666715 | AV12: -0.1999297 | AW12: 0.26511779 | AX12: 0.037742287 | AY12: 1.0436265 | AZ12: -0.26471463 | BA12: -0.55382514 | BB12: -0.062842317
A13: 970 | B13: 0.0021634749 | C13: 0.45458063 | D13: 0.90359151 | E13: -0.31157237 | F13: -0.32126081 | G13: -0.21932709 | H13: -0.62778044 | I13: -0.19288225 | J13: 0.035144683 | K13: 0.63904005 | L13: -0.24152778 | M13: -0.39407563 | N13: -0.12690708 | O13: -0.31577724 | P13: 1.4502227 | Q13: 0.3076331 | R13: -0.130594 | S13: 0.40488511 | T13: 0.39960885 | U13: 0.13927858 | V13: 0.16217721 | W13: 0.15028821 | X13: 0.086787924 | Y13: 0.26458475 | Z13: -0.074171275 | AA13: -0.11056935 | AB13: 0.36564952 | AC13: 0.5250721 | AD13: 0.28366825 | AE13: -0.64948112 | AF13: 3.0513783 | AG13: -0.46581197 | AH13: 0.21523009 | AI13: 0.024764985 | AJ13: 0.065588608 | AK13: 0.41465402 | AL13: 0.1056261 | AM13: -0.36401361 | AN13: 0.68616295 | AO13: 0.68209279 | AP13: 0.44141895 | AQ13: 0.13531718 | AR13: 0.032366622 | AS13: 0.15674494 | AT13: -0.23853621 | AU13: 0.0035250543 | AV13: 0.004231412 | AW13: -0.12424154 | AX13: -0.42192397 | AY13: 0.30183068 | AZ13: -0.63038516 | BA13: -0.76802927 | BB13: -0.074960016
... A1030: 3004 | B1030: 0.99915332 | C1030: 3.5255883 | D1030: 2.459409 | E1030: 6.1538014 | F1030: -11.135055 | G1030: -2.8990183 | H1030: -1.5204887 | I1030: 2.3309073 | J1030: 7.0048323 | K1030: 4.445262 | L1030: 1.5684401 | M1030: 6.0940099 | N1030: -2.9967694 | O1030: -3.8387744 | P1030: 3.8456943 | Q1030: 1.7915328 | R1030: -2.9342117 | S1030: 1.2096262 | T1030: 1.7365981 | U1030: 3.4326129 | V1030: 3.0705552 | W1030: 3.7841306 | X1030: 7.2538958 | Y1030: 6.0118389 | Z1030: 0.020516133 | AA1030: 5.4793959 | AB1030: -0.22914353 | AC1030: -1.8213996 | AD1030: -10.893955 | AE1030: -4.805388 | AF1030: 0.17646946 | AG1030: 4.7030978 | AH1030: -2.9633317 | AI1030: -7.016715 | AJ1030: -2.6105833 | AK1030: 7.7331371 | AL1030: -5.6775751 | AM1030: -9.5268679 | AN1030: -10.185044 | AO1030: 3.0673409 | AP1030: 1.6204658 | AQ1030: -1.9194758 | AR1030: 2.7935994 | AS1030: 1.8789285 | AT1030: 8.3188324 | AU1030: 7.1683855 | AV1030: -4.1222024 | AW1030: 2.2172556 | AX1030: -5.0705266 | AY1030: 5.3565221 | AZ1030: -5.1403565 | BA1030: -2.7830677 | BB1030: 3.2529657

Sheet O-PTIR norm
A1: OPTIR waveno | B1: 1 | C1: =B1+1 -> 2 | D1: =C1+1 -> 3 | E1: =D1+1 -> 4 | F1: =E1+1 -> 5 | G1: =F1+1 -> 6 | H1: =G1+1 -> 7 | I1: =H1+1 -> 8 | J1: =I1+1 -> 9 | ... BB1: =BA1+1 -> 53
A2: 948 | B2: ='O-PTIR'!B2/MAX('O-PTIR'!B:B) -> -0.25464818 | C2: ='O-PTIR'!C2/MAX('O-PTIR'!C:C) -> -0.23967845 | D2: ='O-PTIR'!D2/MAX('O-PTIR'!D:D) -> 0.096462376 | E2: ='O-PTIR'!E2/MAX('O-PTIR'!E:E) -> -0.11468248 | F2: ='O-PTIR'!F2/MAX('O-PTIR'!F:F) -> -1.0571597 | G2: ='O-PTIR'!G2/MAX('O-PTIR'!G:G) -> 1 | H2: ='O-PTIR'!H2/MAX('O-PTIR'!H:H) -> -14.088313 | I2: ='O-PTIR'!I2/MAX('O-PTIR'!I:I) -> 0.93243229 | J2: ='O-PTIR'!J2/MAX('O-PTIR'!J:J) -> 0.13862151 | K2: ='O-PTIR'!K2/MAX('O-PTIR'!K:K) -> 0.20117369 | L2: ='O-PTIR'!L2/MAX('O-PTIR'!L:L) -> 0.21664736 | M2: ='O-PTIR'!M2/MAX('O-PTIR'!M:M) -> -0.03209444 | N2: ='O-PTIR'!N2/MAX('O-PTIR'!N:N) -> 0.59480278 | O2: ='O-PTIR'!O2/MAX('O-PTIR'!O:O) -> -0.97760748 | P2: ='O-PTIR'!P2/MAX('O-PTIR'!P:P) -> -0.095772608 | Q2: ='O-PTIR'!Q2/MAX('O-PTIR'!Q:Q) -> 0.087930708 | R2: ='O-PTIR'!R2/MAX('O-PTIR'!R:R) -> -0.097317159 | S2: ='O-PTIR'!S2/MAX('O-PTIR'!S:S) -> 0.11077161 | T2: ='O-PTIR'!T2/MAX('O-PTIR'!T:T) -> 0.35688756 | U2: ='O-PTIR'!U2/MAX('O-PTIR'!U:U) -> -0.72614789 | V2: ='O-PTIR'!V2/MAX('O-PTIR'!V:V) -> -0.44385862 | W2: ='O-PTIR'!W2/MAX('O-PTIR'!W:W) -> 0.57083858 | X2: ='O-PTIR'!X2/MAX('O-PTIR'!X:X) -> 0.28372081 | Y2: ='O-PTIR'!Y2/MAX('O-PTIR'!Y:Y) -> 0.69718593 | Z2: ='O-PTIR'!Z2/MAX('O-PTIR'!Z:Z) -> -0.90547682 | AA2: ='O-PTIR'!AA2/MAX('O-PTIR'!AA:AA) -> -0.13063691 | AB2: ='O-PTIR'!AB2/MAX('O-PTIR'!AB:AB) -> 0.027529218 | AC2: ='O-PTIR'!AC2/MAX('O-PTIR'!AC:AC) -> -0.034678735 | AD2: ='O-PTIR'!AD2/MAX('O-PTIR'!AD:AD) -> -0.12299947 | AE2: ='O-PTIR'!AE2/MAX('O-PTIR'!AE:AE) -> -16.874371 | AF2: ='O-PTIR'!AF2/MAX('O-PTIR'!AF:AF) -> -0.11728971 | AG2: ='O-PTIR'!AG2/MAX('O-PTIR'!AG:AG) -> 0.44328665 | AH2: ='O-PTIR'!AH2/MAX('O-PTIR'!AH:AH) -> 0.92241151 | AI2: ='O-PTIR'!AI2/MAX('O-PTIR'!AI:AI) -> 0.79695559 | AJ2: ='O-PTIR'!AJ2/MAX('O-PTIR'!AJ:AJ) -> -0.5239098 | AK2: ='O-PTIR'!AK2/MAX('O-PTIR'!AK:AK) -> 0.056289904 | AL2: ='O-PTIR'!AL2/MAX('O-PTIR'!AL:AL) -> -0.52221923 | AM2: ='O-PTIR'!AM2/MAX('O-PTIR'!AM:AM) -> 0.14272602 | AN2: ='O-PTIR'!AN2/MAX('O-PTIR'!AN:AN) -> -0.88847533 | AO2: ='O-PTIR'!AO2/MAX('O-PTIR'!AO:AO) -> 0.2334657 | AP2: ='O-PTIR'!AP2/MAX('O-PTIR'!AP:AP) -> 1 | AQ2: ='O-PTIR'!AQ2/MAX('O-PTIR'!AQ:AQ) -> 0.10739971 | AR2: ='O-PTIR'!AR2/MAX('O-PTIR'!AR:AR) -> -0.59381076 | AS2: ='O-PTIR'!AS2/MAX('O-PTIR'!AS:AS) -> -0.22542599 | AT2: ='O-PTIR'!AT2/MAX('O-PTIR'!AT:AT) -> -0.014773944 | AU2: ='O-PTIR'!AU2/MAX('O-PTIR'!AU:AU) -> -0.071376648 | AV2: ='O-PTIR'!AV2/MAX('O-PTIR'!AV:AV) -> 0.44818368 | AW2: ='O-PTIR'!AW2/MAX('O-PTIR'!AW:AW) -> -0.20880787 | AX2: ='O-PTIR'!AX2/MAX('O-PTIR'!AX:AX) -> -0.12265492 | AY2: ='O-PTIR'!AY2/MAX('O-PTIR'!AY:AY) -> 0.24418047 | AZ2: ='O-PTIR'!AZ2/MAX('O-PTIR'!AZ:AZ) -> 0.12870686 | BA2: ='O-PTIR'!BA2/MAX('O-PTIR'!BA:BA) -> -1.1092501 | BB2: ='O-PTIR'!BB2/MAX('O-PTIR'!BB:BB) -> 0.26072189
A3: 950 | B3: ='O-PTIR'!B3/MAX('O-PTIR'!B:B) -> -0.20025365 | C3: ='O-PTIR'!C3/MAX('O-PTIR'!C:C) -> -0.074113434 | D3: ='O-PTIR'!D3/MAX('O-PTIR'!D:D) -> 0.20448534 | E3: ='O-PTIR'!E3/MAX('O-PTIR'!E:E) -> 0.3760157 | F3: ='O-PTIR'!F3/MAX('O-PTIR'!F:F) -> -0.10815152 | G3: ='O-PTIR'!G3/MAX('O-PTIR'!G:G) -> 0.25894352 | H3: ='O-PTIR'!H3/MAX('O-PTIR'!H:H) -> -43.84959 | I3: ='O-PTIR'!I3/MAX('O-PTIR'!I:I) -> 1 | J3: ='O-PTIR'!J3/MAX('O-PTIR'!J:J) -> 0.12618904 | K3: ='O-PTIR'!K3/MAX('O-PTIR'!K:K) -> 0.2674972 | L3: ='O-PTIR'!L3/MAX('O-PTIR'!L:L) -> 0.64152693 | M3: ='O-PTIR'!M3/MAX('O-PTIR'!M:M) -> 0.094490629 | N3: ='O-PTIR'!N3/MAX('O-PTIR'!N:N) -> -0.37393186 | O3: ='O-PTIR'!O3/MAX('O-PTIR'!O:O) -> 0.666239 | P3: ='O-PTIR'!P3/MAX('O-PTIR'!P:P) -> 0.037202594 | Q3: ='O-PTIR'!Q3/MAX('O-PTIR'!Q:Q) -> 0.27223867 | R3: ='O-PTIR'!R3/MAX('O-PTIR'!R:R) -> -0.44947935 | S3: ='O-PTIR'!S3/MAX('O-PTIR'!S:S) -> 0.48338749 | T3: ='O-PTIR'!T3/MAX('O-PTIR'!T:T) -> 0.030445684 | U3: ='O-PTIR'!U3/MAX('O-PTIR'!U:U) -> -0.1901884 | V3: ='O-PTIR'!V3/MAX('O-PTIR'!V:V) -> -0.073889156 | W3: ='O-PTIR'!W3/MAX('O-PTIR'!W:W) -> 0.13675928 | X3: ='O-PTIR'!X3/MAX('O-PTIR'!X:X) -> 0.52227839 | Y3: ='O-PTIR'!Y3/MAX('O-PTIR'!Y:Y) -> 0.44332874 | Z3: ='O-PTIR'!Z3/MAX('O-PTIR'!Z:Z) -> 0.53978207 | AA3: ='O-PTIR'!AA3/MAX('O-PTIR'!AA:AA) -> 0.084225128 | AB3: ='O-PTIR'!AB3/MAX('O-PTIR'!AB:AB) -> 0.0012461022 | AC3: ='O-PTIR'!AC3/MAX('O-PTIR'!AC:AC) -> 0.0091131961 | AD3: ='O-PTIR'!AD3/MAX('O-PTIR'!AD:AD) -> 0.2232819 | AE3: ='O-PTIR'!AE3/MAX('O-PTIR'!AE:AE) -> -15.63791 | AF3: ='O-PTIR'!AF3/MAX('O-PTIR'!AF:AF) -> -0.001211282 | AG3: ='O-PTIR'!AG3/MAX('O-PTIR'!AG:AG) -> -0.58188708 | AH3: ='O-PTIR'!AH3/MAX('O-PTIR'!AH:AH) -> 1 | AI3: ='O-PTIR'!AI3/MAX('O-PTIR'!AI:AI) -> 0.46285048 | AJ3: ='O-PTIR'!AJ3/MAX('O-PTIR'!AJ:AJ) -> -0.057304437 | AK3: ='O-PTIR'!AK3/MAX('O-PTIR'!AK:AK) -> 0.13901576 | AL3: ='O-PTIR'!AL3/MAX('O-PTIR'!AL:AL) -> -0.9134583 | AM3: ='O-PTIR'!AM3/MAX('O-PTIR'!AM:AM) -> 0.31682566 | AN3: ='O-PTIR'!AN3/MAX('O-PTIR'!AN:AN) -> 0.01811433 | AO3: ='O-PTIR'!AO3/MAX('O-PTIR'!AO:AO) -> 0.21440734 | AP3: ='O-PTIR'!AP3/MAX('O-PTIR'!AP:AP) -> 0.55171659 | AQ3: ='O-PTIR'!AQ3/MAX('O-PTIR'!AQ:AQ) -> 0.31880101 | AR3: ='O-PTIR'!AR3/MAX('O-PTIR'!AR:AR) -> 0.037543884 | AS3: ='O-PTIR'!AS3/MAX('O-PTIR'!AS:AS) -> -0.013591514 | AT3: ='O-PTIR'!AT3/MAX('O-PTIR'!AT:AT) -> 0.0024496297 | AU3: ='O-PTIR'!AU3/MAX('O-PTIR'!AU:AU) -> 0.13441573 | AV3: ='O-PTIR'!AV3/MAX('O-PTIR'!AV:AV) -> -1.4647645 | AW3: ='O-PTIR'!AW3/MAX('O-PTIR'!AW:AW) -> 0.13282293 | AX3: ='O-PTIR'!AX3/MAX('O-PTIR'!AX:AX) -> -1.4205425 | AY3: ='O-PTIR'!AY3/MAX('O-PTIR'!AY:AY) -> 0.023342476 | AZ3: ='O-PTIR'!AZ3/MAX('O-PTIR'!AZ:AZ) -> 0.087078452 | BA3: ='O-PTIR'!BA3/MAX('O-PTIR'!BA:BA) -> -0.23338746 | BB3: ='O-PTIR'!BB3/MAX('O-PTIR'!BB:BB) -> 0.20503593
A4: 952 | B4: ='O-PTIR'!B4/MAX('O-PTIR'!B:B) -> -0.013403193 | C4: ='O-PTIR'!C4/MAX('O-PTIR'!C:C) -> 0.38646578 | D4: ='O-PTIR'!D4/MAX('O-PTIR'!D:D) -> 0.32398573 | E4: ='O-PTIR'!E4/MAX('O-PTIR'!E:E) -> 0.26666892 | F4: ='O-PTIR'!F4/MAX('O-PTIR'!F:F) -> 0.38478205 | G4: ='O-PTIR'!G4/MAX('O-PTIR'!G:G) -> -0.057442471 | H4: ='O-PTIR'!H4/MAX('O-PTIR'!H:H) -> -21.314718 | I4: ='O-PTIR'!I4/MAX('O-PTIR'!I:I) -> -0.044532405 | J4: ='O-PTIR'!J4/MAX('O-PTIR'!J:J) -> 0.069804654 | K4: ='O-PTIR'!K4/MAX('O-PTIR'!K:K) -> 0.04588474 | L4: ='O-PTIR'!L4/MAX('O-PTIR'!L:L) -> 0.11676675 | M4: ='O-PTIR'!M4/MAX('O-PTIR'!M:M) -> -0.082895539 | N4: ='O-PTIR'!N4/MAX('O-PTIR'!N:N) -> -0.52044978 | O4: ='O-PTIR'!O4/MAX('O-PTIR'!O:O) -> -0.7260015 | P4: ='O-PTIR'!P4/MAX('O-PTIR'!P:P) -> 0.10046216 | Q4: ='O-PTIR'!Q4/MAX('O-PTIR'!Q:Q) -> 0.096748533 | R4: ='O-PTIR'!R4/MAX('O-PTIR'!R:R) -> 0.13701578 | S4: ='O-PTIR'!S4/MAX('O-PTIR'!S:S) -> 0.25229131 | T4: ='O-PTIR'!T4/MAX('O-PTIR'!T:T) -> 0.11252981 | U4: ='O-PTIR'!U4/MAX('O-PTIR'!U:U) -> -0.37114713 | V4: ='O-PTIR'!V4/MAX('O-PTIR'!V:V) -> -0.19469415 | W4: ='O-PTIR'!W4/MAX('O-PTIR'!W:W) -> -0.039251989 | X4: ='O-PTIR'!X4/MAX('O-PTIR'!X:X) -> 0.073121455 | Y4: ='O-PTIR'!Y4/MAX('O-PTIR'!Y:Y) -> -0.2437048 | Z4: ='O-PTIR'!Z4/MAX('O-PTIR'!Z:Z) -> 0.16988928 | AA4: ='O-PTIR'!AA4/MAX('O-PTIR'!AA:AA) -> -0.20753158 | AB4: ='O-PTIR'!AB4/MAX('O-PTIR'!AB:AB) -> -0.035120809 | AC4: ='O-PTIR'!AC4/MAX('O-PTIR'!AC:AC) -> -0.0070974148 | AD4: ='O-PTIR'!AD4/MAX('O-PTIR'!AD:AD) -> 0.0055919831 | AE4: ='O-PTIR'!AE4/MAX('O-PTIR'!AE:AE) -> -13.634951 | AF4: ='O-PTIR'!AF4/MAX('O-PTIR'!AF:AF) -> 0.037159044 | AG4: ='O-PTIR'!AG4/MAX('O-PTIR'!AG:AG) -> -0.16390531 | AH4: ='O-PTIR'!AH4/MAX('O-PTIR'!AH:AH) -> 0.37054751 | AI4: ='O-PTIR'!AI4/MAX('O-PTIR'!AI:AI) -> -0.59006191 | AJ4: ='O-PTIR'!AJ4/MAX('O-PTIR'!AJ:AJ) -> 0.1015295 | AK4: ='O-PTIR'!AK4/MAX('O-PTIR'!AK:AK) -> -0.016645522 | AL4: ='O-PTIR'!AL4/MAX('O-PTIR'!AL:AL) -> -0.78112494 | AM4: ='O-PTIR'!AM4/MAX('O-PTIR'!AM:AM) -> 0.71566081 | AN4: ='O-PTIR'!AN4/MAX('O-PTIR'!AN:AN) -> -0.095129492 | AO4: ='O-PTIR'!AO4/MAX('O-PTIR'!AO:AO) -> 0.12566831 | AP4: ='O-PTIR'!AP4/MAX('O-PTIR'!AP:AP) -> -9.5591467e-05 | AQ4: ='O-PTIR'!AQ4/MAX('O-PTIR'!AQ:AQ) -> 0.0097189756 | AR4: ='O-PTIR'!AR4/MAX('O-PTIR'!AR:AR) -> -0.2575939 | AS4: ='O-PTIR'!AS4/MAX('O-PTIR'!AS:AS) -> -0.13056305 | AT4: ='O-PTIR'!AT4/MAX('O-PTIR'!AT:AT) -> -0.062940699 | AU4: ='O-PTIR'!AU4/MAX('O-PTIR'!AU:AU) -> 0.093457867 | AV4: ='O-PTIR'!AV4/MAX('O-PTIR'!AV:AV) -> -3.3704125 | AW4: ='O-PTIR'!AW4/MAX('O-PTIR'!AW:AW) -> 0.03791895 | AX4: ='O-PTIR'!AX4/MAX('O-PTIR'!AX:AX) -> -0.33508678 | AY4: ='O-PTIR'!AY4/MAX('O-PTIR'!AY:AY) -> 0.042740091 | AZ4: ='O-PTIR'!AZ4/MAX('O-PTIR'!AZ:AZ) -> -0.26713967 | BA4: ='O-PTIR'!BA4/MAX('O-PTIR'!BA:BA) -> 0.26975658 | BB4: ='O-PTIR'!BB4/MAX('O-PTIR'!BB:BB) -> -0.067287126
A5: 954 | B5: ='O-PTIR'!B5/MAX('O-PTIR'!B:B) -> 0.053123346 | C5: ='O-PTIR'!C5/MAX('O-PTIR'!C:C) -> 0.3149609 | D5: ='O-PTIR'!D5/MAX('O-PTIR'!D:D) -> 0.44869306 | E5: ='O-PTIR'!E5/MAX('O-PTIR'!E:E) -> 0.017148611 | F5: ='O-PTIR'!F5/MAX('O-PTIR'!F:F) -> -0.12077915 | G5: ='O-PTIR'!G5/MAX('O-PTIR'!G:G) -> -0.12558269 | H5: ='O-PTIR'!H5/MAX('O-PTIR'!H:H) -> -12.80063 | I5: ='O-PTIR'!I5/MAX('O-PTIR'!I:I) -> 0.10703085 | J5: ='O-PTIR'!J5/MAX('O-PTIR'!J:J) -> -0.040540698 | K5: ='O-PTIR'!K5/MAX('O-PTIR'!K:K) -> -0.11540482 | L5: ='O-PTIR'!L5/MAX('O-PTIR'!L:L) -> 0.33946329 | M5: ='O-PTIR'!M5/MAX('O-PTIR'!M:M) -> 0.10841507 | N5: ='O-PTIR'!N5/MAX('O-PTIR'!N:N) -> -0.54512591 | O5: ='O-PTIR'!O5/MAX('O-PTIR'!O:O) -> -0.8651647 | P5: ='O-PTIR'!P5/MAX('O-PTIR'!P:P) -> -0.15086604 | Q5: ='O-PTIR'!Q5/MAX('O-PTIR'!Q:Q) -> 0.16358505 | R5: ='O-PTIR'!R5/MAX('O-PTIR'!R:R) -> 0.23791759 | S5: ='O-PTIR'!S5/MAX('O-PTIR'!S:S) -> 0.10539091 | T5: ='O-PTIR'!T5/MAX('O-PTIR'!T:T) -> 0.11189978 | U5: ='O-PTIR'!U5/MAX('O-PTIR'!U:U) -> -0.12046341 | V5: ='O-PTIR'!V5/MAX('O-PTIR'!V:V) -> -0.099525294 | W5: ='O-PTIR'!W5/MAX('O-PTIR'!W:W) -> -0.10300438 | X5: ='O-PTIR'!X5/MAX('O-PTIR'!X:X) -> 0.0095691234 | Y5: ='O-PTIR'!Y5/MAX('O-PTIR'!Y:Y) -> 0.0096173573 | Z5: ='O-PTIR'!Z5/MAX('O-PTIR'!Z:Z) -> 0.26176729 | AA5: ='O-PTIR'!AA5/MAX('O-PTIR'!AA:AA) -> -0.21146548 | AB5: ='O-PTIR'!AB5/MAX('O-PTIR'!AB:AB) -> -0.026483614 | AC5: ='O-PTIR'!AC5/MAX('O-PTIR'!AC:AC) -> -0.017209215 | AD5: ='O-PTIR'!AD5/MAX('O-PTIR'!AD:AD) -> 0.050920439 | AE5: ='O-PTIR'!AE5/MAX('O-PTIR'!AE:AE) -> -7.3798674 | AF5: ='O-PTIR'!AF5/MAX('O-PTIR'!AF:AF) -> 0.020659813 | AG5: ='O-PTIR'!AG5/MAX('O-PTIR'!AG:AG) -> -0.14511281 | AH5: ='O-PTIR'!AH5/MAX('O-PTIR'!AH:AH) -> 0.61542741 | AI5: ='O-PTIR'!AI5/MAX('O-PTIR'!AI:AI) -> -0.2123542 | AJ5: ='O-PTIR'!AJ5/MAX('O-PTIR'!AJ:AJ) -> -0.055063666 | AK5: ='O-PTIR'!AK5/MAX('O-PTIR'!AK:AK) -> -0.084058271 | AL5: ='O-PTIR'!AL5/MAX('O-PTIR'!AL:AL) -> -0.43881822 | AM5: ='O-PTIR'!AM5/MAX('O-PTIR'!AM:AM) -> 0.23089945 | AN5: ='O-PTIR'!AN5/MAX('O-PTIR'!AN:AN) -> 0.095444421 | AO5: ='O-PTIR'!AO5/MAX('O-PTIR'!AO:AO) -> 0.38394798 | AP5: ='O-PTIR'!AP5/MAX('O-PTIR'!AP:AP) -> 0.26215569 | AQ5: ='O-PTIR'!AQ5/MAX('O-PTIR'!AQ:AQ) -> -0.13891754 | AR5: ='O-PTIR'!AR5/MAX('O-PTIR'!AR:AR) -> -0.015762964 | AS5: ='O-PTIR'!AS5/MAX('O-PTIR'!AS:AS) -> 0.12261857 | AT5: ='O-PTIR'!AT5/MAX('O-PTIR'!AT:AT) -> -0.052519725 | AU5: ='O-PTIR'!AU5/MAX('O-PTIR'!AU:AU) -> -0.12831035 | AV5: ='O-PTIR'!AV5/MAX('O-PTIR'!AV:AV) -> -3.6903045 | AW5: ='O-PTIR'!AW5/MAX('O-PTIR'!AW:AW) -> 0.2623521 | AX5: ='O-PTIR'!AX5/MAX('O-PTIR'!AX:AX) -> -0.82207776 | AY5: ='O-PTIR'!AY5/MAX('O-PTIR'!AY:AY) -> 0.098504603 | AZ5: ='O-PTIR'!AZ5/MAX('O-PTIR'!AZ:AZ) -> 0.056752438 | BA5: ='O-PTIR'!BA5/MAX('O-PTIR'!BA:BA) -> 0.011004841 | BB5: ='O-PTIR'!BB5/MAX('O-PTIR'!BB:BB) -> -0.0092312445
A6: 956 | B6: ='O-PTIR'!B6/MAX('O-PTIR'!B:B) -> -0.0090861543 | C6: ='O-PTIR'!C6/MAX('O-PTIR'!C:C) -> 0.13386277 | D6: ='O-PTIR'!D6/MAX('O-PTIR'!D:D) -> 0.25387627 | E6: ='O-PTIR'!E6/MAX('O-PTIR'!E:E) -> 0.1507308 | F6: ='O-PTIR'!F6/MAX('O-PTIR'!F:F) -> -0.29062491 | G6: ='O-PTIR'!G6/MAX('O-PTIR'!G:G) -> -0.0086009913 | H6: ='O-PTIR'!H6/MAX('O-PTIR'!H:H) -> -8.7853829 | I6: ='O-PTIR'!I6/MAX('O-PTIR'!I:I) -> -0.060728315 | J6: ='O-PTIR'!J6/MAX('O-PTIR'!J:J) -> 0.09015161 | K6: ='O-PTIR'!K6/MAX('O-PTIR'!K:K) -> 0.026252371 | L6: ='O-PTIR'!L6/MAX('O-PTIR'!L:L) -> 0.55717529 | M6: ='O-PTIR'!M6/MAX('O-PTIR'!M:M) -> 0.021729408 | N6: ='O-PTIR'!N6/MAX('O-PTIR'!N:N) -> 0.35399123 | O6: ='O-PTIR'!O6/MAX('O-PTIR'!O:O) -> -1.0567959 | P6: ='O-PTIR'!P6/MAX('O-PTIR'!P:P) -> 0.10368412 | Q6: ='O-PTIR'!Q6/MAX('O-PTIR'!Q:Q) -> 0.20324295 | R6: ='O-PTIR'!R6/MAX('O-PTIR'!R:R) -> 0.23498689 | S6: ='O-PTIR'!S6/MAX('O-PTIR'!S:S) -> 0.19264331 | T6: ='O-PTIR'!T6/MAX('O-PTIR'!T:T) -> -0.021093858 | U6: ='O-PTIR'!U6/MAX('O-PTIR'!U:U) -> 0.025090213 | V6: ='O-PTIR'!V6/MAX('O-PTIR'!V:V) -> -0.20889977 | W6: ='O-PTIR'!W6/MAX('O-PTIR'!W:W) -> -0.082471959 | X6: ='O-PTIR'!X6/MAX('O-PTIR'!X:X) -> -0.080063089 | Y6: ='O-PTIR'!Y6/MAX('O-PTIR'!Y:Y) -> 0.12284801 | Z6: ='O-PTIR'!Z6/MAX('O-PTIR'!Z:Z) -> 0.39766952 | AA6: ='O-PTIR'!AA6/MAX('O-PTIR'!AA:AA) -> -0.25680358 | AB6: ='O-PTIR'!AB6/MAX('O-PTIR'!AB:AB) -> -0.0037546074 | AC6: ='O-PTIR'!AC6/MAX('O-PTIR'!AC:AC) -> -0.012930656 | AD6: ='O-PTIR'!AD6/MAX('O-PTIR'!AD:AD) -> 0.1078894 | AE6: ='O-PTIR'!AE6/MAX('O-PTIR'!AE:AE) -> -4.4459874 | AF6: ='O-PTIR'!AF6/MAX('O-PTIR'!AF:AF) -> 0.017631839 | AG6: ='O-PTIR'!AG6/MAX('O-PTIR'!AG:AG) -> 0.041184235 | AH6: ='O-PTIR'!AH6/MAX('O-PTIR'!AH:AH) -> 0.49552231 | AI6: ='O-PTIR'!AI6/MAX('O-PTIR'!AI:AI) -> -0.31727335 | AJ6: ='O-PTIR'!AJ6/MAX('O-PTIR'!AJ:AJ) -> 0.14515843 | AK6: ='O-PTIR'!AK6/MAX('O-PTIR'!AK:AK) -> 0.0024768856 | AL6: ='O-PTIR'!AL6/MAX('O-PTIR'!AL:AL) -> -0.4380422 | AM6: ='O-PTIR'!AM6/MAX('O-PTIR'!AM:AM) -> 0.14131212 | AN6: ='O-PTIR'!AN6/MAX('O-PTIR'!AN:AN) -> -0.020850025 | AO6: ='O-PTIR'!AO6/MAX('O-PTIR'!AO:AO) -> 0.040714184 | AP6: ='O-PTIR'!AP6/MAX('O-PTIR'!AP:AP) -> 0.30111345 | AQ6: ='O-PTIR'!AQ6/MAX('O-PTIR'!AQ:AQ) -> -0.2400958 | AR6: ='O-PTIR'!AR6/MAX('O-PTIR'!AR:AR) -> 0.56180075 | AS6: ='O-PTIR'!AS6/MAX('O-PTIR'!AS:AS) -> -0.17102975 | AT6: ='O-PTIR'!AT6/MAX('O-PTIR'!AT:AT) -> 0.0737662 | AU6: ='O-PTIR'!AU6/MAX('O-PTIR'!AU:AU) -> -0.11161083 | AV6: ='O-PTIR'!AV6/MAX('O-PTIR'!AV:AV) -> -1.051143 | AW6: ='O-PTIR'!AW6/MAX('O-PTIR'!AW:AW) -> 0.091841555 | AX6: ='O-PTIR'!AX6/MAX('O-PTIR'!AX:AX) -> -0.18608051 | AY6: ='O-PTIR'!AY6/MAX('O-PTIR'!AY:AY) -> 0.062296802 | AZ6: ='O-PTIR'!AZ6/MAX('O-PTIR'!AZ:AZ) -> -0.19122938 | BA6: ='O-PTIR'!BA6/MAX('O-PTIR'!BA:BA) -> -0.093725185 | BB6: ='O-PTIR'!BB6/MAX('O-PTIR'!BB:BB) -> 0.051411107
A7: 958 | B7: ='O-PTIR'!B7/MAX('O-PTIR'!B:B) -> 0.048756001 | C7: ='O-PTIR'!C7/MAX('O-PTIR'!C:C) -> 0.38383688 | D7: ='O-PTIR'!D7/MAX('O-PTIR'!D:D) -> 0.19786612 | E7: ='O-PTIR'!E7/MAX('O-PTIR'!E:E) -> 0.17261899 | F7: ='O-PTIR'!F7/MAX('O-PTIR'!F:F) -> -0.30167073 | G7: ='O-PTIR'!G7/MAX('O-PTIR'!G:G) -> -0.4354015 | H7: ='O-PTIR'!H7/MAX('O-PTIR'!H:H) -> -7.943803 | I7: ='O-PTIR'!I7/MAX('O-PTIR'!I:I) -> -0.216245 | J7: ='O-PTIR'!J7/MAX('O-PTIR'!J:J) -> 0.093065398 | K7: ='O-PTIR'!K7/MAX('O-PTIR'!K:K) -> -0.041426776 | L7: ='O-PTIR'!L7/MAX('O-PTIR'!L:L) -> -0.010285337 | M7: ='O-PTIR'!M7/MAX('O-PTIR'!M:M) -> 0.11949506 | N7: ='O-PTIR'!N7/MAX('O-PTIR'!N:N) -> 0.051341319 | O7: ='O-PTIR'!O7/MAX('O-PTIR'!O:O) -> -0.59968877 | P7: ='O-PTIR'!P7/MAX('O-PTIR'!P:P) -> 0.035651289 | Q7: ='O-PTIR'!Q7/MAX('O-PTIR'!Q:Q) -> 0.16584064 | R7: ='O-PTIR'!R7/MAX('O-PTIR'!R:R) -> 0.14833927 | S7: ='O-PTIR'!S7/MAX('O-PTIR'!S:S) -> -0.13557101 | T7: ='O-PTIR'!T7/MAX('O-PTIR'!T:T) -> 0.15544362 | U7: ='O-PTIR'!U7/MAX('O-PTIR'!U:U) -> 0.19874896 | V7: ='O-PTIR'!V7/MAX('O-PTIR'!V:V) -> 0.016481703 | W7: ='O-PTIR'!W7/MAX('O-PTIR'!W:W) -> 0.13753283 | X7: ='O-PTIR'!X7/MAX('O-PTIR'!X:X) -> 0.10704889 | Y7: ='O-PTIR'!Y7/MAX('O-PTIR'!Y:Y) -> 0.08936789 | Z7: ='O-PTIR'!Z7/MAX('O-PTIR'!Z:Z) -> 0.071975135 | AA7: ='O-PTIR'!AA7/MAX('O-PTIR'!AA:AA) -> -0.13330283 | AB7: ='O-PTIR'!AB7/MAX('O-PTIR'!AB:AB) -> -0.0020154492 | AC7: ='O-PTIR'!AC7/MAX('O-PTIR'!AC:AC) -> -0.020478386 | AD7: ='O-PTIR'!AD7/MAX('O-PTIR'!AD:AD) -> 0.050705941 | AE7: ='O-PTIR'!AE7/MAX('O-PTIR'!AE:AE) -> -4.1148618 | AF7: ='O-PTIR'!AF7/MAX('O-PTIR'!AF:AF) -> 0.035304934 | AG7: ='O-PTIR'!AG7/MAX('O-PTIR'!AG:AG) -> 0.075478124 | AH7: ='O-PTIR'!AH7/MAX('O-PTIR'!AH:AH) -> 0.49963845 | AI7: ='O-PTIR'!AI7/MAX('O-PTIR'!AI:AI) -> -0.075100553 | AJ7: ='O-PTIR'!AJ7/MAX('O-PTIR'!AJ:AJ) -> -0.040616723 | AK7: ='O-PTIR'!AK7/MAX('O-PTIR'!AK:AK) -> 0.19230008 | AL7: ='O-PTIR'!AL7/MAX('O-PTIR'!AL:AL) -> -0.52586806 | AM7: ='O-PTIR'!AM7/MAX('O-PTIR'!AM:AM) -> -0.054843182 | AN7: ='O-PTIR'!AN7/MAX('O-PTIR'!AN:AN) -> 0.11897311 | AO7: ='O-PTIR'!AO7/MAX('O-PTIR'!AO:AO) -> -0.12486119 | AP7: ='O-PTIR'!AP7/MAX('O-PTIR'!AP:AP) -> 0.19114141 | AQ7: ='O-PTIR'!AQ7/MAX('O-PTIR'!AQ:AQ) -> -0.12056347 | AR7: ='O-PTIR'!AR7/MAX('O-PTIR'!AR:AR) -> 0.34080529 | AS7: ='O-PTIR'!AS7/MAX('O-PTIR'!AS:AS) -> -0.12221085 | AT7: ='O-PTIR'!AT7/MAX('O-PTIR'!AT:AT) -> 0.24729999 | AU7: ='O-PTIR'!AU7/MAX('O-PTIR'!AU:AU) -> -0.13892244 | AV7: ='O-PTIR'!AV7/MAX('O-PTIR'!AV:AV) -> -0.92327199 | AW7: ='O-PTIR'!AW7/MAX('O-PTIR'!AW:AW) -> 0.2087893 | AX7: ='O-PTIR'!AX7/MAX('O-PTIR'!AX:AX) -> 0.060018246 | AY7: ='O-PTIR'!AY7/MAX('O-PTIR'!AY:AY) -> -0.058715504 | AZ7: ='O-PTIR'!AZ7/MAX('O-PTIR'!AZ:AZ) -> -0.045999241 | BA7: ='O-PTIR'!BA7/MAX('O-PTIR'!BA:BA) -> -0.36703089 | BB7: ='O-PTIR'!BB7/MAX('O-PTIR'!BB:BB) -> -0.027128092
A8: 960 | B8: ='O-PTIR'!B8/MAX('O-PTIR'!B:B) -> -0.021090474 | C8: ='O-PTIR'!C8/MAX('O-PTIR'!C:C) -> 0.29317828 | D8: ='O-PTIR'!D8/MAX('O-PTIR'!D:D) -> -0.1106967 | E8: ='O-PTIR'!E8/MAX('O-PTIR'!E:E) -> 0.071992172 | F8: ='O-PTIR'!F8/MAX('O-PTIR'!F:F) -> -0.11878751 | G8: ='O-PTIR'!G8/MAX('O-PTIR'!G:G) -> -0.23990267 | H8: ='O-PTIR'!H8/MAX('O-PTIR'!H:H) -> -4.8584093 | I8: ='O-PTIR'!I8/MAX('O-PTIR'!I:I) -> -0.025936193 | J8: ='O-PTIR'!J8/MAX('O-PTIR'!J:J) -> -0.0063254678 | K8: ='O-PTIR'!K8/MAX('O-PTIR'!K:K) -> 0.011218334 | L8: ='O-PTIR'!L8/MAX('O-PTIR'!L:L) -> 0.0040608821 | M8: ='O-PTIR'!M8/MAX('O-PTIR'!M:M) -> 0.06787776 | N8: ='O-PTIR'!N8/MAX('O-PTIR'!N:N) -> 0.047934053 | O8: ='O-PTIR'!O8/MAX('O-PTIR'!O:O) -> -1.3644081 | P8: ='O-PTIR'!P8/MAX('O-PTIR'!P:P) -> 0.026316108 | Q8: ='O-PTIR'!Q8/MAX('O-PTIR'!Q:Q) -> 0.042879701 | R8: ='O-PTIR'!R8/MAX('O-PTIR'!R:R) -> 0.23415235 | S8: ='O-PTIR'!S8/MAX('O-PTIR'!S:S) -> 0.04069837 | T8: ='O-PTIR'!T8/MAX('O-PTIR'!T:T) -> 0.16690596 | U8: ='O-PTIR'!U8/MAX('O-PTIR'!U:U) -> 0.078276259 | V8: ='O-PTIR'!V8/MAX('O-PTIR'!V:V) -> -0.018275375 | W8: ='O-PTIR'!W8/MAX('O-PTIR'!W:W) -> 0.093684504 | X8: ='O-PTIR'!X8/MAX('O-PTIR'!X:X) -> 0.17878115 | Y8: ='O-PTIR'!Y8/MAX('O-PTIR'!Y:Y) -> 0.038238946 | Z8: ='O-PTIR'!Z8/MAX('O-PTIR'!Z:Z) -> -0.22773706 | AA8: ='O-PTIR'!AA8/MAX('O-PTIR'!AA:AA) -> -0.028483778 | AB8: ='O-PTIR'!AB8/MAX('O-PTIR'!AB:AB) -> -0.002839006 | AC8: ='O-PTIR'!AC8/MAX('O-PTIR'!AC:AC) -> 0.018147902 | AD8: ='O-PTIR'!AD8/MAX('O-PTIR'!AD:AD) -> -0.024020364 | AE8: ='O-PTIR'!AE8/MAX('O-PTIR'!AE:AE) -> -5.0134651 | AF8: ='O-PTIR'!AF8/MAX('O-PTIR'!AF:AF) -> 0.027468734 | AG8: ='O-PTIR'!AG8/MAX('O-PTIR'!AG:AG) -> 0.27259014 | AH8: ='O-PTIR'!AH8/MAX('O-PTIR'!AH:AH) -> 0.13725472 | AI8: ='O-PTIR'!AI8/MAX('O-PTIR'!AI:AI) -> 0.044077424 | AJ8: ='O-PTIR'!AJ8/MAX('O-PTIR'!AJ:AJ) -> 0.12227525 | AK8: ='O-PTIR'!AK8/MAX('O-PTIR'!AK:AK) -> 0.15578977 | AL8: ='O-PTIR'!AL8/MAX('O-PTIR'!AL:AL) -> -0.42243086 | AM8: ='O-PTIR'!AM8/MAX('O-PTIR'!AM:AM) -> -0.1700607 | AN8: ='O-PTIR'!AN8/MAX('O-PTIR'!AN:AN) -> 0.010545527 | AO8: ='O-PTIR'!AO8/MAX('O-PTIR'!AO:AO) -> -0.065245368 | AP8: ='O-PTIR'!AP8/MAX('O-PTIR'!AP:AP) -> 0.14260283 | AQ8: ='O-PTIR'!AQ8/MAX('O-PTIR'!AQ:AQ) -> -0.020099886 | AR8: ='O-PTIR'!AR8/MAX('O-PTIR'!AR:AR) -> 0.31611014 | AS8: ='O-PTIR'!AS8/MAX('O-PTIR'!AS:AS) -> 0.03270297 | AT8: ='O-PTIR'!AT8/MAX('O-PTIR'!AT:AT) -> 0.056016136 | AU8: ='O-PTIR'!AU8/MAX('O-PTIR'!AU:AU) -> 0.064557709 | AV8: ='O-PTIR'!AV8/MAX('O-PTIR'!AV:AV) -> -1.2613188 | AW8: ='O-PTIR'!AW8/MAX('O-PTIR'!AW:AW) -> -0.077948767 | AX8: ='O-PTIR'!AX8/MAX('O-PTIR'!AX:AX) -> -0.086840805 | AY8: ='O-PTIR'!AY8/MAX('O-PTIR'!AY:AY) -> -0.13126338 | AZ8: ='O-PTIR'!AZ8/MAX('O-PTIR'!AZ:AZ) -> -0.30777698 | BA8: ='O-PTIR'!BA8/MAX('O-PTIR'!BA:BA) -> -0.13953399 | BB8: ='O-PTIR'!BB8/MAX('O-PTIR'!BB:BB) -> 0.062986652
A9: 962 | B9: ='O-PTIR'!B9/MAX('O-PTIR'!B:B) -> -0.025738117 | C9: ='O-PTIR'!C9/MAX('O-PTIR'!C:C) -> 0.29704638 | D9: ='O-PTIR'!D9/MAX('O-PTIR'!D:D) -> -0.02470644 | E9: ='O-PTIR'!E9/MAX('O-PTIR'!E:E) -> 0.1896608 | F9: ='O-PTIR'!F9/MAX('O-PTIR'!F:F) -> -0.32639379 | G9: ='O-PTIR'!G9/MAX('O-PTIR'!G:G) -> -0.056898022 | H9: ='O-PTIR'!H9/MAX('O-PTIR'!H:H) -> -10.466038 | I9: ='O-PTIR'!I9/MAX('O-PTIR'!I:I) -> 0.14829051 | J9: ='O-PTIR'!J9/MAX('O-PTIR'!J:J) -> 0.086420712 | K9: ='O-PTIR'!K9/MAX('O-PTIR'!K:K) -> 0.096476755 | L9: ='O-PTIR'!L9/MAX('O-PTIR'!L:L) -> 0.019584803 | M9: ='O-PTIR'!M9/MAX('O-PTIR'!M:M) -> 0.021586512 | N9: ='O-PTIR'!N9/MAX('O-PTIR'!N:N) -> 0.093858289 | O9: ='O-PTIR'!O9/MAX('O-PTIR'!O:O) -> -0.50781268 | P9: ='O-PTIR'!P9/MAX('O-PTIR'!P:P) -> 0.11569479 | Q9: ='O-PTIR'!Q9/MAX('O-PTIR'!Q:Q) -> 0.050194302 | R9: ='O-PTIR'!R9/MAX('O-PTIR'!R:R) -> 0.36998231 | S9: ='O-PTIR'!S9/MAX('O-PTIR'!S:S) -> 0.14624029 | T9: ='O-PTIR'!T9/MAX('O-PTIR'!T:T) -> 0.08657519 | U9: ='O-PTIR'!U9/MAX('O-PTIR'!U:U) -> 0.014883413 | V9: ='O-PTIR'!V9/MAX('O-PTIR'!V:V) -> -0.11035449 | W9: ='O-PTIR'!W9/MAX('O-PTIR'!W:W) -> 0.14354584 | X9: ='O-PTIR'!X9/MAX('O-PTIR'!X:X) -> 0.14707308 | Y9: ='O-PTIR'!Y9/MAX('O-PTIR'!Y:Y) -> -0.11668984 | Z9: ='O-PTIR'!Z9/MAX('O-PTIR'!Z:Z) -> -0.26181202 | AA9: ='O-PTIR'!AA9/MAX('O-PTIR'!AA:AA) -> -0.088208778 | AB9: ='O-PTIR'!AB9/MAX('O-PTIR'!AB:AB) -> -0.025707554 | AC9: ='O-PTIR'!AC9/MAX('O-PTIR'!AC:AC) -> -0.008735905 | AD9: ='O-PTIR'!AD9/MAX('O-PTIR'!AD:AD) -> 0.010435446 | AE9: ='O-PTIR'!AE9/MAX('O-PTIR'!AE:AE) -> -4.8539539 | AF9: ='O-PTIR'!AF9/MAX('O-PTIR'!AF:AF) -> 0.053818489 | AG9: ='O-PTIR'!AG9/MAX('O-PTIR'!AG:AG) -> 0.089939908 | AH9: ='O-PTIR'!AH9/MAX('O-PTIR'!AH:AH) -> 0.18173762 | AI9: ='O-PTIR'!AI9/MAX('O-PTIR'!AI:AI) -> -0.11081449 | AJ9: ='O-PTIR'!AJ9/MAX('O-PTIR'!AJ:AJ) -> 0.16063613 | AK9: ='O-PTIR'!AK9/MAX('O-PTIR'!AK:AK) -> 0.060809551 | AL9: ='O-PTIR'!AL9/MAX('O-PTIR'!AL:AL) -> -0.16446637 | AM9: ='O-PTIR'!AM9/MAX('O-PTIR'!AM:AM) -> -0.10598441 | AN9: ='O-PTIR'!AN9/MAX('O-PTIR'!AN:AN) -> 0.01581572 | AO9: ='O-PTIR'!AO9/MAX('O-PTIR'!AO:AO) -> 0.1886115 | AP9: ='O-PTIR'!AP9/MAX('O-PTIR'!AP:AP) -> 0.14989587 | AQ9: ='O-PTIR'!AQ9/MAX('O-PTIR'!AQ:AQ) -> 0.036617543 | AR9: ='O-PTIR'!AR9/MAX('O-PTIR'!AR:AR) -> -0.022836105 | AS9: ='O-PTIR'!AS9/MAX('O-PTIR'!AS:AS) -> -0.10020553 | AT9: ='O-PTIR'!AT9/MAX('O-PTIR'!AT:AT) -> -0.038338073 | AU9: ='O-PTIR'!AU9/MAX('O-PTIR'!AU:AU) -> -0.035652799 | AV9: ='O-PTIR'!AV9/MAX('O-PTIR'!AV:AV) -> -1.0605617 | AW9: ='O-PTIR'!AW9/MAX('O-PTIR'!AW:AW) -> -0.15466993 | AX9: ='O-PTIR'!AX9/MAX('O-PTIR'!AX:AX) -> 0.14880235 | AY9: ='O-PTIR'!AY9/MAX('O-PTIR'!AY:AY) -> -0.087572368 | AZ9: ='O-PTIR'!AZ9/MAX('O-PTIR'!AZ:AZ) -> -0.29739264 | BA9: ='O-PTIR'!BA9/MAX('O-PTIR'!BA:BA) -> -0.21220778 | BB9: ='O-PTIR'!BB9/MAX('O-PTIR'!BB:BB) -> 0.042259746
A10: 964 | B10: ='O-PTIR'!B10/MAX('O-PTIR'!B:B) -> -0.016060008 | C10: ='O-PTIR'!C10/MAX('O-PTIR'!C:C) -> 0.1842919 | D10: ='O-PTIR'!D10/MAX('O-PTIR'!D:D) -> 0.040622371 | E10: ='O-PTIR'!E10/MAX('O-PTIR'!E:E) -> 0.088114479 | F10: ='O-PTIR'!F10/MAX('O-PTIR'!F:F) -> -0.03998234 | G10: ='O-PTIR'!G10/MAX('O-PTIR'!G:G) -> -0.023640665 | H10: ='O-PTIR'!H10/MAX('O-PTIR'!H:H) -> -12.971837 | I10: ='O-PTIR'!I10/MAX('O-PTIR'!I:I) -> 0.23149988 | J10: ='O-PTIR'!J10/MAX('O-PTIR'!J:J) -> 0.13466355 | K10: ='O-PTIR'!K10/MAX('O-PTIR'!K:K) -> 0.11542666 | L10: ='O-PTIR'!L10/MAX('O-PTIR'!L:L) -> 0.31358483 | M10: ='O-PTIR'!M10/MAX('O-PTIR'!M:M) -> 0.0099966426 | N10: ='O-PTIR'!N10/MAX('O-PTIR'!N:N) -> 0.054683087 | O10: ='O-PTIR'!O10/MAX('O-PTIR'!O:O) -> 0.35052282 | P10: ='O-PTIR'!P10/MAX('O-PTIR'!P:P) -> 0.13924529 | Q10: ='O-PTIR'!Q10/MAX('O-PTIR'!Q:Q) -> 0.049560154 | R10: ='O-PTIR'!R10/MAX('O-PTIR'!R:R) -> 0.01187824 | S10: ='O-PTIR'!S10/MAX('O-PTIR'!S:S) -> 0.17365937 | T10: ='O-PTIR'!T10/MAX('O-PTIR'!T:T) -> 0.16376684 | U10: ='O-PTIR'!U10/MAX('O-PTIR'!U:U) -> 0.0735515 | V10: ='O-PTIR'!V10/MAX('O-PTIR'!V:V) -> 0.039021886 | W10: ='O-PTIR'!W10/MAX('O-PTIR'!W:W) -> 0.0094443169 | X10: ='O-PTIR'!X10/MAX('O-PTIR'!X:X) -> 0.046587973 | Y10: ='O-PTIR'!Y10/MAX('O-PTIR'!Y:Y) -> -0.062920238 | Z10: ='O-PTIR'!Z10/MAX('O-PTIR'!Z:Z) -> -0.34331265 | AA10: ='O-PTIR'!AA10/MAX('O-PTIR'!AA:AA) -> -0.016335336 | AB10: ='O-PTIR'!AB10/MAX('O-PTIR'!AB:AB) -> -0.028079489 | AC10: ='O-PTIR'!AC10/MAX('O-PTIR'!AC:AC) -> 0.0091539892 | AD10: ='O-PTIR'!AD10/MAX('O-PTIR'!AD:AD) -> -0.048980703 | AE10: ='O-PTIR'!AE10/MAX('O-PTIR'!AE:AE) -> -2.8258437 | AF10: ='O-PTIR'!AF10/MAX('O-PTIR'!AF:AF) -> 0.06318073 | AG10: ='O-PTIR'!AG10/MAX('O-PTIR'!AG:AG) -> 0.040175232 | AH10: ='O-PTIR'!AH10/MAX('O-PTIR'!AH:AH) -> 0.26681779 | AI10: ='O-PTIR'!AI10/MAX('O-PTIR'!AI:AI) -> 0.058243468 | AJ10: ='O-PTIR'!AJ10/MAX('O-PTIR'!AJ:AJ) -> -0.023224638 | AK10: ='O-PTIR'!AK10/MAX('O-PTIR'!AK:AK) -> 0.039777812 | AL10: ='O-PTIR'!AL10/MAX('O-PTIR'!AL:AL) -> -0.0070916504 | AM10: ='O-PTIR'!AM10/MAX('O-PTIR'!AM:AM) -> -0.097938981 | AN10: ='O-PTIR'!AN10/MAX('O-PTIR'!AN:AN) -> -0.075978638 | AO10: ='O-PTIR'!AO10/MAX('O-PTIR'!AO:AO) -> 0.24478878 | AP10: ='O-PTIR'!AP10/MAX('O-PTIR'!AP:AP) -> 0.1494919 | AQ10: ='O-PTIR'!AQ10/MAX('O-PTIR'!AQ:AQ) -> 0.032005983 | AR10: ='O-PTIR'!AR10/MAX('O-PTIR'!AR:AR) -> -0.11849417 | AS10: ='O-PTIR'!AS10/MAX('O-PTIR'!AS:AS) -> -0.010924831 | AT10: ='O-PTIR'!AT10/MAX('O-PTIR'!AT:AT) -> 0.0071549423 | AU10: ='O-PTIR'!AU10/MAX('O-PTIR'!AU:AU) -> -0.063861084 | AV10: ='O-PTIR'!AV10/MAX('O-PTIR'!AV:AV) -> -0.9740066 | AW10: ='O-PTIR'!AW10/MAX('O-PTIR'!AW:AW) -> -0.056347515 | AX10: ='O-PTIR'!AX10/MAX('O-PTIR'!AX:AX) -> -0.24923846 | AY10: ='O-PTIR'!AY10/MAX('O-PTIR'!AY:AY) -> 0.022198448 | AZ10: ='O-PTIR'!AZ10/MAX('O-PTIR'!AZ:AZ) -> -0.44428726 | BA10: ='O-PTIR'!BA10/MAX('O-PTIR'!BA:BA) -> 0.10240719 | BB10: ='O-PTIR'!BB10/MAX('O-PTIR'!BB:BB) -> 0.048504396
A11: 966 | B11: ='O-PTIR'!B11/MAX('O-PTIR'!B:B) -> -0.0055385904 | C11: ='O-PTIR'!C11/MAX('O-PTIR'!C:C) -> -0.0034395597 | D11: ='O-PTIR'!D11/MAX('O-PTIR'!D:D) -> 0.16719011 | E11: ='O-PTIR'!E11/MAX('O-PTIR'!E:E) -> 0.089415625 | F11: ='O-PTIR'!F11/MAX('O-PTIR'!F:F) -> -0.055639795 | G11: ='O-PTIR'!G11/MAX('O-PTIR'!G:G) -> 0.310994 | H11: ='O-PTIR'!H11/MAX('O-PTIR'!H:H) -> -4.3445354 | I11: ='O-PTIR'!I11/MAX('O-PTIR'!I:I) -> 0.10728222 | J11: ='O-PTIR'!J11/MAX('O-PTIR'!J:J) -> -0.020229171 | K11: ='O-PTIR'!K11/MAX('O-PTIR'!K:K) -> 0.10868589 | L11: ='O-PTIR'!L11/MAX('O-PTIR'!L:L) -> 0.21878453 | M11: ='O-PTIR'!M11/MAX('O-PTIR'!M:M) -> -0.0097538579 | N11: ='O-PTIR'!N11/MAX('O-PTIR'!N:N) -> -0.35314482 | O11: ='O-PTIR'!O11/MAX('O-PTIR'!O:O) -> 0.27651567 | P11: ='O-PTIR'!P11/MAX('O-PTIR'!P:P) -> 0.11328466 | Q11: ='O-PTIR'!Q11/MAX('O-PTIR'!Q:Q) -> 0.061054096 | R11: ='O-PTIR'!R11/MAX('O-PTIR'!R:R) -> 0.019343829 | S11: ='O-PTIR'!S11/MAX('O-PTIR'!S:S) -> 0.13270641 | T11: ='O-PTIR'!T11/MAX('O-PTIR'!T:T) -> 0.045500191 | U11: ='O-PTIR'!U11/MAX('O-PTIR'!U:U) -> 0.0728659 | V11: ='O-PTIR'!V11/MAX('O-PTIR'!V:V) -> -0.14479081 | W11: ='O-PTIR'!W11/MAX('O-PTIR'!W:W) -> 0.12806729 | X11: ='O-PTIR'!X11/MAX('O-PTIR'!X:X) -> 0.089814439 | Y11: ='O-PTIR'!Y11/MAX('O-PTIR'!Y:Y) -> 0.031741506 | Z11: ='O-PTIR'!Z11/MAX('O-PTIR'!Z:Z) -> -0.18056983 | AA11: ='O-PTIR'!AA11/MAX('O-PTIR'!AA:AA) -> -0.018960937 | AB11: ='O-PTIR'!AB11/MAX('O-PTIR'!AB:AB) -> -0.015943355 | AC11: ='O-PTIR'!AC11/MAX('O-PTIR'!AC:AC) -> -0.0080479139 | AD11: ='O-PTIR'!AD11/MAX('O-PTIR'!AD:AD) -> -0.012971765 | AE11: ='O-PTIR'!AE11/MAX('O-PTIR'!AE:AE) -> -3.3598519 | AF11: ='O-PTIR'!AF11/MAX('O-PTIR'!AF:AF) -> 0.044141852 | AG11: ='O-PTIR'!AG11/MAX('O-PTIR'!AG:AG) -> 0.066873948 | AH11: ='O-PTIR'!AH11/MAX('O-PTIR'!AH:AH) -> 0.094715143 | AI11: ='O-PTIR'!AI11/MAX('O-PTIR'!AI:AI) -> 0.017789906 | AJ11: ='O-PTIR'!AJ11/MAX('O-PTIR'!AJ:AJ) -> 0.0039137356 | AK11: ='O-PTIR'!AK11/MAX('O-PTIR'!AK:AK) -> 0.035962006 | AL11: ='O-PTIR'!AL11/MAX('O-PTIR'!AL:AL) -> -0.02128816 | AM11: ='O-PTIR'!AM11/MAX('O-PTIR'!AM:AM) -> -0.060635381 | AN11: ='O-PTIR'!AN11/MAX('O-PTIR'!AN:AN) -> 0.05155101 | AO11: ='O-PTIR'!AO11/MAX('O-PTIR'!AO:AO) -> -0.0091066738 | AP11: ='O-PTIR'!AP11/MAX('O-PTIR'!AP:AP) -> 0.17356453 | AQ11: ='O-PTIR'!AQ11/MAX('O-PTIR'!AQ:AQ) -> 0.014854152 | AR11: ='O-PTIR'!AR11/MAX('O-PTIR'!AR:AR) -> 0.02872875 | AS11: ='O-PTIR'!AS11/MAX('O-PTIR'!AS:AS) -> -0.16606157 | AT11: ='O-PTIR'!AT11/MAX('O-PTIR'!AT:AT) -> -0.0060681826 | AU11: ='O-PTIR'!AU11/MAX('O-PTIR'!AU:AU) -> -0.10999916 | AV11: ='O-PTIR'!AV11/MAX('O-PTIR'!AV:AV) -> -0.46103336 | AW11: ='O-PTIR'!AW11/MAX('O-PTIR'!AW:AW) -> 0.034411966 | AX11: ='O-PTIR'!AX11/MAX('O-PTIR'!AX:AX) -> -0.27299535 | AY11: ='O-PTIR'!AY11/MAX('O-PTIR'!AY:AY) -> 0.11018873 | AZ11: ='O-PTIR'!AZ11/MAX('O-PTIR'!AZ:AZ) -> -0.16132026 | BA11: ='O-PTIR'!BA11/MAX('O-PTIR'!BA:BA) -> -0.051654908 | BB11: ='O-PTIR'!BB11/MAX('O-PTIR'!BB:BB) -> 0.07372594
A12: 968 | B12: ='O-PTIR'!B12/MAX('O-PTIR'!B:B) -> 0.0061877615 | C12: ='O-PTIR'!C12/MAX('O-PTIR'!C:C) -> 0.02425717 | D12: ='O-PTIR'!D12/MAX('O-PTIR'!D:D) -> 0.088895118 | E12: ='O-PTIR'!E12/MAX('O-PTIR'!E:E) -> 0.10429737 | F12: ='O-PTIR'!F12/MAX('O-PTIR'!F:F) -> -0.040760908 | G12: ='O-PTIR'!G12/MAX('O-PTIR'!G:G) -> 0.11182133 | H12: ='O-PTIR'!H12/MAX('O-PTIR'!H:H) -> -4.5262878 | I12: ='O-PTIR'!I12/MAX('O-PTIR'!I:I) -> 0.052995706 | J12: ='O-PTIR'!J12/MAX('O-PTIR'!J:J) -> -0.004511534 | K12: ='O-PTIR'!K12/MAX('O-PTIR'!K:K) -> -0.022429193 | L12: ='O-PTIR'!L12/MAX('O-PTIR'!L:L) -> -0.16723441 | M12: ='O-PTIR'!M12/MAX('O-PTIR'!M:M) -> -0.0033502788 | N12: ='O-PTIR'!N12/MAX('O-PTIR'!N:N) -> -0.11120405 | O12: ='O-PTIR'!O12/MAX('O-PTIR'!O:O) -> -0.18245026 | P12: ='O-PTIR'!P12/MAX('O-PTIR'!P:P) -> 0.098791965 | Q12: ='O-PTIR'!Q12/MAX('O-PTIR'!Q:Q) -> 0.023453445 | R12: ='O-PTIR'!R12/MAX('O-PTIR'!R:R) -> 0.058980149 | S12: ='O-PTIR'!S12/MAX('O-PTIR'!S:S) -> 0.062636067 | T12: ='O-PTIR'!T12/MAX('O-PTIR'!T:T) -> 0.12948012 | U12: ='O-PTIR'!U12/MAX('O-PTIR'!U:U) -> -0.015920006 | V12: ='O-PTIR'!V12/MAX('O-PTIR'!V:V) -> -0.074549371 | W12: ='O-PTIR'!W12/MAX('O-PTIR'!W:W) -> -0.020437122 | X12: ='O-PTIR'!X12/MAX('O-PTIR'!X:X) -> 0.098920514 | Y12: ='O-PTIR'!Y12/MAX('O-PTIR'!Y:Y) -> 0.0091008486 | Z12: ='O-PTIR'!Z12/MAX('O-PTIR'!Z:Z) -> -0.10249451 | AA12: ='O-PTIR'!AA12/MAX('O-PTIR'!AA:AA) -> 0.042909454 | AB12: ='O-PTIR'!AB12/MAX('O-PTIR'!AB:AB) -> -0.0026136364 | AC12: ='O-PTIR'!AC12/MAX('O-PTIR'!AC:AC) -> 0.017359568 | AD12: ='O-PTIR'!AD12/MAX('O-PTIR'!AD:AD) -> -0.045083011 | AE12: ='O-PTIR'!AE12/MAX('O-PTIR'!AE:AE) -> -1.3317255 | AF12: ='O-PTIR'!AF12/MAX('O-PTIR'!AF:AF) -> 0.070803964 | AG12: ='O-PTIR'!AG12/MAX('O-PTIR'!AG:AG) -> 0.071826398 | AH12: ='O-PTIR'!AH12/MAX('O-PTIR'!AH:AH) -> 0.15185587 | AI12: ='O-PTIR'!AI12/MAX('O-PTIR'!AI:AI) -> 0.17656597 | AJ12: ='O-PTIR'!AJ12/MAX('O-PTIR'!AJ:AJ) -> -0.024312852 | AK12: ='O-PTIR'!AK12/MAX('O-PTIR'!AK:AK) -> -0.0092630419 | AL12: ='O-PTIR'!AL12/MAX('O-PTIR'!AL:AL) -> -0.10399393 | AM12: ='O-PTIR'!AM12/MAX('O-PTIR'!AM:AM) -> -0.091361875 | AN12: ='O-PTIR'!AN12/MAX('O-PTIR'!AN:AN) -> 0.096814243 | AO12: ='O-PTIR'!AO12/MAX('O-PTIR'!AO:AO) -> 0.079392933 | AP12: ='O-PTIR'!AP12/MAX('O-PTIR'!AP:AP) -> 0.13465576 | AQ12: ='O-PTIR'!AQ12/MAX('O-PTIR'!AQ:AQ) -> 0.001250939 | AR12: ='O-PTIR'!AR12/MAX('O-PTIR'!AR:AR) -> -0.022216715 | AS12: ='O-PTIR'!AS12/MAX('O-PTIR'!AS:AS) -> 0.049033761 | AT12: ='O-PTIR'!AT12/MAX('O-PTIR'!AT:AT) -> -0.074220405 | AU12: ='O-PTIR'!AU12/MAX('O-PTIR'!AU:AU) -> -0.042780505 | AV12: ='O-PTIR'!AV12/MAX('O-PTIR'!AV:AV) -> -0.22233739 | AW12: ='O-PTIR'!AW12/MAX('O-PTIR'!AW:AW) -> 0.057907512 | AX12: ='O-PTIR'!AX12/MAX('O-PTIR'!AX:AX) -> 0.018239378 | AY12: ='O-PTIR'!AY12/MAX('O-PTIR'!AY:AY) -> 0.1577228 | AZ12: ='O-PTIR'!AZ12/MAX('O-PTIR'!AZ:AZ) -> -0.10584227 | BA12: ='O-PTIR'!BA12/MAX('O-PTIR'!BA:BA) -> -0.17087092 | BB12: ='O-PTIR'!BB12/MAX('O-PTIR'!BB:BB) -> -0.0094423249
A13: 970 | B13: ='O-PTIR'!B13/MAX('O-PTIR'!B:B) -> 0.00018703853 | C13: ='O-PTIR'!C13/MAX('O-PTIR'!C:C) -> 0.11540814 | D13: ='O-PTIR'!D13/MAX('O-PTIR'!D:D) -> 0.19007905 | E13: ='O-PTIR'!E13/MAX('O-PTIR'!E:E) -> -0.050630878 | F13: ='O-PTIR'!F13/MAX('O-PTIR'!F:F) -> -0.11987334 | G13: ='O-PTIR'!G13/MAX('O-PTIR'!G:G) -> -0.064231338 | H13: ='O-PTIR'!H13/MAX('O-PTIR'!H:H) -> -6.3197611 | I13: ='O-PTIR'!I13/MAX('O-PTIR'!I:I) -> -0.045154505 | J13: ='O-PTIR'!J13/MAX('O-PTIR'!J:J) -> 0.0050172055 | K13: ='O-PTIR'!K13/MAX('O-PTIR'!K:K) -> 0.14375757 | L13: ='O-PTIR'!L13/MAX('O-PTIR'!L:L) -> -0.092086159 | M13: ='O-PTIR'!M13/MAX('O-PTIR'!M:M) -> -0.064666064 | N13: ='O-PTIR'!N13/MAX('O-PTIR'!N:N) -> -0.064373731 | O13: ='O-PTIR'!O13/MAX('O-PTIR'!O:O) -> -0.25397779 | P13: ='O-PTIR'!P13/MAX('O-PTIR'!P:P) -> 0.15716987 | Q13: ='O-PTIR'!Q13/MAX('O-PTIR'!Q:Q) -> 0.042451646 | R13: ='O-PTIR'!R13/MAX('O-PTIR'!R:R) -> -0.035513054 | S13: ='O-PTIR'!S13/MAX('O-PTIR'!S:S) -> 0.066942911 | T13: ='O-PTIR'!T13/MAX('O-PTIR'!T:T) -> 0.062368706 | U13: ='O-PTIR'!U13/MAX('O-PTIR'!U:U) -> 0.035373864 | V13: ='O-PTIR'!V13/MAX('O-PTIR'!V:V) -> 0.05210373 | W13: ='O-PTIR'!W13/MAX('O-PTIR'!W:W) -> 0.031520448 | X13: ='O-PTIR'!X13/MAX('O-PTIR'!X:X) -> 0.011964319 | Y13: ='O-PTIR'!Y13/MAX('O-PTIR'!Y:Y) -> 0.044010619 | Z13: ='O-PTIR'!Z13/MAX('O-PTIR'!Z:Z) -> -0.026718589 | AA13: ='O-PTIR'!AA13/MAX('O-PTIR'!AA:AA) -> -0.020179113 | AB13: ='O-PTIR'!AB13/MAX('O-PTIR'!AB:AB) -> 0.0094011399 | AC13: ='O-PTIR'!AC13/MAX('O-PTIR'!AC:AC) -> 0.023303828 | AD13: ='O-PTIR'!AD13/MAX('O-PTIR'!AD:AD) -> 0.027630261 | AE13: ='O-PTIR'!AE13/MAX('O-PTIR'!AE:AE) -> -1.7154427 | AF13: ='O-PTIR'!AF13/MAX('O-PTIR'!AF:AF) -> 0.089890328 | AG13: ='O-PTIR'!AG13/MAX('O-PTIR'!AG:AG) -> -0.098230584 | AH13: ='O-PTIR'!AH13/MAX('O-PTIR'!AH:AH) -> 0.053365824 | AI13: ='O-PTIR'!AI13/MAX('O-PTIR'!AI:AI) -> 0.0071504238 | AJ13: ='O-PTIR'!AJ13/MAX('O-PTIR'!AJ:AJ) -> 0.01026674 | AK13: ='O-PTIR'!AK13/MAX('O-PTIR'!AK:AK) -> 0.035923584 | AL13: ='O-PTIR'!AL13/MAX('O-PTIR'!AL:AL) -> 0.032141356 | AM13: ='O-PTIR'!AM13/MAX('O-PTIR'!AM:AM) -> -0.10665157 | AN13: ='O-PTIR'!AN13/MAX('O-PTIR'!AN:AN) -> 0.21507002 | AO13: ='O-PTIR'!AO13/MAX('O-PTIR'!AO:AO) -> 0.19967203 | AP13: ='O-PTIR'!AP13/MAX('O-PTIR'!AP:AP) -> 0.057520168 | AQ13: ='O-PTIR'!AQ13/MAX('O-PTIR'!AQ:AQ) -> 0.014881361 | AR13: ='O-PTIR'!AR13/MAX('O-PTIR'!AR:AR) -> 0.008332217 | AS13: ='O-PTIR'!AS13/MAX('O-PTIR'!AS:AS) -> 0.028963025 | AT13: ='O-PTIR'!AT13/MAX('O-PTIR'!AT:AT) -> -0.028674241 | AU13: ='O-PTIR'!AU13/MAX('O-PTIR'!AU:AU) -> 0.0004917501 | AV13: ='O-PTIR'!AV13/MAX('O-PTIR'!AV:AV) -> 0.0047056596 | AW13: ='O-PTIR'!AW13/MAX('O-PTIR'!AW:AW) -> -0.027137063 | AX13: ='O-PTIR'!AX13/MAX('O-PTIR'!AX:AX) -> -0.20389943 | AY13: ='O-PTIR'!AY13/MAX('O-PTIR'!AY:AY) -> 0.045615533 | AZ13: ='O-PTIR'!AZ13/MAX('O-PTIR'!AZ:AZ) -> -0.25205027 | BA13: ='O-PTIR'!BA13/MAX('O-PTIR'!BA:BA) -> -0.23695903 | BB13: ='O-PTIR'!BB13/MAX('O-PTIR'!BB:BB) -> -0.011263061
... A1030: 3004 | B1030: ='O-PTIR'!B1030/MAX('O-PTIR'!B:B) -> 0.086379632 | C1030: ='O-PTIR'!C1030/MAX('O-PTIR'!C:C) -> 0.89507017 | D1030: ='O-PTIR'!D1030/MAX('O-PTIR'!D:D) -> 0.51736002 | E1030: ='O-PTIR'!E1030/MAX('O-PTIR'!E:E) -> 1 | F1030: ='O-PTIR'!F1030/MAX('O-PTIR'!F:F) -> -4.1548677 | G1030: ='O-PTIR'!G1030/MAX('O-PTIR'!G:G) -> -0.848996 | H1030: ='O-PTIR'!H1030/MAX('O-PTIR'!H:H) -> -15.306507 | I1030: ='O-PTIR'!I1030/MAX('O-PTIR'!I:I) -> 0.54567471 | J1030: ='O-PTIR'!J1030/MAX('O-PTIR'!J:J) -> 1 | K1030: ='O-PTIR'!K1030/MAX('O-PTIR'!K:K) -> 1 | L1030: ='O-PTIR'!L1030/MAX('O-PTIR'!L:L) -> 0.59799176 | M1030: ='O-PTIR'!M1030/MAX('O-PTIR'!M:M) -> 1 | N1030: ='O-PTIR'!N1030/MAX('O-PTIR'!N:N) -> -1.520114 | O1030: ='O-PTIR'!O1030/MAX('O-PTIR'!O:O) -> -3.0875039 | P1030: ='O-PTIR'!P1030/MAX('O-PTIR'!P:P) -> 0.41678236 | Q1030: ='O-PTIR'!Q1030/MAX('O-PTIR'!Q:Q) -> 0.24722149 | R1030: ='O-PTIR'!R1030/MAX('O-PTIR'!R:R) -> -0.79791431 | S1030: ='O-PTIR'!S1030/MAX('O-PTIR'!S:S) -> 0.19999722 | T1030: ='O-PTIR'!T1030/MAX('O-PTIR'!T:T) -> 0.27103849 | U1030: ='O-PTIR'!U1030/MAX('O-PTIR'!U:U) -> 0.87181234 | V1030: ='O-PTIR'!V1030/MAX('O-PTIR'!V:V) -> 0.98649733 | W1030: ='O-PTIR'!W1030/MAX('O-PTIR'!W:W) -> 0.79365835 | X1030: ='O-PTIR'!X1030/MAX('O-PTIR'!X:X) -> 1 | Y1030: ='O-PTIR'!Y1030/MAX('O-PTIR'!Y:Y) -> 1 | Z1030: ='O-PTIR'!Z1030/MAX('O-PTIR'!Z:Z) -> 0.0073904908 | AA1030: ='O-PTIR'!AA1030/MAX('O-PTIR'!AA:AA) -> 1 | AB1030: ='O-PTIR'!AB1030/MAX('O-PTIR'!AB:AB) -> -0.0058914623 | AC1030: ='O-PTIR'!AC1030/MAX('O-PTIR'!AC:AC) -> -0.080837625 | AD1030: ='O-PTIR'!AD1030/MAX('O-PTIR'!AD:AD) -> -1.0611086 | AE1030: ='O-PTIR'!AE1030/MAX('O-PTIR'!AE:AE) -> -12.692236 | AF1030: ='O-PTIR'!AF1030/MAX('O-PTIR'!AF:AF) -> 0.0051986009 | AG1030: ='O-PTIR'!AG1030/MAX('O-PTIR'!AG:AG) -> 0.99179084 | AH1030: ='O-PTIR'!AH1030/MAX('O-PTIR'!AH:AH) -> -0.73475152 | AI1030: ='O-PTIR'!AI1030/MAX('O-PTIR'!AI:AI) -> -2.0259445 | AJ1030: ='O-PTIR'!AJ1030/MAX('O-PTIR'!AJ:AJ) -> -0.40864077 | AK1030: ='O-PTIR'!AK1030/MAX('O-PTIR'!AK:AK) -> 0.66996096 | AL1030: ='O-PTIR'!AL1030/MAX('O-PTIR'!AL:AL) -> -1.7276503 | AM1030: ='O-PTIR'!AM1030/MAX('O-PTIR'!AM:AM) -> -2.7912566 | AN1030: ='O-PTIR'!AN1030/MAX('O-PTIR'!AN:AN) -> -3.192387 | AO1030: ='O-PTIR'!AO1030/MAX('O-PTIR'!AO:AO) -> 0.89791624 | AP1030: ='O-PTIR'!AP1030/MAX('O-PTIR'!AP:AP) -> 0.21115873 | AQ1030: ='O-PTIR'!AQ1030/MAX('O-PTIR'!AQ:AQ) -> -0.21109229 | AR1030: ='O-PTIR'!AR1030/MAX('O-PTIR'!AR:AR) -> 0.71916297 | AS1030: ='O-PTIR'!AS1030/MAX('O-PTIR'!AS:AS) -> 0.34718476 | AT1030: ='O-PTIR'!AT1030/MAX('O-PTIR'!AT:AT) -> 1 | AU1030: ='O-PTIR'!AU1030/MAX('O-PTIR'!AU:AU) -> 1 | AV1030: ='O-PTIR'!AV1030/MAX('O-PTIR'!AV:AV) -> -4.5842101 | AW1030: ='O-PTIR'!AW1030/MAX('O-PTIR'!AW:AW) -> 0.48429701 | AX1030: ='O-PTIR'!AX1030/MAX('O-PTIR'!AX:AX) -> -2.4503881 | AY1030: ='O-PTIR'!AY1030/MAX('O-PTIR'!AY:AY) -> 0.80952874 | AZ1030: ='O-PTIR'!AZ1030/MAX('O-PTIR'!AZ:AZ) -> -2.0552963 | BA1030: ='O-PTIR'!BA1030/MAX('O-PTIR'!BA:BA) -> -0.85865609 | BB1030: ='O-PTIR'!BB1030/MAX('O-PTIR'!BB:BB) -> 0.48877191

Sheet Raman
A1: X value [cmâ»Â¹] | B1: Raman Spectrum 1/Raman Intensity [] | C1: Raman Spectrum 2/Raman Intensity [] | D1: Raman Spectrum 3/Raman Intensity [] | E1: Raman Spectrum 4/Raman Intensity [] | F1: Raman Spectrum 5/Raman Intensity [] | G1: Raman Spectrum 6/Raman Intensity [] | H1: Raman Spectrum 7/Raman Intensity [] | I1: Raman Spectrum 8/Raman Intensity [] | J1: Raman Spectrum 9/Raman Intensity [] | K1: Raman Spectrum 10/Raman Intensity [] | L1: Raman Spectrum 11/Raman Intensity [] | M1: Raman Spectrum 12/Raman Intensity [] | N1: Raman Spectrum 13/Raman Intensity [] | O1: Raman Spectrum 14/Raman Intensity [] | P1: Raman Spectrum 15/Raman Intensity [] | Q1: Raman Spectrum 16/Raman Intensity [] | R1: Raman Spectrum 17/Raman Intensity [] | S1: Raman Spectrum 18/Raman Intensity [] | T1: Raman Spectrum 19/Raman Intensity [] | U1: Raman Spectrum 20/Raman Intensity [] | V1: Raman Spectrum 21/Raman Intensity [] | W1: Raman Spectrum 22/Raman Intensity [] | X1: Raman Spectrum 23/Raman Intensity [] | Y1: Raman Spectrum 24/Raman Intensity [] | Z1: Raman Spectrum 25/Raman Intensity [] | AA1: Raman Spectrum 26/Raman Intensity [] | AB1: Raman Spectrum 27/Raman Intensity [] | AC1: Raman Spectrum 28/Raman Intensity [] | AD1: Raman Spectrum 29/Raman Intensity [] | AE1: Raman Spectrum 30/Raman Intensity [] | AF1: Raman Spectrum 31/Raman Intensity [] | AG1: Raman Spectrum 32/Raman Intensity [] | AH1: Raman Spectrum 33/Raman Intensity [] | AI1: Raman Spectrum 34/Raman Intensity [] | AJ1: Raman Spectrum 35/Raman Intensity [] | AK1: Raman Spectrum 36/Raman Intensity [] | AL1: Raman Spectrum 37/Raman Intensity [] | AM1: Raman Spectrum 38/Raman Intensity [] | AN1: Raman Spectrum 39/Raman Intensity [] | AO1: Raman Spectrum 40/Raman Intensity [] | AP1: Raman Spectrum 41/Raman Intensity [] | AQ1: Raman Spectrum 42/Raman Intensity [] | AR1: Raman Spectrum 43/Raman Intensity [] | AS1: Raman Spectrum 44/Raman Intensity [] | AT1: Raman Spectrum 45/Raman Intensity [] | AU1: Raman Spectrum 46/Raman Intensity [] | AV1: Raman Spectrum 47/Raman Intensity [] | AW1: Raman Spectrum 48/Raman Intensity [] | AX1: Raman Spectrum 49/Raman Intensity [] | AY1: Raman Spectrum 50/Raman Intensity [] | AZ1: Raman Spectrum 51/Raman Intensity [] | BA1: Raman Spectrum 52/Raman Intensity [] | BB1: Raman Spectrum 53/Raman Intensity []
A2: 326.12215 | B2: 7814 | C2: 7438 | D2: 7349.5 | E2: 6878 | F2: 7106.5 | G2: 7132.6665 | H2: 7032 | I2: 7026 | J2: 6901 | K2: 6834 | L2: 6732 | M2: 6825 | N2: 6834 | O2: 6728.6665 | P2: 7518.6665 | Q2: 7044 | R2: 6888 | S2: 6976.6665 | T2: 7244 | U2: 6849.3335 | V2: 8807 | W2: 8488.4004 | X2: 6692 | Y2: 7919 | Z2: 7873 | AA2: 8572 | AB2: 8180 | AC2: 8404.5 | AD2: 7741 | AE2: 6839.5 | AF2: 7692 | AG2: 7244 | AH2: 8161.3335 | AI2: 8222 | AJ2: 8140.6665 | AK2: 8244 | AL2: 8170 | AM2: 8181 | AN2: 6943.5 | AO2: 7500.6665 | AP2: 7146 | AQ2: 6896 | AR2: 7416 | AS2: 7523 | AT2: 8635 | AU2: 8444 | AV2: 7100.7998 | AW2: 7003 | AX2: 6588 | AY2: 7166.5 | AZ2: 7270.7998 | BA2: 8252 | BB2: 9258
A3: 329.59377 | B3: 7819.9189 | C3: 7383.8091 | D3: 7308.3306 | E3: 7021.2378 | F3: 7127.8872 | G3: 7067.4268 | H3: 7066.4609 | I3: 6934.98 | J3: 6916.9419 | K3: 6886.4019 | L3: 6648.3462 | M3: 6796.1948 | N3: 6743.6377 | O3: 6779.9116 | P3: 7571.2793 | Q3: 6931.9351 | R3: 6981.3877 | S3: 6960.3569 | T3: 7224.0073 | U3: 6808.8218 | V3: 8887.1025 | W3: 8455.7275 | X3: 6502.5947 | Y3: 7925.1558 | Z3: 7924.2974 | AA3: 8564.7393 | AB3: 8213.1455 | AC3: 8325.9756 | AD3: 7643.9297 | AE3: 6883.458 | AF3: 7779.9946 | AG3: 7258.6001 | AH3: 8141.3408 | AI3: 8191.4849 | AJ3: 8136.9839 | AK3: 8259.1523 | AL3: 8135.2759 | AM3: 8187.0503 | AN3: 6913.1162 | AO3: 7565.4854 | AP3: 7101.4106 | AQ3: 6906.4175 | AR3: 7460.5894 | AS3: 7460.6543 | AT3: 8440.0703 | AU3: 8475.5674 | AV3: 6992.8389 | AW3: 6978.272 | AX3: 6753.7295 | AY3: 7188.2026 | AZ3: 7210.8213 | BA3: 8229.9023 | BB3: 9232.7461
A4: 333.06539 | B4: 7889.978 | C4: 7398.2788 | D4: 7339.1001 | E4: 7058.626 | F4: 7162.1953 | G4: 7134.3101 | H4: 7052.5493 | I4: 7010.751 | J4: 6952.5542 | K4: 6945.3916 | L4: 6729.1538 | M4: 6810.3545 | N4: 6690.6519 | O4: 6771.687 | P4: 7677.4146 | Q4: 7012.0308 | R4: 7035.978 | S4: 7034.4824 | T4: 7283.2593 | U4: 6857.7358 | V4: 9004.7188 | W4: 8412.6152 | X4: 6537.0874 | Y4: 7964.7979 | Z4: 7885.5488 | AA4: 8642.9922 | AB4: 8308.7188 | AC4: 8393.875 | AD4: 7735.7236 | AE4: 6920.5317 | AF4: 7862.0703 | AG4: 7259.8774 | AH4: 8209.4316 | AI4: 8210.8213 | AJ4: 8208.2656 | AK4: 8191.4004 | AL4: 8187.3872 | AM4: 8220.6807 | AN4: 6933.2651 | AO4: 7619.166 | AP4: 7178.3755 | AQ4: 6947.4312 | AR4: 7461.1357 | AS4: 7599.022 | AT4: 8555.2607 | AU4: 8517.8018 | AV4: 7096.876 | AW4: 6975.6489 | AX4: 6803.4395 | AY4: 7182.3442 | AZ4: 7159.9492 | BA4: 8267.126 | BB4: 9264.6973
A5: 336.537 | B5: 7950.6401 | C5: 7438.1504 | D5: 7396.4111 | E5: 7066.5112 | F5: 7181.9155 | G5: 7218.2603 | H5: 7049.8931 | I5: 7061.9731 | J5: 6976.7275 | K5: 6938.1982 | L5: 6788.356 | M5: 6830.8813 | N5: 6716.8115 | O5: 6775.5259 | P5: 7754.8486 | Q5: 7104.3174 | R5: 7018.2612 | S5: 7093.7959 | T5: 7354.1699 | U5: 6909.8247 | V5: 8971.6152 | W5: 8444.8242 | X5: 6590.4902 | Y5: 7999.0093 | Z5: 7858.5137 | AA5: 8753.3193 | AB5: 8400.5391 | AC5: 8447.1738 | AD5: 7870.166 | AE5: 6940.4189 | AF5: 7897.2412 | AG5: 7273.7705 | AH5: 8261.624 | AI5: 8225.9941 | AJ5: 8267.0098 | AK5: 8200.6426 | AL5: 8231.208 | AM5: 8244.751 | AN5: 6983.5771 | AO5: 7674.4136 | AP5: 7219.4702 | AQ5: 6969.2427 | AR5: 7509.5117 | AS5: 7735.834 | AT5: 8737.958 | AU5: 8529.9844 | AV5: 7124.4111 | AW5: 6985.0713 | AX5: 6828.2358 | AY5: 7168.7432 | AZ5: 7141.3833 | BA5: 8382.7363 | BB5: 9237.4277
A6: 340.00862 | B6: 7969.1729 | C6: 7480.8081 | D6: 7453.7124 | E6: 7089.3794 | F6: 7177.5786 | G6: 7257.1689 | H6: 7085.0767 | I6: 7038.4224 | J6: 6987.8276 | K6: 6892.2427 | L6: 6787.1606 | M6: 6851.4072 | N6: 6784.4648 | O6: 6819.8452 | P6: 7775.1582 | Q6: 7132.9541 | R6: 6964.832 | S6: 7115.9736 | T6: 7409.6699 | U6: 6943.1118 | V6: 8837.8438 | W6: 8551.4648 | X6: 6604.0723 | Y6: 8013.3687 | Z6: 7911.0718 | AA6: 8845.7441 | AB6: 8461.084 | AC6: 8472.3506 | AD6: 7966.6528 | AE6: 6961.9722 | AF6: 7902.874 | AG6: 7312.8208 | AH6: 8260.9453 | AI6: 8219.9062 | AJ6: 8285.5049 | AK6: 8319.6699 | AL6: 8241.6865 | AM6: 8256.3174 | AN6: 7032.8389 | AO6: 7709.269 | AP6: 7191.4297 | AQ6: 6960.2646 | AR6: 7602.2593 | AS6: 7792.0342 | AT6: 8854.4678 | AU6: 8511.6543 | AV6: 7051.2407 | AW6: 7003.1689 | AX6: 6868.6577 | AY6: 7183.3813 | AZ6: 7173.1753 | BA6: 8494.1094 | BB6: 9178.0938
