Workbook

Sheet O-PTIR
A1: X value [cmâ»Â¹] | B1: IR Spectrum 11/OPTIR (mV) [] | C1: IR Spectrum 12/OPTIR (mV) [] | D1: IR Spectrum 13/OPTIR (mV) [] | E1: IR Spectrum 14/OPTIR (mV) [] | F1: IR Spectrum 16/OPTIR (mV) [] | G1: IR Spectrum 17/OPTIR (mV) [] | H1: IR Spectrum 18/OPTIR (mV) [] | I1: IR Spectrum 19/OPTIR (mV) [] | J1: IR Spectrum 20/OPTIR (mV) [] | K1: IR Spectrum 27/OPTIR (mV) [] | L1: IR Spectrum 1/OPTIR (mV) [] | M1: IR Spectrum 2/OPTIR (mV) [] | N1: IR Spectrum 3/OPTIR (mV) [] | O1: IR Spectrum 9/OPTIR (mV) [] | P1: IR Spectrum 10/OPTIR (mV) [] | Q1: IR Spectrum 13/OPTIR (mV) [] | R1: IR Spectrum 14/OPTIR (mV) [] | S1: IR Spectrum 15/OPTIR (mV) [] | T1: IR Spectrum 17/OPTIR (mV) [] | U1: IR Spectrum 18/OPTIR (mV) [] | V1: IR Spectrum 21/OPTIR (mV) [] | W1: IR Spectrum 23/OPTIR (mV) [] | X1: IR Spectrum 26/OPTIR (mV) [] | Y1: IR Spectrum 27/OPTIR (mV) [] | Z1: IR Spectrum 28/OPTIR (mV) [] | AA1: IR Spectrum 3/OPTIR (mV) [] | AB1: IR Spectrum 4/OPTIR (mV) [] | AC1: IR Spectrum 5/OPTIR (mV) [] | AD1: IR Spectrum 6/OPTIR (mV) [] | AE1: IR Spectrum 9/OPTIR (mV) [] | AF1: IR Spectrum 10/OPTIR (mV) [] | AG1: IR Spectrum 11/OPTIR (mV) []
A2: 948 | B2: -1.4816493 | C2: -2.0226026 | D2: -1.1032218 | E2: 5.202014 | F2: 2.4701705 | G2: 1.0259819 | H2: -0.67809093 | I2: -1.243077 | J2: -2.2975576 | K2: -0.1420693 | L2: 4.7539072 | M2: -2.2522564 | N2: 1.6935322 | O2: 5.1689568 | P2: -2.5506344 | Q2: -2.2238097 | R2: -2.0407555 | S2: 3.0824831 | T2: -2.0396588 | U2: 1.5578564 | V2: -1.0325003 | W2: 3.6676352 | X2: -1.1061794 | Y2: 0.045389634 | Z2: 3.253185 | AA2: -0.14676017 | AB2: -1.8376087 | AC2: -1.9546518 | AD2: 1.6959002 | AE2: -1.4317696 | AF2: 0.21368557 | AG2: -0.96430081
A3: 950 | B3: 1.488722 | C3: -0.24258339 | D3: -1.9707612 | E3: 3.9273512 | F3: -0.20414048 | G3: 1.0145372 | H3: -0.16759241 | I3: -0.75636315 | J3: -3.0231543 | K3: -0.4681243 | L3: 2.5711484 | M3: -2.7783284 | N3: -1.2580132 | O3: -0.05793222 | P3: -0.49012941 | Q3: -1.1259453 | R3: -2.424545 | S3: 1.0533981 | T3: -2.8416643 | U3: -1.3420475 | V3: 3.520319 | W3: 0.44246015 | X3: 0.82651567 | Y3: -0.33855429 | Z3: 2.8469059 | AA3: 1.7062997 | AB3: -1.2757307 | AC3: 0.61443907 | AD3: 2.1625817 | AE3: 0.47325146 | AF3: -0.80485809 | AG3: -1.3485974
A4: 952 | B4: -0.14879403 | C4: -0.59482491 | D4: 0.47658685 | E4: 2.2888308 | F4: -0.77689451 | G4: 0.76185316 | H4: 0.30686164 | I4: -0.14149415 | J4: -3.401089 | K4: -0.90928578 | L4: -0.55333686 | M4: -3.5754435 | N4: 1.0926653 | O4: -0.062036835 | P4: -0.89410502 | Q4: -0.45664647 | R4: -0.015390155 | S4: 3.6300371 | T4: 0.20463963 | U4: -1.5196736 | V4: 2.6748786 | W4: 1.5696387 | X4: -1.0464998 | Y4: 0.14316788 | Z4: -0.39281368 | AA4: -0.57716715 | AB4: 1.6828138 | AC4: 0.98399168 | AD4: 2.6110423 | AE4: 1.3517032 | AF4: 2.2758291 | AG4: -2.9805369
A5: 954 | B5: 0.06527783 | C5: 0.020493999 | D5: -1.2786971 | E5: 1.6733885 | F5: -2.1560326 | G5: 0.024382824 | H5: 0.58394659 | I5: 1.1185308 | J5: -1.4508742 | K5: -0.16043116 | L5: -0.75063598 | M5: -1.9022068 | N5: 2.4711993 | O5: -0.24450004 | P5: 0.75320435 | Q5: -2.2037911 | R5: -0.86966062 | S5: 2.1600275 | T5: 0.21613908 | U5: -1.2075689 | V5: 1.2506766 | W5: 1.4434624 | X5: 2.4447968 | Y5: 0.63928956 | Z5: -1.1634668 | AA5: -1.1449209 | AB5: 1.5653528 | AC5: 1.0136536 | AD5: 1.262566 | AE5: 0.47303006 | AF5: -0.48805436 | AG5: -2.0080016
A6: 956 | B6: 0.78137994 | C6: -1.2328899 | D6: -0.18549345 | E6: 1.6069649 | F6: -0.44315448 | G6: -0.60623062 | H6: 1.5099275 | I6: 0.98830801 | J6: 0.64748621 | K6: 0.059786826 | L6: 0.004849589 | M6: 0.031368155 | N6: 0.91960871 | O6: 0.45644462 | P6: 0.85751653 | Q6: -1.3606473 | R6: -0.82839644 | S6: 2.2678685 | T6: -0.11148958 | U6: -0.31918094 | V6: 0.46659303 | W6: 1.0975183 | X6: 1.0948534 | Y6: -0.73075461 | Z6: 0.40847683 | AA6: -1.1121099 | AB6: 0.81666082 | AC6: -1.4915532 | AD6: 1.5683558 | AE6: -0.56146228 | AF6: -1.7980335 | AG6: -0.53292787
A7: 958 | B7: -1.0612369 | C7: -1.9355907 | D7: 0.58567435 | E7: 1.8039505 | F7: 0.15975554 | G7: 0.20883971 | H7: 1.0567029 | I7: -0.90562165 | J7: -1.2459233 | K7: 0.16687422 | L7: 0.72973537 | M7: 0.32996571 | N7: 0.76040846 | O7: 0.94546902 | P7: 0.40020558 | Q7: -0.4405944 | R7: -0.69679224 | S7: 1.191327 | T7: -1.3626989 | U7: 0.62455016 | V7: 1.0636672 | W7: 1.658754 | X7: -0.11741274 | Y7: -0.35843375 | Z7: 0.088649094 | AA7: 0.67923033 | AB7: -0.53319418 | AC7: -0.18638849 | AD7: 1.8007632 | AE7: 1.4800442 | AF7: -1.5684108 | AG7: -0.43355048
A8: 960 | B8: -0.44717148 | C8: -0.92169654 | D8: 0.30227128 | E8: 1.009897 | F8: -0.12465387 | G8: 0.5112465 | H8: 0.58902746 | I8: -0.67968291 | J8: -0.88061619 | K8: 0.34866163 | L8: 0.16510244 | M8: -1.1865892 | N8: 0.30120108 | O8: -0.43596652 | P8: -0.30769345 | Q8: -0.93353015 | R8: 0.36378777 | S8: 1.6520909 | T8: -0.68514341 | U8: -0.61422306 | V8: 0.5044319 | W8: 0.65941542 | X8: 0.25596076 | Y8: -0.24257219 | Z8: -0.21717486 | AA8: -0.43861946 | AB8: -0.53762943 | AC8: -0.4359318 | AD8: 1.1643745 | AE8: 1.0667154 | AF8: -1.3474815 | AG8: -0.17244506
A9: 962 | B9: -0.28835589 | C9: -0.4127537 | D9: -1.0435393 | E9: 1.5616735 | F9: -0.30989322 | G9: 1.4467027 | H9: 0.85975462 | I9: -0.89922619 | J9: -1.1515745 | K9: 0.98337775 | L9: -0.016204022 | M9: -0.29906172 | N9: 0.013619155 | O9: -0.090269797 | P9: -1.2059774 | Q9: -1.0066457 | R9: 0.71412569 | S9: 0.73730952 | T9: -0.91880202 | U9: -0.2959221 | V9: 0.94240814 | W9: 0.35867426 | X9: 0.56113642 | Y9: -2.5492907e-05 | Z9: -0.30014077 | AA9: 0.013560629 | AB9: 0.59963363 | AC9: -0.20154873 | AD9: 0.34727153 | AE9: 0.23443905 | AF9: -0.91900116 | AG9: -0.12167752
A10: 964 | B10: 0.19726658 | C10: -0.91568434 | D10: -0.58949006 | E10: 0.96896183 | F10: -0.46260479 | G10: 1.2196518 | H10: 1.0204629 | I10: -0.61039323 | J10: -1.1984537 | K10: 0.26410455 | L10: 0.028728286 | M10: -0.74130261 | N10: -0.0077599236 | O10: 0.3032085 | P10: -0.38385528 | Q10: 0.014143234 | R10: -0.088007562 | S10: 0.7239722 | T10: -0.64608252 | U10: -0.25461185 | V10: 0.75526214 | W10: 1.6753663 | X10: 0.36740059 | Y10: -0.54820997 | Z10: 0.14382713 | AA10: 0.3890242 | AB10: -0.066636458 | AC10: 0.086232394 | AD10: 0.59279865 | AE10: 0.31961083 | AF10: -0.4645896 | AG10: -0.68030226
A11: 966 | B11: 0.063002855 | C11: -0.08321324 | D11: 0.10867299 | E11: 1.1287385 | F11: -0.11874086 | G11: 1.5460591 | H11: 1.4714069 | I11: -0.12510821 | J11: -0.64452684 | K11: 0.26752394 | L11: -0.15131181 | M11: -1.2292403 | N11: 0.57711124 | O11: -0.12393124 | P11: 0.2151798 | Q11: 0.18373741 | R11: 0.042696979 | S11: 0.76062214 | T11: -0.25306079 | U11: 0.0022947714 | V11: 0.14084353 | W11: 1.6643077 | X11: 0.11903192 | Y11: 0.031542741 | Z11: 0.82029516 | AA11: 0.4025887 | AB11: -0.04576733 | AC11: 0.061915819 | AD11: 0.58913749 | AE11: 1.2398236 | AF11: -0.69218349 | AG11: -0.30373114
A12: 968 | B12: -0.033403821 | C12: -0.56960154 | D12: -0.2487011 | E12: 0.72766948 | F12: -0.41125828 | G12: 0.46050951 | H12: 1.1095977 | I12: -0.62449878 | J12: -0.76580513 | K12: 0.38178095 | L12: 0.67874604 | M12: -0.8525151 | N12: 0.64273131 | O12: -0.20116591 | P12: 0.01159543 | Q12: 0.18937063 | R12: 0.64088815 | S12: 0.387485 | T12: 0.12627779 | U12: -0.39201576 | V12: 0.82976079 | W12: 1.6810213 | X12: -0.19919321 | Y12: -0.14549048 | Z12: 0.37946013 | AA12: 0.85326248 | AB12: 0.013282559 | AC12: 0.45148975 | AD12: 0.90727818 | AE12: 1.5829813 | AF12: -0.10512153 | AG12: -0.090747125
A13: 970 | B13: -0.44424945 | C13: -0.49380162 | D13: -0.11942433 | E13: 0.24014638 | F13: -0.043171316 | G13: 0.66200393 | H13: 1.2309264 | I13: 0.28840673 | J13: -0.62386781 | K13: -0.041149851 | L13: 0.80371308 | M13: -0.56709653 | N13: 0.35174197 | O13: -0.17010732 | P13: -0.048331015 | Q13: 0.39920181 | R13: 0.69006366 | S13: 0.9809894 | T13: -0.11803485 | U13: -0.20711923 | V13: 0.51581109 | W13: 1.2613091 | X13: -0.042804718 | Y13: 0.15603067 | Z13: 0.29948261 | AA13: 0.76983118 | AB13: 0.0942863 | AC13: 0.5818184 | AD13: 1.412793 | AE13: 1.1901245 | AF13: -0.45302582 | AG13: -0.56675911
... A1029: 3002 | B1029: -5.1698208 | C1029: -0.99900222 | D1029: 6.298141 | E1029: 6.0897112 | F1029: -7.9328008 | G1029: -3.3400047 | H1029: -0.2178987 | I1029: -2.3682814 | J1029: -0.53375113 | K1029: 0.78391564 | L1029: -0.94265395 | M1029: -2.3973956 | N1029: 2.4427705 | O1029: -2.6557653 | P1029: -5.1307549 | Q1029: -3.1220217 | R1029: 1.1235874 | S1029: 10.720841 | T1029: 4.2068558 | U1029: -6.1000333 | V1029: 2.9219062 | W1029: 3.5543845 | X1029: 3.1934528 | Y1029: 5.4618607 | Z1029: -0.25979298 | AA1029: -1.2526121 | AB1029: 1.4898493 | AC1029: -5.8013906 | AD1029: 14.987514 | AE1029: 0.10339698 | AF1029: 0.38980895 | AG1029: -4.718617
B1030: =MAX(B2:B1029) -> 10.534205 | C1030: =MAX(C2:C1029) -> 3.8250079 | D1030: =MAX(D2:D1029) -> 6.298141 | E1030: =MAX(E2:E1029) -> 19.706179 | F1030: =MAX(F2:F1029) -> 3.0554385 | G1030: =MAX(G2:G1029) -> 6.8406806 | H1030: =MAX(H2:H1029) -> 64.079842 | I1030: =MAX(I2:I1029) -> 5.5102921 | ... AG1030: =MAX(AG2:AG1029) -> 4.2559524

Sheet O-PTIR norm
A1: OPTIR waveno | B1: =#REF!+1 -> #REF! | C1: =B1+1 -> #REF! | D1: =C1+1 -> #REF! | E1: =D1+1 -> #REF! | F1: =#REF!+1 -> #REF! | G1: =F1+1 -> #REF! | H1: =G1+1 -> #REF! | I1: =H1+1 -> #REF! | J1: =I1+1 -> #REF! | K1: =#REF!+1 -> #REF! | L1: =#REF!+1 -> #REF! | M1: =L1+1 -> #REF! | N1: =M1+1 -> #REF! | O1: =#REF!+1 -> #REF! | P1: =O1+1 -> #REF! | Q1: =#REF!+1 -> #REF! | R1: =Q1+1 -> #REF! | S1: =R1+1 -> #REF! | T1: =#REF!+1 -> #REF! | U1: =T1+1 -> #REF! | V1: =#REF!+1 -> #REF! | W1: =#REF!+1 -> #REF! | X1: =#REF!+1 -> #REF! | Y1: =X1+1 -> #REF! | Z1: =Y1+1 -> #REF! | AA1: =#REF!+1 -> #REF! | AB1: =AA1+1 -> #REF! | AC1: =AB1+1 -> #REF! | AD1: =AC1+1 -> #REF! | AE1: =#REF!+1 -> #REF! | AF1: =AE1+1 -> #REF! | AG1: =AF1+1 -> #REF!
A2: 948 | B2: ='O-PTIR'!B2/MAX('O-PTIR'!B:B) -> -0.14065126 | C2: ='O-PTIR'!C2/MAX('O-PTIR'!C:C) -> -0.52878389 | D2: ='O-PTIR'!D2/MAX('O-PTIR'!D:D) -> -0.17516626 | E2: ='O-PTIR'!E2/MAX('O-PTIR'!E:E) -> 0.26397883 | F2: ='O-PTIR'!F2/MAX('O-PTIR'!F:F) -> 0.8084504 | G2: ='O-PTIR'!G2/MAX('O-PTIR'!G:G) -> 0.14998243 | H2: ='O-PTIR'!H2/MAX('O-PTIR'!H:H) -> -0.01058197 | I2: ='O-PTIR'!I2/MAX('O-PTIR'!I:I) -> -0.22559186 | J2: ='O-PTIR'!J2/MAX('O-PTIR'!J:J) -> -0.092097577 | K2: ='O-PTIR'!K2/MAX('O-PTIR'!K:K) -> -0.0072600234 | L2: ='O-PTIR'!L2/MAX('O-PTIR'!L:L) -> 0.75156721 | M2: ='O-PTIR'!M2/MAX('O-PTIR'!M:M) -> -0.77873999 | N2: ='O-PTIR'!N2/MAX('O-PTIR'!N:N) -> 0.34410531 | O2: ='O-PTIR'!O2/MAX('O-PTIR'!O:O) -> 0.52249541 | P2: ='O-PTIR'!P2/MAX('O-PTIR'!P:P) -> -0.43940921 | Q2: ='O-PTIR'!Q2/MAX('O-PTIR'!Q:Q) -> -0.72968042 | R2: ='O-PTIR'!R2/MAX('O-PTIR'!R:R) -> -0.026541379 | S2: ='O-PTIR'!S2/MAX('O-PTIR'!S:S) -> 0.28752249 | T2: ='O-PTIR'!T2/MAX('O-PTIR'!T:T) -> -0.48484162 | U2: ='O-PTIR'!U2/MAX('O-PTIR'!U:U) -> 0.17469682 | V2: ='O-PTIR'!V2/MAX('O-PTIR'!V:V) -> -0.24928627 | W2: ='O-PTIR'!W2/MAX('O-PTIR'!W:W) -> 0.18644796 | X2: ='O-PTIR'!X2/MAX('O-PTIR'!X:X) -> -0.06073096 | Y2: ='O-PTIR'!Y2/MAX('O-PTIR'!Y:Y) -> 0.00099727195 | Z2: ='O-PTIR'!Z2/MAX('O-PTIR'!Z:Z) -> 0.73714371 | AA2: ='O-PTIR'!AA2/MAX('O-PTIR'!AA:AA) -> -0.002847134 | AB2: ='O-PTIR'!AB2/MAX('O-PTIR'!AB:AB) -> -0.40785625 | AC2: ='O-PTIR'!AC2/MAX('O-PTIR'!AC:AC) -> -0.052423373 | AD2: ='O-PTIR'!AD2/MAX('O-PTIR'!AD:AD) -> 0.1131542 | AE2: ='O-PTIR'!AE2/MAX('O-PTIR'!AE:AE) -> -0.022522319 | AF2: ='O-PTIR'!AF2/MAX('O-PTIR'!AF:AF) -> 0.084245134 | AG2: ='O-PTIR'!AG2/MAX('O-PTIR'!AG:AG) -> -0.22657698
A3: 950 | B3: ='O-PTIR'!B3/MAX('O-PTIR'!B:B) -> 0.14132266 | C3: ='O-PTIR'!C3/MAX('O-PTIR'!C:C) -> -0.063420364 | D3: ='O-PTIR'!D3/MAX('O-PTIR'!D:D) -> -0.31291157 | E3: ='O-PTIR'!E3/MAX('O-PTIR'!E:E) -> 0.19929542 | F3: ='O-PTIR'!F3/MAX('O-PTIR'!F:F) -> -0.066812172 | G3: ='O-PTIR'!G3/MAX('O-PTIR'!G:G) -> 0.1483094 | H3: ='O-PTIR'!H3/MAX('O-PTIR'!H:H) -> -0.0026153686 | I3: ='O-PTIR'!I3/MAX('O-PTIR'!I:I) -> -0.13726371 | J3: ='O-PTIR'!J3/MAX('O-PTIR'!J:J) -> -0.12118311 | K3: ='O-PTIR'!K3/MAX('O-PTIR'!K:K) -> -0.023922082 | L3: ='O-PTIR'!L3/MAX('O-PTIR'!L:L) -> 0.40648476 | M3: ='O-PTIR'!M3/MAX('O-PTIR'!M:M) -> -0.96063462 | N3: ='O-PTIR'!N3/MAX('O-PTIR'!N:N) -> -0.25561311 | O3: ='O-PTIR'!O3/MAX('O-PTIR'!O:O) -> -0.0058559823 | P3: ='O-PTIR'!P3/MAX('O-PTIR'!P:P) -> -0.084436788 | Q3: ='O-PTIR'!Q3/MAX('O-PTIR'!Q:Q) -> -0.36944719 | R3: ='O-PTIR'!R3/MAX('O-PTIR'!R:R) -> -0.031532817 | S3: ='O-PTIR'!S3/MAX('O-PTIR'!S:S) -> 0.098257039 | T3: ='O-PTIR'!T3/MAX('O-PTIR'!T:T) -> -0.67548413 | U3: ='O-PTIR'!U3/MAX('O-PTIR'!U:U) -> -0.15049616 | V3: ='O-PTIR'!V3/MAX('O-PTIR'!V:V) -> 0.84994378 | W3: ='O-PTIR'!W3/MAX('O-PTIR'!W:W) -> 0.022492911 | X3: ='O-PTIR'!X3/MAX('O-PTIR'!X:X) -> 0.045376991 | Y3: ='O-PTIR'!Y3/MAX('O-PTIR'!Y:Y) -> -0.007438498 | Z3: ='O-PTIR'!Z3/MAX('O-PTIR'!Z:Z) -> 0.64508437 | AA3: ='O-PTIR'!AA3/MAX('O-PTIR'!AA:AA) -> 0.03310206 | AB3: ='O-PTIR'!AB3/MAX('O-PTIR'!AB:AB) -> -0.28314774 | AC3: ='O-PTIR'!AC3/MAX('O-PTIR'!AC:AC) -> 0.016479133 | AD3: ='O-PTIR'!AD3/MAX('O-PTIR'!AD:AD) -> 0.14429222 | AE3: ='O-PTIR'!AE3/MAX('O-PTIR'!AE:AE) -> 0.0074444383 | AF3: ='O-PTIR'!AF3/MAX('O-PTIR'!AF:AF) -> -0.31731379 | AG3: ='O-PTIR'!AG3/MAX('O-PTIR'!AG:AG) -> -0.31687324
A4: 952 | B4: ='O-PTIR'!B4/MAX('O-PTIR'!B:B) -> -0.014124846 | C4: ='O-PTIR'!C4/MAX('O-PTIR'!C:C) -> -0.15550946 | D4: ='O-PTIR'!D4/MAX('O-PTIR'!D:D) -> 0.075671035 | E4: ='O-PTIR'!E4/MAX('O-PTIR'!E:E) -> 0.11614787 | F4: ='O-PTIR'!F4/MAX('O-PTIR'!F:F) -> -0.25426612 | G4: ='O-PTIR'!G4/MAX('O-PTIR'!G:G) -> 0.11137096 | H4: ='O-PTIR'!H4/MAX('O-PTIR'!H:H) -> 0.004788739 | I4: ='O-PTIR'!I4/MAX('O-PTIR'!I:I) -> -0.025678159 | J4: ='O-PTIR'!J4/MAX('O-PTIR'!J:J) -> -0.13633262 | K4: ='O-PTIR'!K4/MAX('O-PTIR'!K:K) -> -0.046466311 | L4: ='O-PTIR'!L4/MAX('O-PTIR'!L:L) -> -0.087479587 | M4: ='O-PTIR'!M4/MAX('O-PTIR'!M:M) -> -1.2362451 | N4: ='O-PTIR'!N4/MAX('O-PTIR'!N:N) -> 0.2220164 | O4: ='O-PTIR'!O4/MAX('O-PTIR'!O:O) -> -0.0062708905 | P4: ='O-PTIR'!P4/MAX('O-PTIR'!P:P) -> -0.15403147 | Q4: ='O-PTIR'!Q4/MAX('O-PTIR'!Q:Q) -> -0.14983566 | R4: ='O-PTIR'!R4/MAX('O-PTIR'!R:R) -> -0.00020015918 | S4: ='O-PTIR'!S4/MAX('O-PTIR'!S:S) -> 0.33859628 | T4: ='O-PTIR'!T4/MAX('O-PTIR'!T:T) -> 0.048644318 | U4: ='O-PTIR'!U4/MAX('O-PTIR'!U:U) -> -0.17041502 | V4: ='O-PTIR'!V4/MAX('O-PTIR'!V:V) -> 0.64582114 | W4: ='O-PTIR'!W4/MAX('O-PTIR'!W:W) -> 0.07979418 | X4: ='O-PTIR'!X4/MAX('O-PTIR'!X:X) -> -0.057454463 | Y4: ='O-PTIR'!Y4/MAX('O-PTIR'!Y:Y) -> 0.003145593 | Z4: ='O-PTIR'!Z4/MAX('O-PTIR'!Z:Z) -> -0.089008197 | AA4: ='O-PTIR'!AA4/MAX('O-PTIR'!AA:AA) -> -0.011196991 | AB4: ='O-PTIR'!AB4/MAX('O-PTIR'!AB:AB) -> 0.37349959 | AC4: ='O-PTIR'!AC4/MAX('O-PTIR'!AC:AC) -> 0.026390461 | AD4: ='O-PTIR'!AD4/MAX('O-PTIR'!AD:AD) -> 0.17421449 | AE4: ='O-PTIR'!AE4/MAX('O-PTIR'!AE:AE) -> 0.021262842 | AF4: ='O-PTIR'!AF4/MAX('O-PTIR'!AF:AF) -> 0.89724133 | AG4: ='O-PTIR'!AG4/MAX('O-PTIR'!AG:AG) -> -0.70032197
A5: 954 | B5: ='O-PTIR'!B5/MAX('O-PTIR'!B:B) -> 0.0061967493 | C5: ='O-PTIR'!C5/MAX('O-PTIR'!C:C) -> 0.0053578972 | D5: ='O-PTIR'!D5/MAX('O-PTIR'!D:D) -> -0.20302771 | E5: ='O-PTIR'!E5/MAX('O-PTIR'!E:E) -> 0.084916945 | F5: ='O-PTIR'!F5/MAX('O-PTIR'!F:F) -> -0.70563768 | G5: ='O-PTIR'!G5/MAX('O-PTIR'!G:G) -> 0.0035643857 | H5: ='O-PTIR'!H5/MAX('O-PTIR'!H:H) -> 0.009112797 | I5: ='O-PTIR'!I5/MAX('O-PTIR'!I:I) -> 0.20298938 | J5: ='O-PTIR'!J5/MAX('O-PTIR'!J:J) -> -0.058158281 | K5: ='O-PTIR'!K5/MAX('O-PTIR'!K:K) -> -0.0081983513 | L5: ='O-PTIR'!L5/MAX('O-PTIR'!L:L) -> -0.11867152 | M5: ='O-PTIR'!M5/MAX('O-PTIR'!M:M) -> -0.65770687 | N5: ='O-PTIR'!N5/MAX('O-PTIR'!N:N) -> 0.50211787 | O5: ='O-PTIR'!O5/MAX('O-PTIR'!O:O) -> -0.024714881 | P5: ='O-PTIR'!P5/MAX('O-PTIR'!P:P) -> 0.12975789 | Q5: ='O-PTIR'!Q5/MAX('O-PTIR'!Q:Q) -> -0.72311188 | R5: ='O-PTIR'!R5/MAX('O-PTIR'!R:R) -> -0.011310513 | S5: ='O-PTIR'!S5/MAX('O-PTIR'!S:S) -> 0.20147929 | T5: ='O-PTIR'!T5/MAX('O-PTIR'!T:T) -> 0.05137782 | U5: ='O-PTIR'!U5/MAX('O-PTIR'!U:U) -> -0.13541584 | V5: ='O-PTIR'!V5/MAX('O-PTIR'!V:V) -> 0.30196264 | W5: ='O-PTIR'!W5/MAX('O-PTIR'!W:W) -> 0.073379876 | X5: ='O-PTIR'!X5/MAX('O-PTIR'!X:X) -> 0.13422313 | Y5: ='O-PTIR'!Y5/MAX('O-PTIR'!Y:Y) -> 0.014046061 | Z5: ='O-PTIR'!Z5/MAX('O-PTIR'!Z:Z) -> -0.26363156 | AA5: ='O-PTIR'!AA5/MAX('O-PTIR'!AA:AA) -> -0.022211363 | AB5: ='O-PTIR'!AB5/MAX('O-PTIR'!AB:AB) -> 0.3474292 | AC5: ='O-PTIR'!AC5/MAX('O-PTIR'!AC:AC) -> 0.027185988 | AD5: ='O-PTIR'!AD5/MAX('O-PTIR'!AD:AD) -> 0.084241184 | AE5: ='O-PTIR'!AE5/MAX('O-PTIR'!AE:AE) -> 0.0074409556 | AF5: ='O-PTIR'!AF5/MAX('O-PTIR'!AF:AF) -> -0.19241451 | AG5: ='O-PTIR'!AG5/MAX('O-PTIR'!AG:AG) -> -0.47181016
A6: 956 | B6: ='O-PTIR'!B6/MAX('O-PTIR'!B:B) -> 0.074175498 | C6: ='O-PTIR'!C6/MAX('O-PTIR'!C:C) -> -0.32232349 | D6: ='O-PTIR'!D6/MAX('O-PTIR'!D:D) -> -0.029452096 | E6: ='O-PTIR'!E6/MAX('O-PTIR'!E:E) -> 0.081546249 | F6: ='O-PTIR'!F6/MAX('O-PTIR'!F:F) -> -0.14503793 | G6: ='O-PTIR'!G6/MAX('O-PTIR'!G:G) -> -0.088621389 | H6: ='O-PTIR'!H6/MAX('O-PTIR'!H:H) -> 0.023563222 | I6: ='O-PTIR'!I6/MAX('O-PTIR'!I:I) -> 0.17935674 | J6: ='O-PTIR'!J6/MAX('O-PTIR'!J:J) -> 0.025954479 | K6: ='O-PTIR'!K6/MAX('O-PTIR'!K:K) -> 0.0030552257 | L6: ='O-PTIR'!L6/MAX('O-PTIR'!L:L) -> 0.00076669398 | M6: ='O-PTIR'!M6/MAX('O-PTIR'!M:M) -> 0.010845851 | N6: ='O-PTIR'!N6/MAX('O-PTIR'!N:N) -> 0.18685339 | O6: ='O-PTIR'!O6/MAX('O-PTIR'!O:O) -> 0.046138947 | P6: ='O-PTIR'!P6/MAX('O-PTIR'!P:P) -> 0.14772821 | Q6: ='O-PTIR'!Q6/MAX('O-PTIR'!Q:Q) -> -0.44645803 | R6: ='O-PTIR'!R6/MAX('O-PTIR'!R:R) -> -0.010773845 | S6: ='O-PTIR'!S6/MAX('O-PTIR'!S:S) -> 0.2115383 | T6: ='O-PTIR'!T6/MAX('O-PTIR'!T:T) -> -0.026501878 | U6: ='O-PTIR'!U6/MAX('O-PTIR'!U:U) -> -0.035792703 | V6: ='O-PTIR'!V6/MAX('O-PTIR'!V:V) -> 0.11265395 | W6: ='O-PTIR'!W6/MAX('O-PTIR'!W:W) -> 0.055793459 | X6: ='O-PTIR'!X6/MAX('O-PTIR'!X:X) -> 0.060109148 | Y6: ='O-PTIR'!Y6/MAX('O-PTIR'!Y:Y) -> -0.016055672 | Z6: ='O-PTIR'!Z6/MAX('O-PTIR'!Z:Z) -> 0.092557331 | AA6: ='O-PTIR'!AA6/MAX('O-PTIR'!AA:AA) -> -0.021574832 | AB6: ='O-PTIR'!AB6/MAX('O-PTIR'!AB:AB) -> 0.18125742 | AC6: ='O-PTIR'!AC6/MAX('O-PTIR'!AC:AC) -> -0.040003159 | AD6: ='O-PTIR'!AD6/MAX('O-PTIR'!AD:AD) -> 0.10464416 | AE6: ='O-PTIR'!AE6/MAX('O-PTIR'!AE:AE) -> -0.0088320305 | AF6: ='O-PTIR'!AF6/MAX('O-PTIR'!AF:AF) -> -0.70887131 | AG6: ='O-PTIR'!AG6/MAX('O-PTIR'!AG:AG) -> -0.12521942
A7: 958 | B7: ='O-PTIR'!B7/MAX('O-PTIR'!B:B) -> -0.10074199 | C7: ='O-PTIR'!C7/MAX('O-PTIR'!C:C) -> -0.50603575 | D7: ='O-PTIR'!D7/MAX('O-PTIR'!D:D) -> 0.092991622 | E7: ='O-PTIR'!E7/MAX('O-PTIR'!E:E) -> 0.091542383 | F7: ='O-PTIR'!F7/MAX('O-PTIR'!F:F) -> 0.052285635 | G7: ='O-PTIR'!G7/MAX('O-PTIR'!G:G) -> 0.030529084 | H7: ='O-PTIR'!H7/MAX('O-PTIR'!H:H) -> 0.01649041 | I7: ='O-PTIR'!I7/MAX('O-PTIR'!I:I) -> -0.16435093 | J7: ='O-PTIR'!J7/MAX('O-PTIR'!J:J) -> -0.049942824 | K7: ='O-PTIR'!K7/MAX('O-PTIR'!K:K) -> 0.0085276041 | L7: ='O-PTIR'!L7/MAX('O-PTIR'!L:L) -> 0.11536724 | M7: ='O-PTIR'!M7/MAX('O-PTIR'!M:M) -> 0.11408892 | N7: ='O-PTIR'!N7/MAX('O-PTIR'!N:N) -> 0.15450582 | O7: ='O-PTIR'!O7/MAX('O-PTIR'!O:O) -> 0.095571167 | P7: ='O-PTIR'!P7/MAX('O-PTIR'!P:P) -> 0.068945208 | Q7: ='O-PTIR'!Q7/MAX('O-PTIR'!Q:Q) -> -0.14456862 | R7: ='O-PTIR'!R7/MAX('O-PTIR'!R:R) -> -0.0090622455 | S7: ='O-PTIR'!S7/MAX('O-PTIR'!S:S) -> 0.11112253 | T7: ='O-PTIR'!T7/MAX('O-PTIR'!T:T) -> -0.32392337 | U7: ='O-PTIR'!U7/MAX('O-PTIR'!U:U) -> 0.070036572 | V7: ='O-PTIR'!V7/MAX('O-PTIR'!V:V) -> 0.25681119 | W7: ='O-PTIR'!W7/MAX('O-PTIR'!W:W) -> 0.084324445 | X7: ='O-PTIR'!X7/MAX('O-PTIR'!X:X) -> -0.0064461413 | Y7: ='O-PTIR'!Y7/MAX('O-PTIR'!Y:Y) -> -0.0078752767 | Z7: ='O-PTIR'!Z7/MAX('O-PTIR'!Z:Z) -> 0.020087121 | AA7: ='O-PTIR'!AA7/MAX('O-PTIR'!AA:AA) -> 0.013177007 | AB7: ='O-PTIR'!AB7/MAX('O-PTIR'!AB:AB) -> -0.11834216 | AC7: ='O-PTIR'!AC7/MAX('O-PTIR'!AC:AC) -> -0.0049989022 | AD7: ='O-PTIR'!AD7/MAX('O-PTIR'!AD:AD) -> 0.12015089 | AE7: ='O-PTIR'!AE7/MAX('O-PTIR'!AE:AE) -> 0.023281699 | AF7: ='O-PTIR'!AF7/MAX('O-PTIR'!AF:AF) -> -0.61834299 | AG7: ='O-PTIR'!AG7/MAX('O-PTIR'!AG:AG) -> -0.1018692
A8: 960 | B8: ='O-PTIR'!B8/MAX('O-PTIR'!B:B) -> -0.042449474 | C8: ='O-PTIR'!C8/MAX('O-PTIR'!C:C) -> -0.24096592 | D8: ='O-PTIR'!D8/MAX('O-PTIR'!D:D) -> 0.04799373 | E8: ='O-PTIR'!E8/MAX('O-PTIR'!E:E) -> 0.051247734 | F8: ='O-PTIR'!F8/MAX('O-PTIR'!F:F) -> -0.040797374 | G8: ='O-PTIR'!G8/MAX('O-PTIR'!G:G) -> 0.074736204 | H8: ='O-PTIR'!H8/MAX('O-PTIR'!H:H) -> 0.0091920868 | I8: ='O-PTIR'!I8/MAX('O-PTIR'!I:I) -> -0.12334789 | J8: ='O-PTIR'!J8/MAX('O-PTIR'!J:J) -> -0.035299493 | K8: ='O-PTIR'!K8/MAX('O-PTIR'!K:K) -> 0.017817302 | L8: ='O-PTIR'!L8/MAX('O-PTIR'!L:L) -> 0.026101809 | M8: ='O-PTIR'!M8/MAX('O-PTIR'!M:M) -> -0.410275 | N8: ='O-PTIR'!N8/MAX('O-PTIR'!N:N) -> 0.061200423 | O8: ='O-PTIR'!O8/MAX('O-PTIR'!O:O) -> -0.044068952 | P8: ='O-PTIR'!P8/MAX('O-PTIR'!P:P) -> -0.053007729 | Q8: ='O-PTIR'!Q8/MAX('O-PTIR'!Q:Q) -> -0.30631158 | R8: ='O-PTIR'!R8/MAX('O-PTIR'!R:R) -> 0.0047313013 | S8: ='O-PTIR'!S8/MAX('O-PTIR'!S:S) -> 0.15410086 | T8: ='O-PTIR'!T8/MAX('O-PTIR'!T:T) -> -0.16286354 | U8: ='O-PTIR'!U8/MAX('O-PTIR'!U:U) -> -0.068878499 | V8: ='O-PTIR'!V8/MAX('O-PTIR'!V:V) -> 0.12178975 | W8: ='O-PTIR'!W8/MAX('O-PTIR'!W:W) -> 0.033522053 | X8: ='O-PTIR'!X8/MAX('O-PTIR'!X:X) -> 0.014052642 | Y8: ='O-PTIR'!Y8/MAX('O-PTIR'!Y:Y) -> -0.0053296407 | Z8: ='O-PTIR'!Z8/MAX('O-PTIR'!Z:Z) -> -0.049209952 | AA8: ='O-PTIR'!AA8/MAX('O-PTIR'!AA:AA) -> -0.0085091781 | AB8: ='O-PTIR'!AB8/MAX('O-PTIR'!AB:AB) -> -0.11932656 | AC8: ='O-PTIR'!AC8/MAX('O-PTIR'!AC:AC) -> -0.011691604 | AD8: ='O-PTIR'!AD8/MAX('O-PTIR'!AD:AD) -> 0.077689631 | AE8: ='O-PTIR'!AE8/MAX('O-PTIR'!AE:AE) -> 0.016779867 | AF8: ='O-PTIR'!AF8/MAX('O-PTIR'!AF:AF) -> -0.53124204 | AG8: ='O-PTIR'!AG8/MAX('O-PTIR'!AG:AG) -> -0.040518559
A9: 962 | B9: ='O-PTIR'!B9/MAX('O-PTIR'!B:B) -> -0.027373293 | C9: ='O-PTIR'!C9/MAX('O-PTIR'!C:C) -> -0.10790924 | D9: ='O-PTIR'!D9/MAX('O-PTIR'!D:D) -> -0.16569005 | E9: ='O-PTIR'!E9/MAX('O-PTIR'!E:E) -> 0.079247912 | F9: ='O-PTIR'!F9/MAX('O-PTIR'!F:F) -> -0.10142348 | G9: ='O-PTIR'!G9/MAX('O-PTIR'!G:G) -> 0.2114852 | H9: ='O-PTIR'!H9/MAX('O-PTIR'!H:H) -> 0.013416928 | I9: ='O-PTIR'!I9/MAX('O-PTIR'!I:I) -> -0.1631903 | J9: ='O-PTIR'!J9/MAX('O-PTIR'!J:J) -> -0.046160854 | K9: ='O-PTIR'!K9/MAX('O-PTIR'!K:K) -> 0.050252558 | L9: ='O-PTIR'!L9/MAX('O-PTIR'!L:L) -> -0.0025617689 | M9: ='O-PTIR'!M9/MAX('O-PTIR'!M:M) -> -0.10340356 | N9: ='O-PTIR'!N9/MAX('O-PTIR'!N:N) -> 0.0027672478 | O9: ='O-PTIR'!O9/MAX('O-PTIR'!O:O) -> -0.0091247725 | P9: ='O-PTIR'!P9/MAX('O-PTIR'!P:P) -> -0.20775913 | Q9: ='O-PTIR'!Q9/MAX('O-PTIR'!Q:Q) -> -0.33030238 | R9: ='O-PTIR'!R9/MAX('O-PTIR'!R:R) -> 0.0092876784 | S9: ='O-PTIR'!S9/MAX('O-PTIR'!S:S) -> 0.068773475 | T9: ='O-PTIR'!T9/MAX('O-PTIR'!T:T) -> -0.21840588 | U9: ='O-PTIR'!U9/MAX('O-PTIR'!U:U) -> -0.033184475 | V9: ='O-PTIR'!V9/MAX('O-PTIR'!V:V) -> 0.22753448 | W9: ='O-PTIR'!W9/MAX('O-PTIR'!W:W) -> 0.01823357 | X9: ='O-PTIR'!X9/MAX('O-PTIR'!X:X) -> 0.030807259 | Y9: ='O-PTIR'!Y9/MAX('O-PTIR'!Y:Y) -> -5.6011382e-07 | Z9: ='O-PTIR'!Z9/MAX('O-PTIR'!Z:Z) -> -0.068009313 | AA9: ='O-PTIR'!AA9/MAX('O-PTIR'!AA:AA) -> 0.00026307499 | AB9: ='O-PTIR'!AB9/MAX('O-PTIR'!AB:AB) -> 0.13308836 | AC9: ='O-PTIR'!AC9/MAX('O-PTIR'!AC:AC) -> -0.0054054966 | AD9: ='O-PTIR'!AD9/MAX('O-PTIR'!AD:AD) -> 0.023170722 | AE9: ='O-PTIR'!AE9/MAX('O-PTIR'!AE:AE) -> 0.0036878217 | AF9: ='O-PTIR'!AF9/MAX('O-PTIR'!AF:AF) -> -0.36231448 | AG9: ='O-PTIR'!AG9/MAX('O-PTIR'!AG:AG) -> -0.028589962
A10: 964 | B10: ='O-PTIR'!B10/MAX('O-PTIR'!B:B) -> 0.018726289 | C10: ='O-PTIR'!C10/MAX('O-PTIR'!C:C) -> -0.2393941 | D10: ='O-PTIR'!D10/MAX('O-PTIR'!D:D) -> -0.093597469 | E10: ='O-PTIR'!E10/MAX('O-PTIR'!E:E) -> 0.049170458 | F10: ='O-PTIR'!F10/MAX('O-PTIR'!F:F) -> -0.15140373 | G10: ='O-PTIR'!G10/MAX('O-PTIR'!G:G) -> 0.17829393 | H10: ='O-PTIR'!H10/MAX('O-PTIR'!H:H) -> 0.015924866 | I10: ='O-PTIR'!I10/MAX('O-PTIR'!I:I) -> -0.1107733 | J10: ='O-PTIR'!J10/MAX('O-PTIR'!J:J) -> -0.048040005 | K10: ='O-PTIR'!K10/MAX('O-PTIR'!K:K) -> 0.013496267 | L10: ='O-PTIR'!L10/MAX('O-PTIR'!L:L) -> 0.0045417877 | M10: ='O-PTIR'!M10/MAX('O-PTIR'!M:M) -> -0.25631273 | N10: ='O-PTIR'!N10/MAX('O-PTIR'!N:N) -> -0.0015767228 | O10: ='O-PTIR'!O10/MAX('O-PTIR'!O:O) -> 0.030649328 | P10: ='O-PTIR'!P10/MAX('O-PTIR'!P:P) -> -0.066128468 | Q10: ='O-PTIR'!Q10/MAX('O-PTIR'!Q:Q) -> 0.0046407032 | R10: ='O-PTIR'!R10/MAX('O-PTIR'!R:R) -> -0.0011445967 | S10: ='O-PTIR'!S10/MAX('O-PTIR'!S:S) -> 0.06752942 | T10: ='O-PTIR'!T10/MAX('O-PTIR'!T:T) -> -0.15357848 | U10: ='O-PTIR'!U10/MAX('O-PTIR'!U:U) -> -0.028551976 | V10: ='O-PTIR'!V10/MAX('O-PTIR'!V:V) -> 0.18235005 | W10: ='O-PTIR'!W10/MAX('O-PTIR'!W:W) -> 0.085168947 | X10: ='O-PTIR'!X10/MAX('O-PTIR'!X:X) -> 0.020170861 | Y10: ='O-PTIR'!Y10/MAX('O-PTIR'!Y:Y) -> -0.012044918 | Z10: ='O-PTIR'!Z10/MAX('O-PTIR'!Z:Z) -> 0.032589988 | AA10: ='O-PTIR'!AA10/MAX('O-PTIR'!AA:AA) -> 0.0075470344 | AB10: ='O-PTIR'!AB10/MAX('O-PTIR'!AB:AB) -> -0.014789925 | AC10: ='O-PTIR'!AC10/MAX('O-PTIR'!AC:AC) -> 0.0023127356 | AD10: ='O-PTIR'!AD10/MAX('O-PTIR'!AD:AD) -> 0.039552832 | AE10: ='O-PTIR'!AE10/MAX('O-PTIR'!AE:AE) -> 0.0050276087 | AF10: ='O-PTIR'!AF10/MAX('O-PTIR'!AF:AF) -> -0.18316357 | AG10: ='O-PTIR'!AG10/MAX('O-PTIR'!AG:AG) -> -0.15984725
A11: 966 | B11: ='O-PTIR'!B11/MAX('O-PTIR'!B:B) -> 0.0059807885 | C11: ='O-PTIR'!C11/MAX('O-PTIR'!C:C) -> -0.02175505 | D11: ='O-PTIR'!D11/MAX('O-PTIR'!D:D) -> 0.017254773 | E11: ='O-PTIR'!E11/MAX('O-PTIR'!E:E) -> 0.057278407 | F11: ='O-PTIR'!F11/MAX('O-PTIR'!F:F) -> -0.038862133 | G11: ='O-PTIR'!G11/MAX('O-PTIR'!G:G) -> 0.22600955 | H11: ='O-PTIR'!H11/MAX('O-PTIR'!H:H) -> 0.022962088 | I11: ='O-PTIR'!I11/MAX('O-PTIR'!I:I) -> -0.022704461 | J11: ='O-PTIR'!J11/MAX('O-PTIR'!J:J) -> -0.025835853 | K11: ='O-PTIR'!K11/MAX('O-PTIR'!K:K) -> 0.013671005 | L11: ='O-PTIR'!L11/MAX('O-PTIR'!L:L) -> -0.023921586 | M11: ='O-PTIR'!M11/MAX('O-PTIR'!M:M) -> -0.42502203 | N11: ='O-PTIR'!N11/MAX('O-PTIR'!N:N) -> 0.11726204 | O11: ='O-PTIR'!O11/MAX('O-PTIR'!O:O) -> -0.012527383 | P11: ='O-PTIR'!P11/MAX('O-PTIR'!P:P) -> 0.037069988 | Q11: ='O-PTIR'!Q11/MAX('O-PTIR'!Q:Q) -> 0.060288248 | R11: ='O-PTIR'!R11/MAX('O-PTIR'!R:R) -> 0.00055530254 | S11: ='O-PTIR'!S11/MAX('O-PTIR'!S:S) -> 0.07094799 | T11: ='O-PTIR'!T11/MAX('O-PTIR'!T:T) -> -0.060154377 | U11: ='O-PTIR'!U11/MAX('O-PTIR'!U:U) -> 0.00025733389 | V11: ='O-PTIR'!V11/MAX('O-PTIR'!V:V) -> 0.034005179 | W11: ='O-PTIR'!W11/MAX('O-PTIR'!W:W) -> 0.084606774 | X11: ='O-PTIR'!X11/MAX('O-PTIR'!X:X) -> 0.0065350369 | Y11: ='O-PTIR'!Y11/MAX('O-PTIR'!Y:Y) -> 0.00069303689 | Z11: ='O-PTIR'!Z11/MAX('O-PTIR'!Z:Z) -> 0.18587182 | AA11: ='O-PTIR'!AA11/MAX('O-PTIR'!AA:AA) -> 0.0078101845 | AB11: ='O-PTIR'!AB11/MAX('O-PTIR'!AB:AB) -> -0.010158034 | AC11: ='O-PTIR'!AC11/MAX('O-PTIR'!AC:AC) -> 0.0016605699 | AD11: ='O-PTIR'!AD11/MAX('O-PTIR'!AD:AD) -> 0.039308552 | AE11: ='O-PTIR'!AE11/MAX('O-PTIR'!AE:AE) -> 0.01950293 | AF11: ='O-PTIR'!AF11/MAX('O-PTIR'!AF:AF) -> -0.27289204 | AG11: ='O-PTIR'!AG11/MAX('O-PTIR'!AG:AG) -> -0.071366199
A12: 968 | B12: ='O-PTIR'!B12/MAX('O-PTIR'!B:B) -> -0.0031709863 | C12: ='O-PTIR'!C12/MAX('O-PTIR'!C:C) -> -0.14891513 | D12: ='O-PTIR'!D12/MAX('O-PTIR'!D:D) -> -0.039488016 | E12: ='O-PTIR'!E12/MAX('O-PTIR'!E:E) -> 0.036925956 | F12: ='O-PTIR'!F12/MAX('O-PTIR'!F:F) -> -0.13459877 | G12: ='O-PTIR'!G12/MAX('O-PTIR'!G:G) -> 0.067319253 | H12: ='O-PTIR'!H12/MAX('O-PTIR'!H:H) -> 0.017315862 | I12: ='O-PTIR'!I12/MAX('O-PTIR'!I:I) -> -0.11333316 | J12: ='O-PTIR'!J12/MAX('O-PTIR'!J:J) -> -0.030697292 | K12: ='O-PTIR'!K12/MAX('O-PTIR'!K:K) -> 0.019509766 | L12: ='O-PTIR'!L12/MAX('O-PTIR'!L:L) -> 0.10730611 | M12: ='O-PTIR'!M12/MAX('O-PTIR'!M:M) -> -0.29476555 | N12: ='O-PTIR'!N12/MAX('O-PTIR'!N:N) -> 0.13059524 | O12: ='O-PTIR'!O12/MAX('O-PTIR'!O:O) -> -0.020334523 | P12: ='O-PTIR'!P12/MAX('O-PTIR'!P:P) -> 0.0019975966 | Q12: ='O-PTIR'!Q12/MAX('O-PTIR'!Q:Q) -> 0.06213663 | R12: ='O-PTIR'!R12/MAX('O-PTIR'!R:R) -> 0.0083351757 | S12: ='O-PTIR'!S12/MAX('O-PTIR'!S:S) -> 0.036143152 | T12: ='O-PTIR'!T12/MAX('O-PTIR'!T:T) -> 0.030017143 | U12: ='O-PTIR'!U12/MAX('O-PTIR'!U:U) -> -0.043960343 | V12: ='O-PTIR'!V12/MAX('O-PTIR'!V:V) -> 0.20033697 | W12: ='O-PTIR'!W12/MAX('O-PTIR'!W:W) -> 0.085456428 | X12: ='O-PTIR'!X12/MAX('O-PTIR'!X:X) -> -0.010936016 | Y12: ='O-PTIR'!Y12/MAX('O-PTIR'!Y:Y) -> -0.0031966237 | Z12: ='O-PTIR'!Z12/MAX('O-PTIR'!Z:Z) -> 0.085982396 | AA12: ='O-PTIR'!AA12/MAX('O-PTIR'!AA:AA) -> 0.016553215 | AB12: ='O-PTIR'!AB12/MAX('O-PTIR'!AB:AB) -> 0.0029480567 | AC12: ='O-PTIR'!AC12/MAX('O-PTIR'!AC:AC) -> 0.012108865 | AD12: ='O-PTIR'!AD12/MAX('O-PTIR'!AD:AD) -> 0.0605356 | AE12: ='O-PTIR'!AE12/MAX('O-PTIR'!AE:AE) -> 0.024900942 | AF12: ='O-PTIR'!AF12/MAX('O-PTIR'!AF:AF) -> -0.041443965 | AG12: ='O-PTIR'!AG12/MAX('O-PTIR'!AG:AG) -> -0.021322402
A13: 970 | B13: ='O-PTIR'!B13/MAX('O-PTIR'!B:B) -> -0.042172089 | C13: ='O-PTIR'!C13/MAX('O-PTIR'!C:C) -> -0.1290982 | D13: ='O-PTIR'!D13/MAX('O-PTIR'!D:D) -> -0.018961838 | E13: ='O-PTIR'!E13/MAX('O-PTIR'!E:E) -> 0.01218635 | F13: ='O-PTIR'!F13/MAX('O-PTIR'!F:F) -> -0.014129336 | G13: ='O-PTIR'!G13/MAX('O-PTIR'!G:G) -> 0.096774572 | H13: ='O-PTIR'!H13/MAX('O-PTIR'!H:H) -> 0.019209261 | I13: ='O-PTIR'!I13/MAX('O-PTIR'!I:I) -> 0.052339645 | J13: ='O-PTIR'!J13/MAX('O-PTIR'!J:J) -> -0.025007736 | K13: ='O-PTIR'!K13/MAX('O-PTIR'!K:K) -> -0.0021028392 | L13: ='O-PTIR'!L13/MAX('O-PTIR'!L:L) -> 0.12706272 | M13: ='O-PTIR'!M13/MAX('O-PTIR'!M:M) -> -0.19607925 | N13: ='O-PTIR'!N13/MAX('O-PTIR'!N:N) -> 0.071469723 | O13: ='O-PTIR'!O13/MAX('O-PTIR'!O:O) -> -0.017195016 | P13: ='O-PTIR'!P13/MAX('O-PTIR'!P:P) -> -0.0083262003 | Q13: ='O-PTIR'!Q13/MAX('O-PTIR'!Q:Q) -> 0.13098681 | R13: ='O-PTIR'!R13/MAX('O-PTIR'!R:R) -> 0.0089747357 | S13: ='O-PTIR'!S13/MAX('O-PTIR'!S:S) -> 0.091503023 | T13: ='O-PTIR'!T13/MAX('O-PTIR'!T:T) -> -0.028057736 | U13: ='O-PTIR'!U13/MAX('O-PTIR'!U:U) -> -0.02322619 | V13: ='O-PTIR'!V13/MAX('O-PTIR'!V:V) -> 0.12453713 | W13: ='O-PTIR'!W13/MAX('O-PTIR'!W:W) -> 0.064119932 | X13: ='O-PTIR'!X13/MAX('O-PTIR'!X:X) -> -0.0023500453 | Y13: ='O-PTIR'!Y13/MAX('O-PTIR'!Y:Y) -> 0.0034282059 | Z13: ='O-PTIR'!Z13/MAX('O-PTIR'!Z:Z) -> 0.067860181 | AA13: ='O-PTIR'!AA13/MAX('O-PTIR'!AA:AA) -> 0.014934656 | AB13: ='O-PTIR'!AB13/MAX('O-PTIR'!AB:AB) -> 0.020926793 | AC13: ='O-PTIR'!AC13/MAX('O-PTIR'!AC:AC) -> 0.015604254 | AD13: ='O-PTIR'!AD13/MAX('O-PTIR'!AD:AD) -> 0.094264665 | AE13: ='O-PTIR'!AE13/MAX('O-PTIR'!AE:AE) -> 0.018721144 | AF13: ='O-PTIR'!AF13/MAX('O-PTIR'!AF:AF) -> -0.17860458 | AG13: ='O-PTIR'!AG13/MAX('O-PTIR'!AG:AG) -> -0.13316857
... A1029: 3002 | B1029: ='O-PTIR'!B1029/MAX('O-PTIR'!B:B) -> -0.49076514 | C1029: ='O-PTIR'!C1029/MAX('O-PTIR'!C:C) -> -0.26117651 | D1029: ='O-PTIR'!D1029/MAX('O-PTIR'!D:D) -> 1 | E1029: ='O-PTIR'!E1029/MAX('O-PTIR'!E:E) -> 0.30902547 | F1029: ='O-PTIR'!F1029/MAX('O-PTIR'!F:F) -> -2.5962888 | G1029: ='O-PTIR'!G1029/MAX('O-PTIR'!G:G) -> -0.4882562 | H1029: ='O-PTIR'!H1029/MAX('O-PTIR'!H:H) -> -0.003400425 | I1029: ='O-PTIR'!I1029/MAX('O-PTIR'!I:I) -> -0.42979235 | J1029: ='O-PTIR'!J1029/MAX('O-PTIR'!J:J) -> -0.02139541 | K1029: ='O-PTIR'!K1029/MAX('O-PTIR'!K:K) -> 0.040059648 | L1029: ='O-PTIR'!L1029/MAX('O-PTIR'!L:L) -> -0.14902853 | M1029: ='O-PTIR'!M1029/MAX('O-PTIR'!M:M) -> -0.82892332 | N1029: ='O-PTIR'!N1029/MAX('O-PTIR'!N:N) -> 0.49634148 | O1029: ='O-PTIR'!O1029/MAX('O-PTIR'!O:O) -> -0.26845363 | P1029: ='O-PTIR'!P1029/MAX('O-PTIR'!P:P) -> -0.88389813 | Q1029: ='O-PTIR'!Q1029/MAX('O-PTIR'!Q:Q) -> -1.0244033 | R1029: ='O-PTIR'!R1029/MAX('O-PTIR'!R:R) -> 0.014612999 | S1029: ='O-PTIR'!S1029/MAX('O-PTIR'!S:S) -> 1 | T1029: ='O-PTIR'!T1029/MAX('O-PTIR'!T:T) -> 1 | U1029: ='O-PTIR'!U1029/MAX('O-PTIR'!U:U) -> -0.68405301 | V1029: ='O-PTIR'!V1029/MAX('O-PTIR'!V:V) -> 0.70546335 | W1029: ='O-PTIR'!W1029/MAX('O-PTIR'!W:W) -> 0.18069075 | X1029: ='O-PTIR'!X1029/MAX('O-PTIR'!X:X) -> 0.17532551 | Y1029: ='O-PTIR'!Y1029/MAX('O-PTIR'!Y:Y) -> 0.1200045 | Z1029: ='O-PTIR'!Z1029/MAX('O-PTIR'!Z:Z) -> -0.058866852 | AA1029: ='O-PTIR'!AA1029/MAX('O-PTIR'!AA:AA) -> -0.024300562 | AB1029: ='O-PTIR'!AB1029/MAX('O-PTIR'!AB:AB) -> 0.33067124 | AC1029: ='O-PTIR'!AC1029/MAX('O-PTIR'!AC:AC) -> -0.15559214 | AD1029: ='O-PTIR'!AD1029/MAX('O-PTIR'!AD:AD) -> 1 | AE1029: ='O-PTIR'!AE1029/MAX('O-PTIR'!AE:AE) -> 0.0016264767 | AF1029: ='O-PTIR'!AF1029/MAX('O-PTIR'!AF:AF) -> 0.15368145 | AG1029: ='O-PTIR'!AG1029/MAX('O-PTIR'!AG:AG) -> -1.10871

Sheet Raman
A1: X value [cmâ»Â¹] | B1: Raman Spectrum 1/Raman Intensity [] | C1: Raman Spectrum 2/Raman Intensity [] | D1: Raman Spectrum 3/Raman Intensity [] | E1: Raman Spectrum 4/Raman Intensity [] | F1: Raman Spectrum 5/Raman Intensity [] | G1: Raman Spectrum 6/Raman Intensity [] | H1: Raman Spectrum 7/Raman Intensity [] | I1: Raman Spectrum 8/Raman Intensity [] | J1: Raman Spectrum 9/Raman Intensity [] | K1: Raman Spectrum 10/Raman Intensity [] | L1: Raman Spectrum 11/Raman Intensity [] | M1: Raman Spectrum 12/Raman Intensity [] | N1: Raman Spectrum 13/Raman Intensity [] | O1: Raman Spectrum 14/Raman Intensity [] | P1: Raman Spectrum 15/Raman Intensity [] | Q1: Raman Spectrum 16/Raman Intensity [] | R1: Raman Spectrum 17/Raman Intensity [] | S1: Raman Spectrum 18/Raman Intensity [] | T1: Raman Spectrum 19/Raman Intensity [] | U1: Raman Spectrum 20/Raman Intensity [] | V1: Raman Spectrum 21/Raman Intensity [] | W1: Raman Spectrum 22/Raman Intensity [] | X1: Raman Spectrum 23/Raman Intensity [] | Y1: Raman Spectrum 24/Raman Intensity [] | Z1: Raman Spectrum 25/Raman Intensity [] | AA1: Raman Spectrum 26/Raman Intensity [] | AB1: Raman Spectrum 27/Raman Intensity [] | AC1: Raman Spectrum 28/Raman Intensity [] | AD1: Raman Spectrum 29/Raman Intensity [] | AE1: Raman Spectrum 1/Raman Intensity [] | AF1: Raman Spectrum 2/Raman Intensity [] | AG1: Raman Spectrum 3/Raman Intensity [] | AH1: Raman Spectrum 4/Raman Intensity [] | AI1: Raman Spectrum 5/Raman Intensity [] | AJ1: Raman Spectrum 6/Raman Intensity [] | AK1: Raman Spectrum 7/Raman Intensity [] | AL1: Raman Spectrum 8/Raman Intensity [] | AM1: Raman Spectrum 9/Raman Intensity [] | AN1: Raman Spectrum 10/Raman Intensity [] | AO1: Raman Spectrum 11/Raman Intensity [] | AP1: Raman Spectrum 12/Raman Intensity [] | AQ1: Raman Spectrum 13/Raman Intensity [] | AR1: Raman Spectrum 14/Raman Intensity [] | AS1: Raman Spectrum 15/Raman Intensity [] | AT1: Raman Spectrum 16/Raman Intensity [] | AU1: Raman Spectrum 17/Raman Intensity [] | AV1: Raman Spectrum 18/Raman Intensity [] | AW1: Raman Spectrum 19/Raman Intensity [] | AX1: Raman Spectrum 20/Raman Intensity [] | AY1: Raman Spectrum 21/Raman Intensity [] | AZ1: Raman Spectrum 22/Raman Intensity [] | BA1: Raman Spectrum 23/Raman Intensity [] | BB1: Raman Spectrum 24/Raman Intensity [] | BC1: Raman Spectrum 25/Raman Intensity [] | BD1: Raman Spectrum 26/Raman Intensity [] | BE1: Raman Spectrum 27/Raman Intensity [] | BF1: Raman Spectrum 28/Raman Intensity [] | BG1: Raman Spectrum 29/Raman Intensity [] | BH1: Raman Spectrum 30/Raman Intensity [] | BI1: Raman Spectrum 1/Raman Intensity [] | BJ1: Raman Spectrum 2/Raman Intensity [] | BK1: Raman Spectrum 3/Raman Intensity [] | BL1: Raman Spectrum 4/Raman Intensity [] | BM1: Raman Spectrum 5/Raman Intensity [] | BN1: Raman Spectrum 6/Raman Intensity [] | BO1: Raman Spectrum 7/Raman Intensity [] | BP1: Raman Spectrum 8/Raman Intensity [] | BQ1: Raman Spectrum 9/Raman Intensity [] | BR1: Raman Spectrum 10/Raman Intensity [] | BS1: Raman Spectrum 11/Raman Intensity [] | BT1: Raman Spectrum 12/Raman Intensity [] | BU1: Raman Spectrum 13/Raman Intensity [] | BV1: Raman Spectrum 14/Raman Intensity [] | BW1: Raman Spectrum 15/Raman Intensity [] | BX1: Raman Spectrum 16/Raman Intensity [] | BY1: Raman Spectrum 17/Raman Intensity [] | BZ1: Raman Spectrum 18/Raman Intensity []
A2: 326.12215 | B2: 7737.2002 | C2: 7766.6665 | D2: 7236 | E2: 7464.6665 | F2: 7268 | G2: 7129 | H2: 7928 | I2: 7088 | J2: 7248.3999 | K2: 6869 | L2: 7444 | M2: 7676.5 | N2: 7270 | O2: 7386 | P2: 7932.6665 | Q2: 7777.3335 | R2: 7485.2002 | S2: 7751 | T2: 7442 | U2: 7746.5 | V2: 7247 | W2: 7357 | X2: 7508.5 | Y2: 7565 | Z2: 7530.3999 | AA2: 6847 | AB2: 8632 | AC2: 8470.5 | AD2: 8532.667 | AE2: 7391 | AF2: 7438.5 | AG2: 7402.6665 | AH2: 7398.6665 | AI2: 7186.5 | AJ2: 7648.5 | AK2: 7414.5 | AL2: 7309.3335 | AM2: 7250.6665 | AN2: 7234 | AO2: 7174 | AP2: 7123.5 | AQ2: 7440 | AR2: 8954.5 | AS2: 8282 | AT2: 7422 | AU2: 7528 | AV2: 8503.5 | AW2: 7490.5 | AX2: 7026 | AY2: 7237.3335 | AZ2: 7300.6665 | BA2: 7994.6665 | BB2: 7445.3335 | BC2: 7712 | BD2: 7719.3335 | BE2: 8473 | BF2: 7358 | BG2: 7459.3335 | BH2: 7388 | BI2: 7518 | BJ2: 7542.5 | BK2: 7717 | BL2: 7447 | BM2: 7616 | BN2: 7520 | BO2: 8253.5 | BP2: 7716 | BQ2: 9226.667 | BR2: 7670.6665 | BS2: 7868 | BT2: 7570 | BU2: 7755.6001 | BV2: 7856 | BW2: 17238 | BX2: 16600 | BY2: 16655.334 | BZ2: 16738
A3: 329.59377 | B3: 7687.7178 | C3: 7726.2866 | D3: 7325.4414 | E3: 7427.0488 | F3: 7193.8164 | G3: 7124.6597 | H3: 7866.4434 | I3: 7077.4775 | J3: 7191.2627 | K3: 6943.9731 | L3: 7463.4663 | M3: 7557.7271 | N3: 7312.6162 | O3: 7318.5244 | P3: 7956.6055 | Q3: 7623.1782 | R3: 7556.8584 | S3: 7759.0498 | T3: 7501.0312 | U3: 7677.4458 | V3: 7291.1948 | W3: 7317.8037 | X3: 7481.9043 | Y3: 7572.6289 | Z3: 7470.4214 | AA3: 6901.98 | AB3: 8588.2002 | AC3: 8364.3545 | AD3: 8534.1133 | AE3: 7330.2324 | AF3: 7378.127 | AG3: 7387.9351 | AH3: 7326.3242 | AI3: 7216.8838 | AJ3: 7549.4565 | AK3: 7384.9053 | AL3: 7371.811 | AM3: 7241.7227 | AN3: 7178.7568 | AO3: 7123.4917 | AP3: 7128.2354 | AQ3: 7457.3623 | AR3: 8801.0029 | AS3: 8314.1992 | AT3: 7452.6206 | AU3: 7623.7549 | AV3: 8398.9326 | AW3: 7463.2729 | AX3: 7099 | AY3: 7272.584 | AZ3: 7258.7871 | BA3: 7951.5244 | BB3: 7469.5352 | BC3: 7712.3154 | BD3: 7776.3657 | BE3: 8486.416 | BF3: 7474.4053 | BG3: 7477.6162 | BH3: 7351.6973 | BI3: 7579.8726 | BJ3: 7516.8516 | BK3: 7741.4648 | BL3: 7362.5566 | BM3: 7649.9351 | BN3: 7597.3403 | BO3: 8114.9971 | BP3: 7613.4053 | BQ3: 9190.8896 | BR3: 7645.6758 | BS3: 7896.4106 | BT3: 7611.3535 | BU3: 7734.3442 | BV3: 7778.6597 | BW3: 16942.844 | BX3: 16737.318 | BY3: 16498.021 | BZ3: 16743.787
A4: 333.06539 | B4: 7669.1577 | C4: 7723.9507 | D4: 7360.2119 | E4: 7472.9478 | F4: 7281.6216 | G4: 7165.4609 | H4: 7992.7837 | I4: 7140.7163 | J4: 7208.6362 | K4: 6994.8877 | L4: 7475.2715 | M4: 7618.6636 | N4: 7376.1597 | O4: 7257.082 | P4: 8063.8228 | Q4: 7628.623 | R4: 7613.2983 | S4: 7705.1357 | T4: 7540.811 | U4: 7671.8213 | V4: 7321.0664 | W4: 7382.6104 | X4: 7475.499 | Y4: 7610.7026 | Z4: 7546.8306 | AA4: 6902.9907 | AB4: 8620.2676 | AC4: 8365.1396 | AD4: 8537.1221 | AE4: 7359.4575 | AF4: 7370.7417 | AG4: 7406.146 | AH4: 7308.1655 | AI4: 7227.3311 | AJ4: 7605.562 | AK4: 7371.7549 | AL4: 7335.7573 | AM4: 7323.6436 | AN4: 7275.8955 | AO4: 7198.0015 | AP4: 7181.3682 | AQ4: 7446.8477 | AR4: 8820.6104 | AS4: 8285.6182 | AT4: 7431.1943 | AU4: 7645.4482 | AV4: 8454.9219 | AW4: 7483.9741 | AX4: 7171.8252 | AY4: 7280.8345 | AZ4: 7297.0791 | BA4: 7952.2388 | BB4: 7421.2178 | BC4: 7700.8994 | BD4: 7845.8384 | BE4: 8516.2256 | BF4: 7478.9829 | BG4: 7498.5269 | BH4: 7251.085 | BI4: 7547.7954 | BJ4: 7517.7705 | BK4: 7764.3184 | BL4: 7433.2466 | BM4: 7769.1475 | BN4: 7622.6621 | BO4: 7985.9189 | BP4: 7682.7432 | BQ4: 9124.6084 | BR4: 7737.7246 | BS4: 7915.0732 | BT4: 7672.8696 | BU4: 7649.0186 | BV4: 7805.7886 | BW4: 17002.121 | BX4: 16691.244 | BY4: 16524.186 | BZ4: 16756.795
A5: 336.537 | B5: 7699.7539 | C5: 7758.9131 | D5: 7391.0928 | E5: 7535.6548 | F5: 7353.9102 | G5: 7191.4321 | H5: 8093.1226 | I5: 7184.6206 | J5: 7245.2676 | K5: 6946.0317 | L5: 7515.1089 | M5: 7685.125 | N5: 7437.4189 | O5: 7302.6006 | P5: 8068.7866 | Q5: 7739.6021 | R5: 7641.6899 | S5: 7716.8184 | T5: 7554.0571 | U5: 7707.6602 | V5: 7331.146 | W5: 7392.0039 | X5: 7512.1978 | Y5: 7655.8379 | Z5: 7613.188 | AA5: 6916.7812 | AB5: 8650.999 | AC5: 8442.8242 | AD5: 8534.3691 | AE5: 7413.4033 | AF5: 7386.3872 | AG5: 7428.7588 | AH5: 7319.1382 | AI5: 7235.5337 | AJ5: 7674.7422 | AK5: 7427.1401 | AL5: 7279.2251 | AM5: 7369.4312 | AN5: 7360.1304 | AO5: 7273.8921 | AP5: 7131.9487 | AQ5: 7478.4307 | AR5: 8880.8223 | AS5: 8327.7148 | AT5: 7446.5483 | AU5: 7642.917 | AV5: 8501.1064 | AW5: 7487.979 | AX5: 7226.0713 | AY5: 7301.4033 | AZ5: 7329.4961 | BA5: 8013.9448 | BB5: 7427.998 | BC5: 7717.1987 | BD5: 7861.8867 | BE5: 8531.6201 | BF5: 7484.5947 | BG5: 7494.9805 | BH5: 7256.5928 | BI5: 7562.3774 | BJ5: 7487.5366 | BK5: 7694.8936 | BL5: 7522.1543 | BM5: 7816.083 | BN5: 7660.1699 | BO5: 8049.6704 | BP5: 7758.2583 | BQ5: 9188.8877 | BR5: 7736.9058 | BS5: 7972.4399 | BT5: 7699.6128 | BU5: 7669.915 | BV5: 7855.7705 | BW5: 17078.096 | BX5: 16695.082 | BY5: 16620.312 | BZ5: 16745.6
A6: 340.00862 | B6: 7742.8281 | C6: 7812.9556 | D6: 7419.6567 | E6: 7580.833 | F6: 7337.563 | G6: 7191.5869 | H6: 8103.2344 | I6: 7190.1665 | J6: 7268.271 | K6: 6847.521 | L6: 7573.9136 | M6: 7694.5425 | N6: 7485.3394 | O6: 7431.8198 | P6: 7982.8076 | Q6: 7873.6294 | R6: 7655.2529 | S6: 7816.1245 | T6: 7537.6567 | U6: 7756.9629 | V6: 7324.8999 | W6: 7335.3706 | X6: 7565.7993 | Y6: 7678.2393 | Z6: 7614.4429 | AA6: 6956 | AB6: 8649.0078 | AC6: 8543.2334 | AD6: 8524.9023 | AE6: 7450.1582 | AF6: 7416.8892 | AG6: 7446.7002 | AH6: 7328.3901 | AI6: 7251.1313 | AJ6: 7688.605 | AK6: 7526.3545 | AL6: 7280.0938 | AM6: 7334.7446 | AN6: 7372.6797 | AO6: 7293.9551 | AP6: 7022.0791 | AQ6: 7571.2505 | AR6: 8898.2451 | AS6: 8423.4717 | AT6: 7492.8857 | AU6: 7662.9648 | AV6: 8484.2861 | AW6: 7470.708 | AX6: 7245.5537 | AY6: 7340.4741 | AZ6: 7313.8296 | BA6: 8070.8984 | BB6: 7497.6899 | BC6: 7769.1392 | BD6: 7824 | BE6: 8530.4668 | BF6: 7526.5752 | BG6: 7480.4224 | BH6: 7374.3311 | BI6: 7628.5356 | BJ6: 7462.8237 | BK6: 7604.9976 | BL6: 7548.9087 | BM6: 7779.1572 | BN6: 7729.5176 | BO6: 8228.0557 | BP6: 7777.8203 | BQ6: 9335.9814 | BR6: 7656.4907 | BS6: 8047.7734 | BT6: 7694.4224 | BU6: 7789.9878 | BV6: 7874.7212 | BW6: 17043.805 | BX6: 16807.83 | BY6: 16702.143 | BZ6: 16729.656
A7: 343.48024 | B7: 7675.1562 | C7: 7841.3936 | D7: 7372.6553 | E7: 7616.6436 | F7: 7297.2759 | G7: 7224.6333 | H7: 8166.4297 | I7: 7243.4878 | J7: 7272.7471 | K7: 6940.7339 | L7: 7575.8887 | M7: 7738.5156 | N7: 7524.2041 | O7: 7440.5093 | P7: 8106.0381 | Q7: 7897.3276 | R7: 7706.5991 | S7: 7878.793 | T7: 7490.6553 | U7: 7780.6611 | V7: 7317.7383 | W7: 7418.3145 | X7: 7534.2808 | Y7: 7631.6328 | Z7: 7618.9458 | AA7: 6956 | AB7: 8644.2676 | AC7: 8571.4082 | AD7: 8516.4756 | AE7: 7455.6875 | AF7: 7487.9834 | AG7: 7478.6929 | AH7: 7292.0527 | AI7: 7273.7236 | AJ7: 7674.7808 | AK7: 7530.436 | AL7: 7433.3423 | AM7: 7284.8203 | AN7: 7399.8013 | AO7: 7287.3721 | AP7: 7184.8071 | AQ7: 7677.4976 | AR7: 8847.8467 | AS7: 8334.998 | AT7: 7423.8975 | AU7: 7756.7041 | AV7: 8514.3037 | AW7: 7515.4712 | AX7: 7210.9546 | AY7: 7357.063 | AZ7: 7262.8784 | BA7: 7922.3896 | BB7: 7465.1704 | BC7: 7822.3286 | BD7: 7824 | BE7: 8551.7949 | BF7: 7531.71 | BG7: 7530.1885 | BH7: 7375.9106 | BI7: 7552.3066 | BJ7: 7629.106 | BK7: 7819.8618 | BL7: 7500.7222 | BM7: 7856.3081 | BN7: 7789.2896 | BO7: 8050.0557 | BP7: 7821.5308 | BQ7: 9205.3779 | BR7: 7840.2832 | BS7: 8014.8594 | BT7: 7744.1885 | BU7: 7744.5659 | BV7: 7839.9634 | BW7: 17061.973 | BX7: 16845.221 | BY7: 16717.152 | BZ7: 16807.598
A8: 346.95186 | B8: 7760.1597 | C8: 7840.0161 | D8: 7417.248 | E8: 7656.9624 | F8: 7336.0312 | G8: 7163.4609 | H8: 8180.4443 | I8: 7272.9839 | J8: 7223.0166 | K8: 6960.9204 | L8: 7531.9849 | M8: 7719.3652 | N8: 7566.0884 | O8: 7490.9834 | P8: 8174.1738 | Q8: 7964.5654 | R8: 7692.9634 | S8: 7825.0142 | T8: 7604.0063 | U8: 7856.6021 | V8: 7349.5366 | W8: 7606.7705 | X8: 7613.4434 | Y8: 7716.2847 | Z8: 7669.3325 | AA8: 7015.3086 | AB8: 8725.4658 | AC8: 8602.0947 | AD8: 8658.9375 | AE8: 7545.0254 | AF8: 7475.9604 | AG8: 7522.6504 | AH8: 7394.4434 | AI8: 7273.1348 | AJ8: 7689.6665 | AK8: 7573.8115 | AL8: 7454.6826 | AM8: 7351.6289 | AN8: 7374.228 | AO8: 7309.1318 | AP8: 7260.5454 | AQ8: 7613.7471 | AR8: 8975.0566 | AS8: 8406.6914 | AT8: 7587.1089 | AU8: 7763.8652 | AV8: 8587.2451 | AW8: 7563.5073 | AX8: 7215.7144 | AY8: 7366.9521 | AZ8: 7333.8564 | BA8: 8104.4844 | BB8: 7529.4805 | BC8: 7852.0908 | BD8: 7840.4126 | BE8: 8565.6826 | BF8: 7519.5664 | BG8: 7531.5078 | BH8: 7392.4126 | BI8: 7518.1592 | BJ8: 7668.3408 | BK8: 7816.5825 | BL8: 7500.9839 | BM8: 7782.583 | BN8: 7675.0439 | BO8: 8250.3779 | BP8: 7830.9629 | BQ8: 9347.5029 | BR8: 7819.5825 | BS8: 7985.397 | BT8: 7720.8892 | BU8: 7771.8408 | BV8: 7939.459 | BW8: 17263.184 | BX8: 16752.34 | BY8: 16782.158 | BZ8: 16840.35
A9: 350.42348 | B9: 7775.1572 | C9: 7937.7554 | D9: 7400.415 | E9: 7672.6836 | F9: 7333.8984 | G9: 7208.1948 | H9: 8198.4912 | I9: 7281.6421 | J9: 7304.2188 | K9: 7039.5298 | L9: 7549.3818 | M9: 7759.9468 | N9: 7547.6118 | O9: 7528.9316 | P9: 8195.5371 | Q9: 7976.4448 | R9: 7708.0864 | S9: 7852.999 | T9: 7615.8594 | U9: 7921.7168 | V9: 7433.5825 | W9: 7615.3042 | X9: 7633.665 | Y9: 7746 | Z9: 7671.1572 | AA9: 7009.2012 | AB9: 8782.6123 | AC9: 8567.4531 | AD9: 8671.3184 | AE9: 7585.71 | AF9: 7455.9194 | AG9: 7565.4458 | AH9: 7410.6782 | AI9: 7250.2266 | AJ9: 7725.5928 | AK9: 7542.0742 | AL9: 7487.2314 | AM9: 7407.0889 | AN9: 7431.5527 | AO9: 7371.6978 | AP9: 7269.1382 | AQ9: 7649.5752 | AR9: 9046.8848 | AS9: 8470.3701 | AT9: 7601.063 | AU9: 7753.4976 | AV9: 8573.125 | AW9: 7631.0615 | AX9: 7205.1187 | AY9: 7375.3672 | AZ9: 7382.0786 | BA9: 8214.3457 | BB9: 7568.6382 | BC9: 7885.6743 | BD9: 7851.3672 | BE9: 8644.7822 | BF9: 7555.4082 | BG9: 7520.8022 | BH9: 7438.2534 | BI9: 7554.1577 | BJ9: 7658.1943 | BK9: 7781.6353 | BL9: 7594.6729 | BM9: 7807.5244 | BN9: 7701.0161 | BO9: 8323.6104 | BP9: 7828.3242 | BQ9: 9302.6504 | BR9: 7833.1523 | BS9: 8052.5713 | BT9: 7787.1401 | BU9: 7859.8237 | BV9: 8034.1123 | BW9: 17369.262 | BX9: 16840.762 | BY9: 16902.398 | BZ9: 16934.801
A10: 353.89509 | B10: 7743.5078 | C10: 7966.5327 | D10: 7423.8442 | E10: 7683.5859 | F10: 7380.9253 | G10: 7263.2422 | H10: 8194.8193 | I10: 7321.312 | J10: 7420.811 | K10: 7142.9565 | L10: 7626.4258 | M10: 7808.4883 | N10: 7526.9346 | O10: 7528.5078 | P10: 8218.7852 | Q10: 7980.5972 | R10: 7758.6919 | S10: 7903.0811 | T10: 7623.5361 | U10: 7917.6948 | V10: 7501.2017 | W10: 7551.4399 | X10: 7645.3853 | Y10: 7794.2119 | Z10: 7669.5576 | AA10: 7013.1929 | AB10: 8817.4111 | AC10: 8539.8975 | AD10: 8663.7754 | AE10: 7625.4868 | AF10: 7462.7061 | AG10: 7596.8247 | AH10: 7402.5859 | AI10: 7279.7075 | AJ10: 7767.6855 | AK10: 7507.9438 | AL10: 7528.0229 | AM10: 7425.0889 | AN10: 7492.5005 | AO10: 7379.8379 | AP10: 7268.7778 | AQ10: 7673.5918 | AR10: 9068.0254 | AS10: 8518.166 | AT10: 7583.9453 | AU10: 7760.5107 | AV10: 8586.6709 | AW10: 7638.7954 | AX10: 7256.9067 | AY10: 7434.1558 | AZ10: 7443.6074 | BA10: 8244.6143 | BB10: 7613.1821 | BC10: 7921.5059 | BD10: 7832.2241 | BE10: 8721.6611 | BF10: 7611.4644 | BG10: 7560.6523 | BH10: 7445.9219 | BI10: 7656.4116 | BJ10: 7707.2827 | BK10: 7769.8691 | BL10: 7660.2471 | BM10: 7851.3394 | BN10: 7811.6606 | BO10: 8352.4082 | BP10: 7806.8286 | BQ10: 9252.3613 | BR10: 7828.2427 | BS10: 8110.7412 | BT10: 7835.1587 | BU10: 7880.439 | BV10: 8072.1309 | BW10: 17433.701 | BX10: 16984.957 | BY10: 17069.117 | BZ10: 17009.32
A11: 357.36671 | B11: 7732.7788 | C11: 7864.9331 | D11: 7522.5337 | E11: 7705.0576 | F11: 7504.521 | G11: 7265.0859 | H11: 8166.311 | I11: 7402.666 | J11: 7480.5151 | K11: 7225.2046 | L11: 7725.4292 | M11: 7828.0293 | N11: 7548.2271 | O11: 7501.9043 | P11: 8266.9023 | Q11: 8015.4248 | R11: 7820.9424 | S11: 7921.3096 | T11: 7680.7168 | U11: 7853.1865 | V11: 7513.4429 | W11: 7522.8608 | X11: 7658.4165 | Y11: 7892.6973 | Z11: 7702.5728 | AA11: 7057.3589 | AB11: 8825.0254 | AC11: 8579.582 | AD11: 8722.0586 | AE11: 7671.2632 | AF11: 7509.1851 | AG11: 7604.0732 | AH11: 7429.7207 | AI11: 7369.0537 | AJ11: 7810.4678 | AK11: 7535.6592 | AL11: 7556.2192 | AM11: 7414.791 | AN11: 7498.0024 | AO11: 7304.0576 | AP11: 7305.8193 | AQ11: 7633.9761 | AR11: 9066.2168 | AS11: 8548.8594 | AT11: 7627.0542 | AU11: 7802.0513 | AV11: 8684.5879 | AW11: 7575.9707 | AX11: 7389.5591 | AY11: 7543.6196 | AZ11: 7523.6255 | BA11: 8222.7373 | BB11: 7668.0098 | BC11: 7939.7529 | BD11: 7816.29 | BE11: 8754.4434 | BF11: 7645.7441 | BG11: 7661.7002 | BH11: 7413.3154 | BI11: 7758.7822 | BJ11: 7835.5024 | BK11: 7810.1724 | BL11: 7637.3398 | BM11: 7847.4644 | BN11: 7911.1807 | BO11: 8401.7871 | BP11: 7766.6748 | BQ11: 9336.6387 | BR11: 7799.4565 | BS11: 8099.9072 | BT11: 7808.8188 | BU11: 7809.4146 | BV11: 8047.043 | BW11: 17505.48 | BX11: 17069.043 | BY11: 17209.262 | BZ11: 17014.535
A12: 360.83833 | B12: 7900.0107 | C12: 7945.6982 | D12: 7482.1509 | E12: 7730.3955 | F12: 7504.6528 | G12: 7303.0933 | H12: 8193.2324 | I12: 7404.3291 | J12: 7450.4263 | K12: 7232.7266 | L12: 7721.8662 | M12: 7859.438 | N12: 7593.3608 | O12: 7570.0005 | P12: 8278.7793 | Q12: 8064.9131 | R12: 7795.6045 | S12: 7920.1221 | T12: 7638.3545 | U12: 7935.5356 | V12: 7532.4468 | W12: 7562.5835 | X12: 7511.1382 | Y12: 7897.0522 | Z12: 7762.355 | AA12: 6995.0693 | AB12: 8753.3652 | AC12: 8689.3809 | AD12: 8784.876 | AE12: 7566.7432 | AF12: 7554.0547 | AG12: 7562.8989 | AH12: 7490.4268 | AI12: 7310.0635 | AJ12: 7878.96 | AK12: 7633.4482 | AL12: 7524.2827 | AM12: 7469.6904 | AN12: 7488.0254 | AO12: 7329.3955 | AP12: 7387.957 | AQ12: 7733.7451 | AR12: 9088.3877 | AS12: 8545.9033 | AT12: 7643.6299 | AU12: 7852.332 | AV12: 8704.9111 | AW12: 7654.8882 | AX12: 7421.1523 | AY12: 7541.2441 | AZ12: 7496.3081 | BA12: 8194.8652 | BB12: 7628.1021 | BC12: 7867.4336 | BD12: 8017.9395 | BE12: 8803.0078 | BF12: 7587.9414 | BG12: 7676.481 | BH12: 7552.6758 | BI12: 7607.5454 | BJ12: 7792.4277 | BK12: 7886.1865 | BL12: 7676.9307 | BM12: 7831.6279 | BN12: 7852.9819 | BO12: 8362.9883 | BP12: 7733.4185 | BQ12: 9453.0361 | BR12: 7945.9429 | BS12: 8132.6357 | BT12: 7857.6475 | BU12: 7955.6367 | BV12: 8066.0469 | BW12: 17552.197 | BX12: 17088.047 | BY12: 17048.521 | BZ12: 17030.373
A13: 364.30995 | B13: 7901.1914 | C13: 8038.7783 | D13: 7560.126 | E13: 7708.1348 | F13: 7564.7217 | G13: 7329.0234 | H13: 8191.7373 | I13: 7396.5669 | J13: 7509.3774 | K13: 7201.1753 | L13: 7692.4907 | M13: 7836.6177 | N13: 7584.502 | O13: 7588.604 | P13: 8296.1035 | Q13: 8093.4443 | R13: 7821.7725 | S13: 7936.3398 | T13: 7754.2051 | U13: 7901.374 | V13: 7548.7979 | W13: 7613.0815 | X13: 7663.6616 | Y13: 7908.1562 | Z13: 7798.9302 | AA13: 7097.9546 | AB13: 8797.1514 | AC13: 8712.5068 | AD13: 8831.5908 | AE13: 7617.8076 | AF13: 7651.0225 | AG13: 7590.5176 | AH13: 7542.229 | AI13: 7368.6494 | AJ13: 7856.1621 | AK13: 7652.3804 | AL13: 7626.5698 | AM13: 7558.2168 | AN13: 7536.0195 | AO13: 7385.9927 | AP13: 7328.8618 | AQ13: 7766.7339 | AR13: 9117.1895 | AS13: 8598.9297 | AT13: 7726.4409 | AU13: 7900.0073 | AV13: 8759.335 | AW13: 7687.8652 | AX13: 7437.4717 | AY13: 7544.5522 | AZ13: 7508.4189 | BA13: 8211.8916 | BB13: 7662.0078 | BC13: 7928.2012 | BD13: 8079.3979 | BE13: 8766.085 | BF13: 7775.8052 | BG13: 7718.4946 | BH13: 7613.5332 | BI13: 7701.4062 | BJ13: 7846.6104 | BK13: 7902.5254 | BL13: 7592.1963 | BM13: 7986.6499 | BN13: 7822.1348 | BO13: 8373.9189 | BP13: 7948.8125 | BQ13: 9491.9961 | BR13: 7899.1924 | BS13: 8197.0967 | BT13: 7909.792 | BU13: 7977.2974 | BV13: 8032.4785 | BW13: 17550.605 | BX13: 17097.104 | BY13: 17131.461 | BZ13: 17204.635
... A1025: 3877.5872 | B1025: 2640.5 | C1025: 2781.2 | D1025: 2990 | E1025: 2902 | F1025: 2904.6667 | G1025: 2807 | H1025: 5550 | I1025: 2989.3333 | J1025: 2990 | K1025: 3328 | L1025: 3294 | M1025: 3614 | N1025: 3203.5 | O1025: 2768 | P1025: 2658 | Q1025: 4128 | R1025: 2728 | S1025: 2522.3999 | T1025: 2930 | U1025: 3058.3333 | V1025: 2591 | W1025: 2744 | X1025: 3084 | Y1025: 2971.5 | Z1025: 3030 | AA1025: 2805.6001 | AB1025: 3594 | AC1025: 3120.5 | AD1025: 3045 | AE1025: 3057.3333 | AF1025: 2706 | AG1025: 2896 | AH1025: 2980 | AI1025: 2900.6667 | AJ1025: 3126.3999 | AK1025: 2692 | AL1025: 2859.3333 | AM1025: 2824 | AN1025: 3015.5 | AO1025: 2867 | AP1025: 2706.6667 | AQ1025: 3499 | AR1025: 2994 | AS1025: 2617.3333 | AT1025: 2759.2 | AU1025: 3088.6667 | AV1025: 2710.3333 | AW1025: 3144 | AX1025: 2798.5 | AY1025: 2572.6667 | AZ1025: 2824 | BA1025: 3074.6667 | BB1025: 3049.5 | BC1025: 3064 | BD1025: 2846 | BE1025: 2928.5 | BF1025: 2927 | BG1025: 3210 | BH1025: 2965 | BI1025: 2909.2 | BJ1025: 2970 | BK1025: 2840.5 | BL1025: 3390 | BM1025: 2726.6667 | BN1025: 3241 | BO1025: 4388 | BP1025: 3543.5 | BQ1025: 3651.3333 | BR1025: 2792.5 | BS1025: 3412 | BT1025: 2716.5 | BU1025: 2827.5 | BV1025: 2946 | BW1025: 4478 | BX1025: 4209 | BY1025: 4342.6665 | BZ1025: 4300

Sheet Raman norm
A1: Raman waveno | B1: 1 | C1: =B1+1 -> 2 | D1: =C1+1 -> 3 | E1: =D1+1 -> 4 | F1: =E1+1 -> 5 | G1: =F1+1 -> 6 | H1: =G1+1 -> 7 | I1: =H1+1 -> 8 | J1: =I1+1 -> 9 | ... BZ1: =BY1+1 -> 77
A2: 326.12215 | B2: =Raman!B2/MAX(Raman!B:B) -> 0.85738107 | C2: =Raman!C2/MAX(Raman!C:C) -> 0.84591306 | D2: =Raman!D2/MAX(Raman!D:D) -> 0.72884892 | E2: =Raman!E2/MAX(Raman!E:E) -> 0.670668 | F2: =Raman!F2/MAX(Raman!F:F) -> 0.79650585 | G2: =Raman!G2/MAX(Raman!G:G) -> 0.81739135 | H2: =Raman!H2/MAX(Raman!H:H) -> 0.69983167 | I2: =Raman!I2/MAX(Raman!I:I) -> 0.78581323 | J2: =Raman!J2/MAX(Raman!J:J) -> 0.80915135 | K2: =Raman!K2/MAX(Raman!K:K) -> 0.71925091 | L2: =Raman!L2/MAX(Raman!L:L) -> 0.65468282 | M2: =Raman!M2/MAX(Raman!M:M) -> 0.59184347 | N2: =Raman!N2/MAX(Raman!N:N) -> 0.60432159 | O2: =Raman!O2/MAX(Raman!O:O) -> 0.68730084 | P2: =Raman!P2/MAX(Raman!P:P) -> 0.85910496 | Q2: =Raman!Q2/MAX(Raman!Q:Q) -> 0.53110085 | R2: =Raman!R2/MAX(Raman!R:R) -> 0.54574341 | S2: =Raman!S2/MAX(Raman!S:S) -> 0.60906978 | T2: =Raman!T2/MAX(Raman!T:T) -> 0.59067411 | U2: =Raman!U2/MAX(Raman!U:U) -> 0.78961325 | V2: =Raman!V2/MAX(Raman!V:V) -> 0.84777053 | W2: =Raman!W2/MAX(Raman!W:W) -> 0.85674726 | X2: =Raman!X2/MAX(Raman!X:X) -> 0.76889823 | Y2: =Raman!Y2/MAX(Raman!Y:Y) -> 0.85609513 | Z2: =Raman!Z2/MAX(Raman!Z:Z) -> 0.86473262 | AA2: =Raman!AA2/MAX(Raman!AA:AA) -> 0.82666142 | AB2: =Raman!AB2/MAX(Raman!AB:AB) -> 0.51346873 | AC2: =Raman!AC2/MAX(Raman!AC:AC) -> 0.84446843 | AD2: =Raman!AD2/MAX(Raman!AD:AD) -> 0.83896279 | AE2: =Raman!AE2/MAX(Raman!AE:AE) -> 0.48779193 | AF2: =Raman!AF2/MAX(Raman!AF:AF) -> 0.59874742 | AG2: =Raman!AG2/MAX(Raman!AG:AG) -> 0.6966638 | AH2: =Raman!AH2/MAX(Raman!AH:AH) -> 0.87152136 | AI2: =Raman!AI2/MAX(Raman!AI:AI) -> 0.75069331 | AJ2: =Raman!AJ2/MAX(Raman!AJ:AJ) -> 0.76430319 | AK2: =Raman!AK2/MAX(Raman!AK:AK) -> 0.80688747 | AL2: =Raman!AL2/MAX(Raman!AL:AL) -> 0.7666505 | AM2: =Raman!AM2/MAX(Raman!AM:AM) -> 0.57616175 | AN2: =Raman!AN2/MAX(Raman!AN:AN) -> 0.53912949 | AO2: =Raman!AO2/MAX(Raman!AO:AO) -> 0.77767407 | AP2: =Raman!AP2/MAX(Raman!AP:AP) -> 0.77338881 | AQ2: =Raman!AQ2/MAX(Raman!AQ:AQ) -> 0.66738002 | AR2: =Raman!AR2/MAX(Raman!AR:AR) -> 0.52909843 | AS2: =Raman!AS2/MAX(Raman!AS:AS) -> 0.87586231 | AT2: =Raman!AT2/MAX(Raman!AT:AT) -> 0.85009071 | AU2: =Raman!AU2/MAX(Raman!AU:AU) -> 0.73925255 | AV2: =Raman!AV2/MAX(Raman!AV:AV) -> 0.65768473 | AW2: =Raman!AW2/MAX(Raman!AW:AW) -> 0.80658698 | AX2: =Raman!AX2/MAX(Raman!AX:AX) -> 0.7884421 | AY2: =Raman!AY2/MAX(Raman!AY:AY) -> 0.74772812 | AZ2: =Raman!AZ2/MAX(Raman!AZ:AZ) -> 0.75913376 | BA2: =Raman!BA2/MAX(Raman!BA:BA) -> 0.62086223 | BB2: =Raman!BB2/MAX(Raman!BB:BB) -> 0.61816507 | BC2: =Raman!BC2/MAX(Raman!BC:BC) -> 0.46216466 | BD2: =Raman!BD2/MAX(Raman!BD:BD) -> 0.41129288 | BE2: =Raman!BE2/MAX(Raman!BE:BE) -> 0.54280507 | BF2: =Raman!BF2/MAX(Raman!BF:BF) -> 0.68136931 | BG2: =Raman!BG2/MAX(Raman!BG:BG) -> 0.61744024 | BH2: =Raman!BH2/MAX(Raman!BH:BH) -> 0.80854057 | BI2: =Raman!BI2/MAX(Raman!BI:BI) -> 0.59703435 | BJ2: =Raman!BJ2/MAX(Raman!BJ:BJ) -> 0.59425904 | BK2: =Raman!BK2/MAX(Raman!BK:BK) -> 0.52855517 | BL2: =Raman!BL2/MAX(Raman!BL:BL) -> 0.57931466 | BM2: =Raman!BM2/MAX(Raman!BM:BM) -> 0.40995889 | BN2: =Raman!BN2/MAX(Raman!BN:BN) -> 0.51993804 | BO2: =Raman!BO2/MAX(Raman!BO:BO) -> 0.76518134 | BP2: =Raman!BP2/MAX(Raman!BP:BP) -> 0.83288645 | BQ2: =Raman!BQ2/MAX(Raman!BQ:BQ) -> 0.32368341 | BR2: =Raman!BR2/MAX(Raman!BR:BR) -> 0.719429 | BS2: =Raman!BS2/MAX(Raman!BS:BS) -> 0.74291293 | BT2: =Raman!BT2/MAX(Raman!BT:BT) -> 0.84816711 | BU2: =Raman!BU2/MAX(Raman!BU:BU) -> 0.85044256 | BV2: =Raman!BV2/MAX(Raman!BV:BV) -> 0.68724087 | BW2: =Raman!BW2/MAX(Raman!BW:BW) -> 0.88725424 | BX2: =Raman!BX2/MAX(Raman!BX:BX) -> 0.8766852 | BY2: =Raman!BY2/MAX(Raman!BY:BY) -> 0.87875366 | BZ2: =Raman!BZ2/MAX(Raman!BZ:BZ) -> 0.87278653
